Workbook
Name \0: #REF!
Name \0: #REF!
Name \0: #REF!
Name \0: #REF!
Name \0: #REF!
Name \a: #REF!
Name \a: #REF!
Name \a: #REF!
Name \AT: #REF!
Name \AT: #REF!
Name \AT: #REF!
Name \b: #REF!
Name \b: #REF!
Name \c: #REF!
Name \c: #REF!
Name \d: #REF!
Name \d: #REF!
Name \DCS: #REF!
Name \DCS: #REF!
Name \e: #REF!
Name \e: #REF!
Name \f: #REF!
Name \f: #REF!
Name \g: #REF!
Name \g: #REF!
Name \h: #REF!
Name \h: #REF!
Name \i: #REF!
Name \i: #REF!
Name \j: #REF!
Name \j: #REF!
Name \k: #REF!
Name \k: #REF!
Name \kd: #REF!
Name \kd: #REF!
Name \m: #REF!
Name \m: #REF!
Name \N: #REF!
Name \N: #REF!
Name \p: #REF!
Name \p: #REF!
Name \r: #REF!
Name \r: #REF!
Name \s: #REF!
Name \s: #REF!
Name \t: #N/A
Name \u: #REF!
Name \u: #REF!
Name \u: #REF!
Name \u: #REF!
Name \u: #REF!
Name \v: #REF!
Name \v: #REF!
Name \v: #REF!
Name \x: #REF!
Name \x: #REF!
Name \x: #REF!
Name \z: #REF!
Name \z: #REF!
Name __________Ano95: #REF!

Sheet Resumo
B2: 1 - Capacidade de recebimento rodoviário | F2: 2 - Capacidade de Venda por Filial | K2: 2 - Capacidade de expedição rodo por filial
B3: Capacidade Recebimento Rodo por Filial (m³) | F3: Capacidade Venda por Filial (m³) | K3: Capacidade Expedição por filial
A4: 1 | B4: =VLOOKUP(VLOOKUP(C4,'Recebimento Rodo - ALE'!E:H,4,0),'Recebimento Rodo - ALE'!$H:$I,2,0) -> GUARULHOS | C4: =LARGE('Recebimento Rodo - ALE'!E:E,Resumo!A4) -> 48441.543 | E4: 1 | F4: =VLOOKUP(VLOOKUP(G4,'Capacidade ALE'!A:F,5,0),'Capacidade ALE'!E:F,2,0) -> GUARULHOS | G4: =LARGE('Capacidade ALE'!A:A,Resumo!E4) -> 107286.25 | J4: 1 | K4: =VLOOKUP(L4,'Expedição Rodo - ALE'!B:E,4,0) -> BETIM | L4: =LARGE('Expedição Rodo - ALE'!B:B,Resumo!J4) -> 90988.924
A5: =A4+1 -> 2 | B5: =VLOOKUP(VLOOKUP(C5,'Recebimento Rodo - ALE'!E:H,4,0),'Recebimento Rodo - ALE'!$H:$I,2,0) -> PAULINIA | C5: =LARGE('Recebimento Rodo - ALE'!E:E,Resumo!A5) -> 41486.129 | E5: =E4+1 -> 2 | F5: =VLOOKUP(VLOOKUP(G5,'Capacidade ALE'!A:F,5,0),'Capacidade ALE'!E:F,2,0) -> DUQUE DE CAXIAS | G5: =LARGE('Capacidade ALE'!A:A,Resumo!E5) -> 97708.61 | J5: =J4+1 -> 2 | K5: =VLOOKUP(L5,'Expedição Rodo - ALE'!B:E,4,0) -> GUARULHOS | L5: =LARGE('Expedição Rodo - ALE'!B:B,Resumo!J5) -> 67171.079
A6: =A5+1 -> 3 | B6: =VLOOKUP(VLOOKUP(C6,'Recebimento Rodo - ALE'!E:H,4,0),'Recebimento Rodo - ALE'!$H:$I,2,0) -> IPOJUCA | C6: =LARGE('Recebimento Rodo - ALE'!E:E,Resumo!A6) -> 36287.333 | E6: =E5+1 -> 3 | F6: =VLOOKUP(VLOOKUP(G6,'Capacidade ALE'!A:F,5,0),'Capacidade ALE'!E:F,2,0) -> PAULINIA | G6: =LARGE('Capacidade ALE'!A:A,Resumo!E6) -> 84138.491 | J6: =J5+1 -> 3 | K6: =VLOOKUP(L6,'Expedição Rodo - ALE'!B:E,4,0) -> PAULINIA | L6: =LARGE('Expedição Rodo - ALE'!B:B,Resumo!J6) -> 56760
A7: =A6+1 -> 4 | B7: =VLOOKUP(VLOOKUP(C7,'Recebimento Rodo - ALE'!E:H,4,0),'Recebimento Rodo - ALE'!$H:$I,2,0) -> BETIM | C7: =LARGE('Recebimento Rodo - ALE'!E:E,Resumo!A7) -> 33168.39 | E7: =E6+1 -> 4 | F7: =VLOOKUP(VLOOKUP(G7,'Capacidade ALE'!A:F,5,0),'Capacidade ALE'!E:F,2,0) -> BETIM | G7: =LARGE('Capacidade ALE'!A:A,Resumo!E7) -> 40164.72 | J7: =J6+1 -> 4 | K7: =VLOOKUP(L7,'Expedição Rodo - ALE'!B:E,4,0) -> SAO JOSE DO RIO PRETO | L7: =LARGE('Expedição Rodo - ALE'!B:B,Resumo!J7) -> 56140.501
A8: =A7+1 -> 5 | B8: =VLOOKUP(VLOOKUP(C8,'Recebimento Rodo - ALE'!E:H,4,0),'Recebimento Rodo - ALE'!$H:$I,2,0) -> GOIANIA | C8: =LARGE('Recebimento Rodo - ALE'!E:E,Resumo!A8) -> 30571.429 | E8: =E7+1 -> 5 | F8: =VLOOKUP(VLOOKUP(G8,'Capacidade ALE'!A:F,5,0),'Capacidade ALE'!E:F,2,0) -> GUAMARE | G8: =LARGE('Capacidade ALE'!A:A,Resumo!E8) -> 37755.231 | J8: =J7+1 -> 5 | K8: =VLOOKUP(L8,'Expedição Rodo - ALE'!B:E,4,0) -> SAO LUIS | L8: =LARGE('Expedição Rodo - ALE'!B:B,Resumo!J8) -> 52416
A9: =A8+1 -> 6 | B9: =VLOOKUP(VLOOKUP(C9,'Recebimento Rodo - ALE'!E:H,4,0),'Recebimento Rodo - ALE'!$H:$I,2,0) -> TERESINA | C9: =LARGE('Recebimento Rodo - ALE'!E:E,Resumo!A9) -> 27765.926 | E9: =E8+1 -> 6 | F9: =VLOOKUP(VLOOKUP(G9,'Capacidade ALE'!A:F,5,0),'Capacidade ALE'!E:F,2,0) -> SAO JOSE DO RIO PRETO | G9: =LARGE('Capacidade ALE'!A:A,Resumo!E9) -> 24899.324 | J9: =J8+1 -> 6 | K9: =VLOOKUP(L9,'Expedição Rodo - ALE'!B:E,4,0) -> IPOJUCA | L9: =LARGE('Expedição Rodo - ALE'!B:B,Resumo!J9) -> 44068.4
A10: =A9+1 -> 7 | B10: =VLOOKUP(VLOOKUP(C10,'Recebimento Rodo - ALE'!E:H,4,0),'Recebimento Rodo - ALE'!$H:$I,2,0) -> BAURU | C10: =LARGE('Recebimento Rodo - ALE'!E:E,Resumo!A10) -> 20232.023 | E10: =E9+1 -> 7 | F10: =VLOOKUP(VLOOKUP(G10,'Capacidade ALE'!A:F,5,0),'Capacidade ALE'!E:F,2,0) -> IPOJUCA | G10: =LARGE('Capacidade ALE'!A:A,Resumo!E10) -> 23877.26 | J10: =J9+1 -> 7 | K10: =VLOOKUP(L10,'Expedição Rodo - ALE'!B:E,4,0) -> GOIANIA | L10: =LARGE('Expedição Rodo - ALE'!B:B,Resumo!J10) -> 43701.667
A11: =A10+1 -> 8 | B11: =VLOOKUP(VLOOKUP(C11,'Recebimento Rodo - ALE'!E:H,4,0),'Recebimento Rodo - ALE'!$H:$I,2,0) -> LEM | C11: =LARGE('Recebimento Rodo - ALE'!E:E,Resumo!A11) -> 16344.922 | E11: =E10+1 -> 8 | F11: =VLOOKUP(VLOOKUP(G11,'Capacidade ALE'!A:F,5,0),'Capacidade ALE'!E:F,2,0) -> GOIANIA | G11: =LARGE('Capacidade ALE'!A:A,Resumo!E11) -> 21975.202 | J11: =J10+1 -> 8 | K11: =VLOOKUP(L11,'Expedição Rodo - ALE'!B:E,4,0) -> RONDONOPOLIS | L11: =LARGE('Expedição Rodo - ALE'!B:B,Resumo!J11) -> 37789
A12: =A11+1 -> 9 | B12: =VLOOKUP(VLOOKUP(C12,'Recebimento Rodo - ALE'!E:H,4,0),'Recebimento Rodo - ALE'!$H:$I,2,0) -> DUQUE DE CAXIAS | C12: =LARGE('Recebimento Rodo - ALE'!E:E,Resumo!A12) -> 13305.94 | E12: =E11+1 -> 9 | F12: =VLOOKUP(VLOOKUP(G12,'Capacidade ALE'!A:F,5,0),'Capacidade ALE'!E:F,2,0) -> SAO LUIS | G12: =LARGE('Capacidade ALE'!A:A,Resumo!E12) -> 21576.679 | J12: =J11+1 -> 9 | K12: =VLOOKUP(L12,'Expedição Rodo - ALE'!B:E,4,0) -> DUQUE DE CAXIAS | L12: =LARGE('Expedição Rodo - ALE'!B:B,Resumo!J12) -> 28176.811
A13: =A12+1 -> 10 | B13: =VLOOKUP(VLOOKUP(C13,'Recebimento Rodo - ALE'!E:H,4,0),'Recebimento Rodo - ALE'!$H:$I,2,0) -> RIBEIRAO PRETO | C13: =LARGE('Recebimento Rodo - ALE'!E:E,Resumo!A13) -> 12465.166 | E13: =E12+1 -> 10 | F13: =VLOOKUP(VLOOKUP(G13,'Capacidade ALE'!A:F,5,0),'Capacidade ALE'!E:F,2,0) -> BRASILIA | G13: =LARGE('Capacidade ALE'!A:A,Resumo!E13) -> 20512.8 | J13: =J12+1 -> 10 | K13: =VLOOKUP(L13,'Expedição Rodo - ALE'!B:E,4,0) -> ITAJAI | L13: =LARGE('Expedição Rodo - ALE'!B:B,Resumo!J13) -> 27588
A14: =A13+1 -> 11 | B14: =VLOOKUP(VLOOKUP(C14,'Recebimento Rodo - ALE'!E:H,4,0),'Recebimento Rodo - ALE'!$H:$I,2,0) -> PORTO NACIONAL | C14: =LARGE('Recebimento Rodo - ALE'!E:E,Resumo!A14) -> 12348.674 | E14: =E13+1 -> 11 | F14: =VLOOKUP(VLOOKUP(G14,'Capacidade ALE'!A:F,5,0),'Capacidade ALE'!E:F,2,0) -> CANOAS | G14: =LARGE('Capacidade ALE'!A:A,Resumo!E14) -> 17020.444 | J14: =J13+1 -> 11 | K14: =VLOOKUP(L14,'Expedição Rodo - ALE'!B:E,4,0) -> GUAMARE | L14: =LARGE('Expedição Rodo - ALE'!B:B,Resumo!J14) -> 26620.18
A15: =A14+1 -> 12 | B15: =VLOOKUP(VLOOKUP(C15,'Recebimento Rodo - ALE'!E:H,4,0),'Recebimento Rodo - ALE'!$H:$I,2,0) -> LAGES | C15: =LARGE('Recebimento Rodo - ALE'!E:E,Resumo!A15) -> 11410.543 | E15: =E14+1 -> 12 | F15: =VLOOKUP(VLOOKUP(G15,'Capacidade ALE'!A:F,5,0),'Capacidade ALE'!E:F,2,0) -> ARAUCARIA | G15: =LARGE('Capacidade ALE'!A:A,Resumo!E15) -> 11863.628 | J15: =J14+1 -> 12 | K15: =VLOOKUP(L15,'Expedição Rodo - ALE'!B:E,4,0) -> PORTO NACIONAL | L15: =LARGE('Expedição Rodo - ALE'!B:B,Resumo!J15) -> 24544
A16: =A15+1 -> 13 | B16: =VLOOKUP(VLOOKUP(C16,'Recebimento Rodo - ALE'!E:H,4,0),'Recebimento Rodo - ALE'!$H:$I,2,0) -> CANOAS | C16: =LARGE('Recebimento Rodo - ALE'!E:E,Resumo!A16) -> 11373.958 | E16: =E15+1 -> 13 | F16: =VLOOKUP(VLOOKUP(G16,'Capacidade ALE'!A:F,5,0),'Capacidade ALE'!E:F,2,0) -> CUIABA | G16: =LARGE('Capacidade ALE'!A:A,Resumo!E16) -> 10726.637 | J16: =J15+1 -> 13 | K16: =VLOOKUP(L16,'Expedição Rodo - ALE'!B:E,4,0) -> ARAUCARIA | L16: =LARGE('Expedição Rodo - ALE'!B:B,Resumo!J16) -> 21830
... A46: =A45+1 -> 43 | B46: =VLOOKUP(VLOOKUP(C46,'Recebimento Rodo - ALE'!E:H,4,0),'Recebimento Rodo - ALE'!$H:$I,2,0) -> RIO GRANDE | C46: =LARGE('Recebimento Rodo - ALE'!E:E,Resumo!A46) -> 1077.931 | E46: =E45+1 -> 43 | F46: =VLOOKUP(VLOOKUP(G46,'Capacidade ALE'!A:F,5,0),'Capacidade ALE'!E:F,2,0) -> ACAILANDIA | G46: =LARGE('Capacidade ALE'!A:A,Resumo!E46) -> 0 | J46: =J45+1 -> 43 | K46: =VLOOKUP(L46,'Expedição Rodo - ALE'!B:E,4,0) -> SARANDI | L46: =LARGE('Expedição Rodo - ALE'!B:B,Resumo!J46) -> 2304.1152
A52: 1 - Capacidades de movimentação, descarga, venda e expedição mensal
A58: 1.1 - Capacidades de venda mensal
A60: Tipo de Infraestrutura | B60: Capacidade de venda ALE (m³/mês) | C60: % | E60: Tipo de Infraestrutura | F60: Capacidade de venda ALE (m³/mês) | G60: %
A61: Própria e Pools | B61: =B62+B63 -> 446590.34 | C61: =B61/$B$66 -> 0.69230128 | E61: Própria | F61: =SUMIFS('Capacidade ALE'!E:E,'Capacidade ALE'!G:G,CONCATENATE(Resumo!E61,"Total")) -> 0 | G61: =F61/$B$89 -> 0
A62: Própria | B62: =SUMIFS('Capacidade ALE'!A:A,'Capacidade ALE'!C:C,CONCATENATE(Resumo!A62,"Total")) -> 268557.85 | C62: =B62/$B$66 -> 0.41631655 | E62: Pool | F62: =SUMIFS('Capacidade ALE'!A:A,'Capacidade ALE'!C:C,CONCATENATE(Resumo!E62,"Total")) -> 178032.48 | G62: =F62/$B$89 -> 0.39885965
A63: Pool | B63: =SUMIFS('Capacidade ALE'!A:A,'Capacidade ALE'!C:C,CONCATENATE(Resumo!A63,"Total")) -> 178032.48 | C63: =B63/$B$66 -> 0.27598474 | E63: Própria e Pools | F63: =F62+F61 -> 178032.48 | G63: =F63/$B$66 -> 0.27598474
A64: Terceiros | B64: =SUMIFS('Capacidade ALE'!A:A,'Capacidade ALE'!C:C,CONCATENATE(Resumo!A64,"Total")) -> 197228.8 | C64: =B64/$B$66 -> 0.30574274 | E64: Terceiros | F64: =SUMIFS('Capacidade ALE'!A:A,'Capacidade ALE'!C:C,CONCATENATE(Resumo!E64,"Total")) -> 197228.8 | G64: =F64/$B$66 -> 0.30574274
A65: Democrática | B65: =SUMIFS('Capacidade ALE'!A:A,'Capacidade ALE'!C:C,CONCATENATE(Resumo!A65,"Total")) -> 1261.7647 | C65: =B65/$B$66 -> 0.001955979 | E65: Democrática | F65: =SUMIFS('Capacidade ALE'!A:A,'Capacidade ALE'!C:C,CONCATENATE(Resumo!E65,"Total")) -> 1261.7647 | G65: =F65/$B$66 -> 0.001955979
A66: Total | B66: =SUM(B62:B65) -> 645080.9 | C66: =SUM(C62:C65) -> 1 | E66: Total | F66: =SUM(F63:F65) -> 376523.05 | G66: =SUM(G63:G65) -> 0.58368345
A76: As capacidades de venda consideram a variação de demanda, os recebimentos através de todos os modais, os intervalos de recebimento de cada par produto / base, a variabilidade de cada modal e as tancagens de cada filial deduzido as operações cedidas para terceiros nas bases próprias e Pools e as transferências para as filiais secundárias e terceárias.
A81: 1.2 - Capacidade de recebimento rodoviário
A83: Tipo de Infraestrutura | B83: Capacidade estimada de descarga RODO ALE (m³/mês) | C83: % | E83: Tipo de Infraestrutura | F83: Capacidade estimada de descarga RODO ALE (m³/mês) | G83: %
A84: Própria e Pools | B84: =B85+B86 -> 215999.74 | C84: =B84/$B$89 -> 0.48392057 | E84: Própria | F84: =SUMIFS('[234]Recebimento Rodo - ALE'!T:T,'[234]Recebimento Rodo - ALE'!J:J,CONCATENATE(Resumo!E84,"Total")) -> #VALUE! | G84: =F84/$B$89 -> #VALUE!
A85: Própria | B85: =SUMIFS('Recebimento Rodo - ALE'!P:P,'Recebimento Rodo - ALE'!F:F,CONCATENATE(Resumo!A85,"Total")) -> 141832.22 | C85: =B85/$B$89 -> 0.31775747 | E85: Pool | F85: =SUMIFS('[234]Recebimento Rodo - ALE'!T:T,'[234]Recebimento Rodo - ALE'!J:J,CONCATENATE(Resumo!E85,"Total")) -> #VALUE! | G85: =F85/$B$89 -> #VALUE!
A86: Pool | B86: =SUMIFS('Recebimento Rodo - ALE'!P:P,'Recebimento Rodo - ALE'!F:F,CONCATENATE(Resumo!A86,"Total")) -> 74167.517 | C86: =B86/$B$89 -> 0.1661631 | E86: Própria e Pools | F86: =F85+F84 -> #VALUE! | G86: =F86/$B$89 -> #VALUE!
A87: Terceiros | B87: =SUMIFS('Recebimento Rodo - ALE'!P:P,'Recebimento Rodo - ALE'!F:F,CONCATENATE(Resumo!A87,"Total")) -> 220521.04 | C87: =B87/$B$89 -> 0.49404998 | E87: Terceiros | F87: =SUMIFS('[234]Recebimento Rodo - ALE'!T:T,'[234]Recebimento Rodo - ALE'!J:J,CONCATENATE(Resumo!E87,"Total")) -> #VALUE! | G87: =F87/$B$89 -> #VALUE!
A88: Democrática | B88: =SUMIFS('Recebimento Rodo - ALE'!P:P,'Recebimento Rodo - ALE'!F:F,CONCATENATE(Resumo!A88,"Total")) -> 9832.9299 | C88: =B88/$B$89 -> 0.022029457 | E88: Democrática | F88: =SUMIFS('[234]Recebimento Rodo - ALE'!T:T,'[234]Recebimento Rodo - ALE'!J:J,CONCATENATE(Resumo!E88,"Total")) -> #VALUE! | G88: =F88/$B$89 -> #VALUE!
A89: Total | B89: =SUM(B85:B88) -> 446353.71 | C89: =SUM(C85:C88) -> 1 | E89: Total | F89: =SUM(F86:F88) -> #VALUE! | G89: =SUM(G86:G88) -> #VALUE!
A99: As capacidades de recebimento rodoviário refletem as seguintes condições: - Pools e Filiais Próprias: Nº de posições de descarga para cada produto, exclusiva ou compartilhada. - Operações em 3º's: Basicamente, por ordem de chegada e/ou nº de janelas disponibilizadas - Demais pontos: Capacidade média de CT por recebimento, distribuição da disponibilidade de recebimento entre os produtos de cada filial através da participação no Ale 738 ou no número de janelas disponibilizada por produto, deduzido às movimentações dos espaços cedidos para 3º's e considerando a participação ALE nos pools. - Dados e informações - Time de Operações
A106: 1.3 - Capacidade de expedição rodoviária
A108: Tipo de Infraestrutura | B108: Capacidade estimada de expedição RODO ALE (m³/mês) | C108: % | E108: Tipo de Infraestrutura | F108: Capacidade estimada de descarga RODO ALE (m³/mês) | G108: %
A109: Própria e Pools | B109: =B111+B110 -> 403137.65 | C109: =B109/$B$114 -> 0.48984397 | E109: Própria e Pools | F109: =F111+F110 -> #VALUE! | G109: =F109/$B$89 -> #VALUE!
A110: Própria | B110: =SUMIFS('Expedição Rodo - ALE'!H:H,'Expedição Rodo - ALE'!C:C,Resumo!A110) -> 241428.97 | C110: =B110/$B$114 -> 0.2933552 | E110: Própria | F110: =SUMIFS('[234]Recebimento Rodo - ALE'!T:T,'[234]Recebimento Rodo - ALE'!J:J,CONCATENATE(Resumo!E110,"Total")) -> #VALUE! | G110: =F110/$B$89 -> #VALUE!
A111: Pool | B111: =SUMIFS('Expedição Rodo - ALE'!H:H,'Expedição Rodo - ALE'!C:C,Resumo!A111) -> 161708.68 | C111: =B111/$B$114 -> 0.19648877 | E111: Pool | F111: =SUMIFS('[234]Recebimento Rodo - ALE'!T:T,'[234]Recebimento Rodo - ALE'!J:J,CONCATENATE(Resumo!E111,"Total")) -> #VALUE! | G111: =F111/$B$89 -> #VALUE!
...

Sheet Capacidade ALE
A1: 1 - Capacidade de venda mensal | E1: 1 - Capacidades de movimentação, descarga, venda e expedição mensal
E4: Código Da Base | F4: Unidade | G4: Produto | I4: Tancagem disponível para Movimentação (m³) | K4: Capacidade mensal de recebimento rodoviário (m³) | L4: Capacidade de Mensal de movimentação (m³) | N4: Produto Misturado | O4: Capacidade de Mensal de venda (m³) | P4: Capacidade mensal de Expedição rodoviária (m³) | Q4: Observações | S4: Produto Misturado | T4: Venda Média Mensal (m³) - 6 meses | U4: Venda Média Mensal (m³) - 12 meses
A5: =IF(RIGHT(F5,5)="Total",O5,0) -> 0 | B5: =RIGHT(F5,5) -> ANDIA | C5: =CONCATENATE(D5,RIGHT(F5,5)) -> TerceirosANDIA | D5: Terceiros | E5: 33 | F5: ACAILANDIA | G5: B100 | I5: =IF(RIGHT(F5,5)="Total",VLOOKUP(F5,'BD Cap Venda ALE'!$D:$K,4,0),SUMIFS('BD Cap Venda ALE'!G:G,'BD Cap Venda ALE'!E:E,'Capacidade ALE'!G5,'BD Cap Venda ALE'!C:C,'Capacidade ALE'!E5)) -> 45 | K5: =IF(RIGHT(F5,5)="Total",VLOOKUP(F5,'Recebimento Rodo - ALE'!$I:$P,8,0),SUMIFS('Recebimento Rodo - ALE'!P:P,'Recebimento Rodo - ALE'!I:I,'Capacidade ALE'!F5,'Recebimento Rodo - ALE'!K:K,'Capacidade ALE'!G5)) -> 163.39286 | L5: =IF(RIGHT(F5,5)="Total",VLOOKUP(F5,'BD Cap Venda ALE'!$D:$K,5,0),SUMIFS('BD Cap Venda ALE'!H:H,'BD Cap Venda ALE'!E:E,'Capacidade ALE'!G5,'BD Cap Venda ALE'!C:C,'Capacidade ALE'!E5)) -> 154.28571 | O5: =IF(RIGHT(F5,5)="Total",VLOOKUP(F5,'BD Cap Venda ALE'!$D:$K,8,0),SUMIFS('BD Cap Venda ALE'!K:K,'BD Cap Venda ALE'!E:E,'Capacidade ALE'!G5,'BD Cap Venda ALE'!C:C,'Capacidade ALE'!E5)) -> 0 | P5: =IF(RIGHT(F5,5)="Total",VLOOKUP(F5,'Expedição Rodo - ALE'!$A:$H,8,0),"") | Q5: =IF(P11<O11,"capacidade de expedição rodoviária abaixo da capacidade de venda mensal, prevalece a capacidade de venda mensal em virtude do terminal ter a obrigatoriedade de garantia do giro dos espaços contratados em linha com a logística da filial.","") | T5: =IFERROR(SUMIFS('BD Cap Venda ALE'!M:M,'BD Cap Venda ALE'!E:E,'Capacidade ALE'!G5,'BD Cap Venda ALE'!C:C,'Capacidade ALE'!E5),0) -> 61.316667 | U5: =IFERROR(SUMIFS('BD Cap Venda ALE'!N:N,'BD Cap Venda ALE'!E:E,'Capacidade ALE'!G5,'BD Cap Venda ALE'!C:C,'Capacidade ALE'!E5),0) -> 57.816667
A6: =IF(RIGHT(F6,5)="Total",O6,0) -> 0 | B6: =RIGHT(F6,5) -> ANDIA | C6: =CONCATENATE(D6,RIGHT(F6,5)) -> TerceirosANDIA | D6: Terceiros | E6: 33 | F6: ACAILANDIA | G6: Diesel A S10 | I6: =IF(RIGHT(F6,5)="Total",VLOOKUP(F6,'BD Cap Venda ALE'!$D:$K,4,0),SUMIFS('BD Cap Venda ALE'!G:G,'BD Cap Venda ALE'!E:E,'Capacidade ALE'!G6,'BD Cap Venda ALE'!C:C,'Capacidade ALE'!E6)) -> 5 | K6: =IF(RIGHT(F6,5)="Total",VLOOKUP(F6,'Recebimento Rodo - ALE'!$I:$P,8,0),SUMIFS('Recebimento Rodo - ALE'!P:P,'Recebimento Rodo - ALE'!I:I,'Capacidade ALE'!F6,'Recebimento Rodo - ALE'!K:K,'Capacidade ALE'!G6)) -> 12.708333 | L6: =IF(RIGHT(F6,5)="Total",VLOOKUP(F6,'BD Cap Venda ALE'!$D:$K,5,0),SUMIFS('BD Cap Venda ALE'!H:H,'BD Cap Venda ALE'!E:E,'Capacidade ALE'!G6,'BD Cap Venda ALE'!C:C,'Capacidade ALE'!E6)) -> 40 | N6: Diesel B S10 | O6: =IF(RIGHT(F6,5)="Total",VLOOKUP(F6,'BD Cap Venda ALE'!$D:$K,8,0),SUMIFS('BD Cap Venda ALE'!K:K,'BD Cap Venda ALE'!E:E,'Capacidade ALE'!G6,'BD Cap Venda ALE'!C:C,'Capacidade ALE'!E6)) -> 41.474654 | P6: =IF(RIGHT(F6,5)="Total",VLOOKUP(F6,'Expedição Rodo - ALE'!$A:$H,8,0),"") | S6: Diesel B S10 | T6: =IFERROR(SUMIFS('BD Cap Venda ALE'!M:M,'BD Cap Venda ALE'!E:E,'Capacidade ALE'!G6,'BD Cap Venda ALE'!C:C,'Capacidade ALE'!E6),0) -> 285.75 | U6: =IFERROR(SUMIFS('BD Cap Venda ALE'!N:N,'BD Cap Venda ALE'!E:E,'Capacidade ALE'!G6,'BD Cap Venda ALE'!C:C,'Capacidade ALE'!E6),0) -> 260.4
A7: =IF(RIGHT(F7,5)="Total",O7,0) -> 0 | B7: =RIGHT(F7,5) -> ANDIA | C7: =CONCATENATE(D7,RIGHT(F7,5)) -> TerceirosANDIA | D7: Terceiros | E7: 33 | F7: ACAILANDIA | G7: Diesel A S500 | I7: =IF(RIGHT(F7,5)="Total",VLOOKUP(F7,'BD Cap Venda ALE'!$D:$K,4,0),SUMIFS('BD Cap Venda ALE'!G:G,'BD Cap Venda ALE'!E:E,'Capacidade ALE'!G7,'BD Cap Venda ALE'!C:C,'Capacidade ALE'!E7)) -> 150 | K7: =IF(RIGHT(F7,5)="Total",VLOOKUP(F7,'Recebimento Rodo - ALE'!$I:$P,8,0),SUMIFS('Recebimento Rodo - ALE'!P:P,'Recebimento Rodo - ALE'!I:I,'Capacidade ALE'!F7,'Recebimento Rodo - ALE'!K:K,'Capacidade ALE'!G7)) -> 381.25 | L7: =IF(RIGHT(F7,5)="Total",VLOOKUP(F7,'BD Cap Venda ALE'!$D:$K,5,0),SUMIFS('BD Cap Venda ALE'!H:H,'BD Cap Venda ALE'!E:E,'Capacidade ALE'!G7,'BD Cap Venda ALE'!C:C,'Capacidade ALE'!E7)) -> 1200 | N7: Diesel B S500 | O7: =IF(RIGHT(F7,5)="Total",VLOOKUP(F7,'BD Cap Venda ALE'!$D:$K,8,0),SUMIFS('BD Cap Venda ALE'!K:K,'BD Cap Venda ALE'!E:E,'Capacidade ALE'!G7,'BD Cap Venda ALE'!C:C,'Capacidade ALE'!E7)) -> 1244.2396 | P7: =P11 -> 4158 | S7: Diesel B S500 | T7: =IFERROR(SUMIFS('BD Cap Venda ALE'!M:M,'BD Cap Venda ALE'!E:E,'Capacidade ALE'!G7,'BD Cap Venda ALE'!C:C,'Capacidade ALE'!E7),0) -> 266.1 | U7: =IFERROR(SUMIFS('BD Cap Venda ALE'!N:N,'BD Cap Venda ALE'!E:E,'Capacidade ALE'!G7,'BD Cap Venda ALE'!C:C,'Capacidade ALE'!E7),0) -> 259.95
A8: =IF(RIGHT(F8,5)="Total",O8,0) -> 0 | B8: =RIGHT(F8,5) -> ANDIA | C8: =CONCATENATE(D8,RIGHT(F8,5)) -> TerceirosANDIA | D8: Terceiros | E8: 33 | F8: ACAILANDIA | G8: Etanol Anidro | I8: =IF(RIGHT(F8,5)="Total",VLOOKUP(F8,'BD Cap Venda ALE'!$D:$K,4,0),SUMIFS('BD Cap Venda ALE'!G:G,'BD Cap Venda ALE'!E:E,'Capacidade ALE'!G8,'BD Cap Venda ALE'!C:C,'Capacidade ALE'!E8)) -> 60 | K8: =IF(RIGHT(F8,5)="Total",VLOOKUP(F8,'Recebimento Rodo - ALE'!$I:$P,8,0),SUMIFS('Recebimento Rodo - ALE'!P:P,'Recebimento Rodo - ALE'!I:I,'Capacidade ALE'!F8,'Recebimento Rodo - ALE'!K:K,'Capacidade ALE'!G8)) -> 508.33333 | L8: =IF(RIGHT(F8,5)="Total",VLOOKUP(F8,'BD Cap Venda ALE'!$D:$K,5,0),SUMIFS('BD Cap Venda ALE'!H:H,'BD Cap Venda ALE'!E:E,'Capacidade ALE'!G8,'BD Cap Venda ALE'!C:C,'Capacidade ALE'!E8)) -> 480 | O8: =IF(RIGHT(F8,5)="Total",VLOOKUP(F8,'BD Cap Venda ALE'!$D:$K,8,0),SUMIFS('BD Cap Venda ALE'!K:K,'BD Cap Venda ALE'!E:E,'Capacidade ALE'!G8,'BD Cap Venda ALE'!C:C,'Capacidade ALE'!E8)) -> 0 | P8: =IF(RIGHT(F8,5)="Total",VLOOKUP(F8,'Expedição Rodo - ALE'!$A:$H,8,0),"") | T8: =IFERROR(SUMIFS('BD Cap Venda ALE'!M:M,'BD Cap Venda ALE'!E:E,'Capacidade ALE'!G8,'BD Cap Venda ALE'!C:C,'Capacidade ALE'!E8),0) -> 177.03 | U8: =IFERROR(SUMIFS('BD Cap Venda ALE'!N:N,'BD Cap Venda ALE'!E:E,'Capacidade ALE'!G8,'BD Cap Venda ALE'!C:C,'Capacidade ALE'!E8),0) -> 147.5775
A9: =IF(RIGHT(F9,5)="Total",O9,0) -> 0 | B9: =RIGHT(F9,5) -> ANDIA | C9: =CONCATENATE(D9,RIGHT(F9,5)) -> TerceirosANDIA | D9: Terceiros | E9: 33 | F9: ACAILANDIA | G9: Etanol Hidratado | I9: =IF(RIGHT(F9,5)="Total",VLOOKUP(F9,'BD Cap Venda ALE'!$D:$K,4,0),SUMIFS('BD Cap Venda ALE'!G:G,'BD Cap Venda ALE'!E:E,'Capacidade ALE'!G9,'BD Cap Venda ALE'!C:C,'Capacidade ALE'!E9)) -> 0 | K9: =IF(RIGHT(F9,5)="Total",VLOOKUP(F9,'Recebimento Rodo - ALE'!$I:$P,8,0),SUMIFS('Recebimento Rodo - ALE'!P:P,'Recebimento Rodo - ALE'!I:I,'Capacidade ALE'!F9,'Recebimento Rodo - ALE'!K:K,'Capacidade ALE'!G9)) -> 0 | L9: =IF(RIGHT(F9,5)="Total",VLOOKUP(F9,'BD Cap Venda ALE'!$D:$K,5,0),SUMIFS('BD Cap Venda ALE'!H:H,'BD Cap Venda ALE'!E:E,'Capacidade ALE'!G9,'BD Cap Venda ALE'!C:C,'Capacidade ALE'!E9)) -> 0 | N9: Álcool | O9: =IF(RIGHT(F9,5)="Total",VLOOKUP(F9,'BD Cap Venda ALE'!$D:$K,8,0),SUMIFS('BD Cap Venda ALE'!K:K,'BD Cap Venda ALE'!E:E,'Capacidade ALE'!G9,'BD Cap Venda ALE'!C:C,'Capacidade ALE'!E9)) -> 0 | P9: =IF(RIGHT(F9,5)="Total",VLOOKUP(F9,'Expedição Rodo - ALE'!$A:$H,8,0),"") | S9: Álcool | T9: =IFERROR(SUMIFS('BD Cap Venda ALE'!M:M,'BD Cap Venda ALE'!E:E,'Capacidade ALE'!G9,'BD Cap Venda ALE'!C:C,'Capacidade ALE'!E9),0) -> 0 | U9: =IFERROR(SUMIFS('BD Cap Venda ALE'!N:N,'BD Cap Venda ALE'!E:E,'Capacidade ALE'!G9,'BD Cap Venda ALE'!C:C,'Capacidade ALE'!E9),0) -> 0
A10: =IF(RIGHT(F10,5)="Total",O10,0) -> 0 | B10: =RIGHT(F10,5) -> ANDIA | C10: =CONCATENATE(D10,RIGHT(F10,5)) -> TerceirosANDIA | D10: Terceiros | E10: 33 | F10: ACAILANDIA | G10: Gasolina A | I10: =IF(RIGHT(F10,5)="Total",VLOOKUP(F10,'BD Cap Venda ALE'!$D:$K,4,0),SUMIFS('BD Cap Venda ALE'!G:G,'BD Cap Venda ALE'!E:E,'Capacidade ALE'!G10,'BD Cap Venda ALE'!C:C,'Capacidade ALE'!E10)) -> 150 | K10: =IF(RIGHT(F10,5)="Total",VLOOKUP(F10,'Recebimento Rodo - ALE'!$I:$P,8,0),SUMIFS('Recebimento Rodo - ALE'!P:P,'Recebimento Rodo - ALE'!I:I,'Capacidade ALE'!F10,'Recebimento Rodo - ALE'!K:K,'Capacidade ALE'!G10)) -> 381.25 | L10: =IF(RIGHT(F10,5)="Total",VLOOKUP(F10,'BD Cap Venda ALE'!$D:$K,5,0),SUMIFS('BD Cap Venda ALE'!H:H,'BD Cap Venda ALE'!E:E,'Capacidade ALE'!G10,'BD Cap Venda ALE'!C:C,'Capacidade ALE'!E10)) -> 1200 | N10: Gasolina C | O10: =IF(RIGHT(F10,5)="Total",VLOOKUP(F10,'BD Cap Venda ALE'!$D:$K,8,0),SUMIFS('BD Cap Venda ALE'!K:K,'BD Cap Venda ALE'!E:E,'Capacidade ALE'!G10,'BD Cap Venda ALE'!C:C,'Capacidade ALE'!E10)) -> 1643.8356 | P10: =IF(RIGHT(F10,5)="Total",VLOOKUP(F10,'Expedição Rodo - ALE'!$A:$H,8,0),"") | S10: Gasolina C | T10: =IFERROR(SUMIFS('BD Cap Venda ALE'!M:M,'BD Cap Venda ALE'!E:E,'Capacidade ALE'!G10,'BD Cap Venda ALE'!C:C,'Capacidade ALE'!E10),0) -> 478.63667 | U10: =IFERROR(SUMIFS('BD Cap Venda ALE'!N:N,'BD Cap Venda ALE'!E:E,'Capacidade ALE'!G10,'BD Cap Venda ALE'!C:C,'Capacidade ALE'!E10),0) -> 399.00583
A11: =IF(RIGHT(F11,5)="Total",O11,0) -> 2929.5499 | B11: =RIGHT(F11,5) -> Total | C11: =CONCATENATE(D11,RIGHT(F11,5)) -> TerceirosTotal | D11: Terceiros | E11: 33 | F11: ACAILANDIA Total | I11: =IF(RIGHT(F11,5)="Total",VLOOKUP(F11,'BD Cap Venda ALE'!$D:$K,4,0),SUMIFS('BD Cap Venda ALE'!G:G,'BD Cap Venda ALE'!E:E,'Capacidade ALE'!G11,'BD Cap Venda ALE'!C:C,'Capacidade ALE'!E11)) -> 410 | K11: =IF(RIGHT(F11,5)="Total",VLOOKUP(F11,'Recebimento Rodo - ALE'!$I:$P,8,0),SUMIFS('Recebimento Rodo - ALE'!P:P,'Recebimento Rodo - ALE'!I:I,'Capacidade ALE'!F11,'Recebimento Rodo - ALE'!K:K,'Capacidade ALE'!G11)) -> 1446.9345 | L11: =IF(RIGHT(F11,5)="Total",VLOOKUP(F11,'BD Cap Venda ALE'!$D:$K,5,0),SUMIFS('BD Cap Venda ALE'!H:H,'BD Cap Venda ALE'!E:E,'Capacidade ALE'!G11,'BD Cap Venda ALE'!C:C,'Capacidade ALE'!E11)) -> 3074.2857 | O11: =IF(RIGHT(F11,5)="Total",VLOOKUP(F11,'BD Cap Venda ALE'!$D:$K,8,0),SUMIFS('BD Cap Venda ALE'!K:K,'BD Cap Venda ALE'!E:E,'Capacidade ALE'!G11,'BD Cap Venda ALE'!C:C,'Capacidade ALE'!E11)) -> 2929.5499 | P11: =IF(RIGHT(F11,5)="Total",VLOOKUP(F11,'Expedição Rodo - ALE'!$A:$H,8,0),"") -> 4158 | T11: =IFERROR(SUMIFS('BD Cap Venda ALE'!M:M,'BD Cap Venda ALE'!E:E,'Capacidade ALE'!G11,'BD Cap Venda ALE'!C:C,'Capacidade ALE'!E11),0) -> 0 | U11: =IFERROR(SUMIFS('BD Cap Venda ALE'!N:N,'BD Cap Venda ALE'!E:E,'Capacidade ALE'!G11,'BD Cap Venda ALE'!C:C,'Capacidade ALE'!E11),0) -> 0
A12: =IF(RIGHT(F12,5)="Total",O12,0) -> 0 | B12: =RIGHT(F12,5) -> CARIA | C12: =CONCATENATE(D12,RIGHT(F12,5)) -> TerceirosCARIA | D12: Terceiros | E12: 18 | F12: ARAUCARIA | G12: B100 | I12: =IF(RIGHT(F12,5)="Total",VLOOKUP(F12,'BD Cap Venda ALE'!$D:$K,4,0),SUMIFS('BD Cap Venda ALE'!G:G,'BD Cap Venda ALE'!E:E,'Capacidade ALE'!G12,'BD Cap Venda ALE'!C:C,'Capacidade ALE'!E12)) -> 110 | K12: =IF(RIGHT(F12,5)="Total",VLOOKUP(F12,'Recebimento Rodo - ALE'!$I:$P,8,0),SUMIFS('Recebimento Rodo - ALE'!P:P,'Recebimento Rodo - ALE'!I:I,'Capacidade ALE'!F12,'Recebimento Rodo - ALE'!K:K,'Capacidade ALE'!G12)) -> 1397.9167 | L12: =IF(RIGHT(F12,5)="Total",VLOOKUP(F12,'BD Cap Venda ALE'!$D:$K,5,0),SUMIFS('BD Cap Venda ALE'!H:H,'BD Cap Venda ALE'!E:E,'Capacidade ALE'!G12,'BD Cap Venda ALE'!C:C,'Capacidade ALE'!E12)) -> 1320 | O12: =IF(RIGHT(F12,5)="Total",VLOOKUP(F12,'BD Cap Venda ALE'!$D:$K,8,0),SUMIFS('BD Cap Venda ALE'!K:K,'BD Cap Venda ALE'!E:E,'Capacidade ALE'!G12,'BD Cap Venda ALE'!C:C,'Capacidade ALE'!E12)) -> 0 | P12: =IF(RIGHT(F12,5)="Total",VLOOKUP(F12,'Expedição Rodo - ALE'!$A:$H,8,0),"") | Q12: =IF(P18<O18,"capacidade de expedição rodoviária abaixo da capacidade de venda mensal, prevalece a capacidade de venda mensal em virtude do terminal ter a obrigatoriedade de garantia do giro dos espaços contratados em linha com a logística da filial.","") | T12: =IFERROR(SUMIFS('BD Cap Venda ALE'!M:M,'BD Cap Venda ALE'!E:E,'Capacidade ALE'!G12,'BD Cap Venda ALE'!C:C,'Capacidade ALE'!E12),0) -> 196.53333 | U12: =IFERROR(SUMIFS('BD Cap Venda ALE'!N:N,'BD Cap Venda ALE'!E:E,'Capacidade ALE'!G12,'BD Cap Venda ALE'!C:C,'Capacidade ALE'!E12),0) -> 197.49167
A13: =IF(RIGHT(F13,5)="Total",O13,0) -> 0 | B13: =RIGHT(F13,5) -> CARIA | C13: =CONCATENATE(D13,RIGHT(F13,5)) -> TerceirosCARIA | D13: Terceiros | E13: 18 | F13: ARAUCARIA | G13: Diesel A S10 | I13: =IF(RIGHT(F13,5)="Total",VLOOKUP(F13,'BD Cap Venda ALE'!$D:$K,4,0),SUMIFS('BD Cap Venda ALE'!G:G,'BD Cap Venda ALE'!E:E,'Capacidade ALE'!G13,'BD Cap Venda ALE'!C:C,'Capacidade ALE'!E13)) -> 220 | K13: =IF(RIGHT(F13,5)="Total",VLOOKUP(F13,'Recebimento Rodo - ALE'!$I:$P,8,0),SUMIFS('Recebimento Rodo - ALE'!P:P,'Recebimento Rodo - ALE'!I:I,'Capacidade ALE'!F13,'Recebimento Rodo - ALE'!K:K,'Capacidade ALE'!G13)) -> 838.75 | L13: =IF(RIGHT(F13,5)="Total",VLOOKUP(F13,'BD Cap Venda ALE'!$D:$K,5,0),SUMIFS('BD Cap Venda ALE'!H:H,'BD Cap Venda ALE'!E:E,'Capacidade ALE'!G13,'BD Cap Venda ALE'!C:C,'Capacidade ALE'!E13)) -> 2640 | N13: Diesel B S10 | O13: =IF(RIGHT(F13,5)="Total",VLOOKUP(F13,'BD Cap Venda ALE'!$D:$K,8,0),SUMIFS('BD Cap Venda ALE'!K:K,'BD Cap Venda ALE'!E:E,'Capacidade ALE'!G13,'BD Cap Venda ALE'!C:C,'Capacidade ALE'!E13)) -> 2391.4494 | P13: =IF(RIGHT(F13,5)="Total",VLOOKUP(F13,'Expedição Rodo - ALE'!$A:$H,8,0),"") | S13: Diesel B S10 | T13: =IFERROR(SUMIFS('BD Cap Venda ALE'!M:M,'BD Cap Venda ALE'!E:E,'Capacidade ALE'!G13,'BD Cap Venda ALE'!C:C,'Capacidade ALE'!E13),0) -> 1904.95 | U13: =IFERROR(SUMIFS('BD Cap Venda ALE'!N:N,'BD Cap Venda ALE'!E:E,'Capacidade ALE'!G13,'BD Cap Venda ALE'!C:C,'Capacidade ALE'!E13),0) -> 1647.1167
A14: =IF(RIGHT(F14,5)="Total",O14,0) -> 0 | B14: =RIGHT(F14,5) -> CARIA | C14: =CONCATENATE(D14,RIGHT(F14,5)) -> TerceirosCARIA | D14: Terceiros | E14: 18 | F14: ARAUCARIA | G14: Diesel A S500 | I14: =IF(RIGHT(F14,5)="Total",VLOOKUP(F14,'BD Cap Venda ALE'!$D:$K,4,0),SUMIFS('BD Cap Venda ALE'!G:G,'BD Cap Venda ALE'!E:E,'Capacidade ALE'!G14,'BD Cap Venda ALE'!C:C,'Capacidade ALE'!E14)) -> 360 | K14: =IF(RIGHT(F14,5)="Total",VLOOKUP(F14,'Recebimento Rodo - ALE'!$I:$P,8,0),SUMIFS('Recebimento Rodo - ALE'!P:P,'Recebimento Rodo - ALE'!I:I,'Capacidade ALE'!F14,'Recebimento Rodo - ALE'!K:K,'Capacidade ALE'!G14)) -> 1372.5 | L14: =IF(RIGHT(F14,5)="Total",VLOOKUP(F14,'BD Cap Venda ALE'!$D:$K,5,0),SUMIFS('BD Cap Venda ALE'!H:H,'BD Cap Venda ALE'!E:E,'Capacidade ALE'!G14,'BD Cap Venda ALE'!C:C,'Capacidade ALE'!E14)) -> 4320 | N14: Diesel B S500 | O14: =IF(RIGHT(F14,5)="Total",VLOOKUP(F14,'BD Cap Venda ALE'!$D:$K,8,0),SUMIFS('BD Cap Venda ALE'!K:K,'BD Cap Venda ALE'!E:E,'Capacidade ALE'!G14,'BD Cap Venda ALE'!C:C,'Capacidade ALE'!E14)) -> 4302.7225 | P14: =IF(RIGHT(F14,5)="Total",VLOOKUP(F14,'Expedição Rodo - ALE'!$A:$H,8,0),"") | S14: Diesel B S500 | T14: =IFERROR(SUMIFS('BD Cap Venda ALE'!M:M,'BD Cap Venda ALE'!E:E,'Capacidade ALE'!G14,'BD Cap Venda ALE'!C:C,'Capacidade ALE'!E14),0) -> 768.18333 | U14: =IFERROR(SUMIFS('BD Cap Venda ALE'!N:N,'BD Cap Venda ALE'!E:E,'Capacidade ALE'!G14,'BD Cap Venda ALE'!C:C,'Capacidade ALE'!E14),0) -> 724.225
A15: =IF(RIGHT(F15,5)="Total",O15,0) -> 0 | B15: =RIGHT(F15,5) -> CARIA | C15: =CONCATENATE(D15,RIGHT(F15,5)) -> TerceirosCARIA | D15: Terceiros | E15: 18 | F15: ARAUCARIA | G15: Diesel Marítimo | I15: =IF(RIGHT(F15,5)="Total",VLOOKUP(F15,'BD Cap Venda ALE'!$D:$K,4,0),SUMIFS('BD Cap Venda ALE'!G:G,'BD Cap Venda ALE'!E:E,'Capacidade ALE'!G15,'BD Cap Venda ALE'!C:C,'Capacidade ALE'!E15)) -> 0 | K15: =IF(RIGHT(F15,5)="Total",VLOOKUP(F15,'Recebimento Rodo - ALE'!$I:$P,8,0),SUMIFS('Recebimento Rodo - ALE'!P:P,'Recebimento Rodo - ALE'!I:I,'Capacidade ALE'!F15,'Recebimento Rodo - ALE'!K:K,'Capacidade ALE'!G15)) -> 0 | L15: =IF(RIGHT(F15,5)="Total",VLOOKUP(F15,'BD Cap Venda ALE'!$D:$K,5,0),SUMIFS('BD Cap Venda ALE'!H:H,'BD Cap Venda ALE'!E:E,'Capacidade ALE'!G15,'BD Cap Venda ALE'!C:C,'Capacidade ALE'!E15)) -> 0 | N15: Diesel Marítimo | O15: =IF(RIGHT(F15,5)="Total",VLOOKUP(F15,'BD Cap Venda ALE'!$D:$K,8,0),SUMIFS('BD Cap Venda ALE'!K:K,'BD Cap Venda ALE'!E:E,'Capacidade ALE'!G15,'BD Cap Venda ALE'!C:C,'Capacidade ALE'!E15)) -> 0 | P15: =P19 -> 21830 | S15: Diesel Marítimo | T15: =IFERROR(SUMIFS('BD Cap Venda ALE'!M:M,'BD Cap Venda ALE'!E:E,'Capacidade ALE'!G15,'BD Cap Venda ALE'!C:C,'Capacidade ALE'!E15),0) -> 509.66667 | U15: =IFERROR(SUMIFS('BD Cap Venda ALE'!N:N,'BD Cap Venda ALE'!E:E,'Capacidade ALE'!G15,'BD Cap Venda ALE'!C:C,'Capacidade ALE'!E15),0) -> 467.58333
A16: =IF(RIGHT(F16,5)="Total",O16,0) -> 0 | B16: =RIGHT(F16,5) -> CARIA | C16: =CONCATENATE(D16,RIGHT(F16,5)) -> TerceirosCARIA | D16: Terceiros | E16: 18 | F16: ARAUCARIA | G16: Etanol Anidro | I16: =IF(RIGHT(F16,5)="Total",VLOOKUP(F16,'BD Cap Venda ALE'!$D:$K,4,0),SUMIFS('BD Cap Venda ALE'!G:G,'BD Cap Venda ALE'!E:E,'Capacidade ALE'!G16,'BD Cap Venda ALE'!C:C,'Capacidade ALE'!E16)) -> 150 | K16: =IF(RIGHT(F16,5)="Total",VLOOKUP(F16,'Recebimento Rodo - ALE'!$I:$P,8,0),SUMIFS('Recebimento Rodo - ALE'!P:P,'Recebimento Rodo - ALE'!I:I,'Capacidade ALE'!F16,'Recebimento Rodo - ALE'!K:K,'Capacidade ALE'!G16)) -> 1906.25 | L16: =IF(RIGHT(F16,5)="Total",VLOOKUP(F16,'BD Cap Venda ALE'!$D:$K,5,0),SUMIFS('BD Cap Venda ALE'!H:H,'BD Cap Venda ALE'!E:E,'Capacidade ALE'!G16,'BD Cap Venda ALE'!C:C,'Capacidade ALE'!E16)) -> 1800 | O16: =IF(RIGHT(F16,5)="Total",VLOOKUP(F16,'BD Cap Venda ALE'!$D:$K,8,0),SUMIFS('BD Cap Venda ALE'!K:K,'BD Cap Venda ALE'!E:E,'Capacidade ALE'!G16,'BD Cap Venda ALE'!C:C,'Capacidade ALE'!E16)) -> 0 | P16: =IF(RIGHT(F16,5)="Total",VLOOKUP(F16,'Expedição Rodo - ALE'!$A:$H,8,0),"") | T16: =IFERROR(SUMIFS('BD Cap Venda ALE'!M:M,'BD Cap Venda ALE'!E:E,'Capacidade ALE'!G16,'BD Cap Venda ALE'!C:C,'Capacidade ALE'!E16),0) -> 415.17333 | U16: =IFERROR(SUMIFS('BD Cap Venda ALE'!N:N,'BD Cap Venda ALE'!E:E,'Capacidade ALE'!G16,'BD Cap Venda ALE'!C:C,'Capacidade ALE'!E16),0) -> 384.76667
A17: =IF(RIGHT(F17,5)="Total",O17,0) -> 0 | B17: =RIGHT(F17,5) -> CARIA | C17: =CONCATENATE(D17,RIGHT(F17,5)) -> TerceirosCARIA | D17: Terceiros | E17: 18 | F17: ARAUCARIA | G17: Etanol Hidratado | I17: =IF(RIGHT(F17,5)="Total",VLOOKUP(F17,'BD Cap Venda ALE'!$D:$K,4,0),SUMIFS('BD Cap Venda ALE'!G:G,'BD Cap Venda ALE'!E:E,'Capacidade ALE'!G17,'BD Cap Venda ALE'!C:C,'Capacidade ALE'!E17)) -> 130 | K17: =IF(RIGHT(F17,5)="Total",VLOOKUP(F17,'Recebimento Rodo - ALE'!$I:$P,8,0),SUMIFS('Recebimento Rodo - ALE'!P:P,'Recebimento Rodo - ALE'!I:I,'Capacidade ALE'!F17,'Recebimento Rodo - ALE'!K:K,'Capacidade ALE'!G17)) -> 1652.0833 | L17: =IF(RIGHT(F17,5)="Total",VLOOKUP(F17,'BD Cap Venda ALE'!$D:$K,5,0),SUMIFS('BD Cap Venda ALE'!H:H,'BD Cap Venda ALE'!E:E,'Capacidade ALE'!G17,'BD Cap Venda ALE'!C:C,'Capacidade ALE'!E17)) -> 1560 | N17: Álcool | O17: =IF(RIGHT(F17,5)="Total",VLOOKUP(F17,'BD Cap Venda ALE'!$D:$K,8,0),SUMIFS('BD Cap Venda ALE'!K:K,'BD Cap Venda ALE'!E:E,'Capacidade ALE'!G17,'BD Cap Venda ALE'!C:C,'Capacidade ALE'!E17)) -> 1560 | P17: =IF(RIGHT(F17,5)="Total",VLOOKUP(F17,'Expedição Rodo - ALE'!$A:$H,8,0),"") | S17: Álcool | T17: =IFERROR(SUMIFS('BD Cap Venda ALE'!M:M,'BD Cap Venda ALE'!E:E,'Capacidade ALE'!G17,'BD Cap Venda ALE'!C:C,'Capacidade ALE'!E17),0) -> 183 | U17: =IFERROR(SUMIFS('BD Cap Venda ALE'!N:N,'BD Cap Venda ALE'!E:E,'Capacidade ALE'!G17,'BD Cap Venda ALE'!C:C,'Capacidade ALE'!E17),0) -> 177.83333
A18: =IF(RIGHT(F18,5)="Total",O18,0) -> 0 | B18: =RIGHT(F18,5) -> CARIA | C18: =CONCATENATE(D18,RIGHT(F18,5)) -> TerceirosCARIA | D18: Terceiros | E18: 18 | F18: ARAUCARIA | G18: Gasolina A | I18: =IF(RIGHT(F18,5)="Total",VLOOKUP(F18,'BD Cap Venda ALE'!$D:$K,4,0),SUMIFS('BD Cap Venda ALE'!G:G,'BD Cap Venda ALE'!E:E,'Capacidade ALE'!G18,'BD Cap Venda ALE'!C:C,'Capacidade ALE'!E18)) -> 280 | K18: =IF(RIGHT(F18,5)="Total",VLOOKUP(F18,'Recebimento Rodo - ALE'!$I:$P,8,0),SUMIFS('Recebimento Rodo - ALE'!P:P,'Recebimento Rodo - ALE'!I:I,'Capacidade ALE'!F18,'Recebimento Rodo - ALE'!K:K,'Capacidade ALE'!G18)) -> 1067.5 | L18: =IF(RIGHT(F18,5)="Total",VLOOKUP(F18,'BD Cap Venda ALE'!$D:$K,5,0),SUMIFS('BD Cap Venda ALE'!H:H,'BD Cap Venda ALE'!E:E,'Capacidade ALE'!G18,'BD Cap Venda ALE'!C:C,'Capacidade ALE'!E18)) -> 3360 | N18: Gasolina C | O18: =IF(RIGHT(F18,5)="Total",VLOOKUP(F18,'BD Cap Venda ALE'!$D:$K,8,0),SUMIFS('BD Cap Venda ALE'!K:K,'BD Cap Venda ALE'!E:E,'Capacidade ALE'!G18,'BD Cap Venda ALE'!C:C,'Capacidade ALE'!E18)) -> 3609.4564 | P18: =IF(RIGHT(F18,5)="Total",VLOOKUP(F18,'Expedição Rodo - ALE'!$A:$H,8,0),"") | S18: Gasolina C | T18: =IFERROR(SUMIFS('BD Cap Venda ALE'!M:M,'BD Cap Venda ALE'!E:E,'Capacidade ALE'!G18,'BD Cap Venda ALE'!C:C,'Capacidade ALE'!E18),0) -> 1944.3267 | U18: =IFERROR(SUMIFS('BD Cap Venda ALE'!N:N,'BD Cap Venda ALE'!E:E,'Capacidade ALE'!G18,'BD Cap Venda ALE'!C:C,'Capacidade ALE'!E18),0) -> 1685.5667
A19: =IF(RIGHT(F19,5)="Total",O19,0) -> 11863.628 | B19: =RIGHT(F19,5) -> Total | C19: =CONCATENATE(D19,RIGHT(F19,5)) -> TerceirosTotal | D19: Terceiros | E19: 18 | F19: ARAUCARIA Total | I19: =IF(RIGHT(F19,5)="Total",VLOOKUP(F19,'BD Cap Venda ALE'!$D:$K,4,0),SUMIFS('BD Cap Venda ALE'!G:G,'BD Cap Venda ALE'!E:E,'Capacidade ALE'!G19,'BD Cap Venda ALE'!C:C,'Capacidade ALE'!E19)) -> 1250 | K19: =IF(RIGHT(F19,5)="Total",VLOOKUP(F19,'Recebimento Rodo - ALE'!$I:$P,8,0),SUMIFS('Recebimento Rodo - ALE'!P:P,'Recebimento Rodo - ALE'!I:I,'Capacidade ALE'!F19,'Recebimento Rodo - ALE'!K:K,'Capacidade ALE'!G19)) -> 8235 | L19: =IF(RIGHT(F19,5)="Total",VLOOKUP(F19,'BD Cap Venda ALE'!$D:$K,5,0),SUMIFS('BD Cap Venda ALE'!H:H,'BD Cap Venda ALE'!E:E,'Capacidade ALE'!G19,'BD Cap Venda ALE'!C:C,'Capacidade ALE'!E19)) -> 15000 | O19: =IF(RIGHT(F19,5)="Total",VLOOKUP(F19,'BD Cap Venda ALE'!$D:$K,8,0),SUMIFS('BD Cap Venda ALE'!K:K,'BD Cap Venda ALE'!E:E,'Capacidade ALE'!G19,'BD Cap Venda ALE'!C:C,'Capacidade ALE'!E19)) -> 11863.628 | P19: =IF(RIGHT(F19,5)="Total",VLOOKUP(F19,'Expedição Rodo - ALE'!$A:$H,8,0),"") -> 21830 | T19: =IFERROR(SUMIFS('BD Cap Venda ALE'!M:M,'BD Cap Venda ALE'!E:E,'Capacidade ALE'!G19,'BD Cap Venda ALE'!C:C,'Capacidade ALE'!E19),0) -> 0 | U19: =IFERROR(SUMIFS('BD Cap Venda ALE'!N:N,'BD Cap Venda ALE'!E:E,'Capacidade ALE'!G19,'BD Cap Venda ALE'!C:C,'Capacidade ALE'!E19),0) -> 0
A20: =IF(RIGHT(F20,5)="Total",O20,0) -> 0 | B20: =RIGHT(F20,5) -> BAURU | C20: =CONCATENATE(D20,RIGHT(F20,5)) -> TerceirosBAURU | D20: Terceiros | E20: 47 | F20: BAURU | G20: B100 | I20: =IF(RIGHT(F20,5)="Total",VLOOKUP(F20,'BD Cap Venda ALE'!$D:$K,4,0),SUMIFS('BD Cap Venda ALE'!G:G,'BD Cap Venda ALE'!E:E,'Capacidade ALE'!G20,'BD Cap Venda ALE'!C:C,'Capacidade ALE'!E20)) -> 45 | K20: =IF(RIGHT(F20,5)="Total",VLOOKUP(F20,'Recebimento Rodo - ALE'!$I:$P,8,0),SUMIFS('Recebimento Rodo - ALE'!P:P,'Recebimento Rodo - ALE'!I:I,'Capacidade ALE'!F20,'Recebimento Rodo - ALE'!K:K,'Capacidade ALE'!G20)) -> 3034.8035 | L20: =IF(RIGHT(F20,5)="Total",VLOOKUP(F20,'BD Cap Venda ALE'!$D:$K,5,0),SUMIFS('BD Cap Venda ALE'!H:H,'BD Cap Venda ALE'!E:E,'Capacidade ALE'!G20,'BD Cap Venda ALE'!C:C,'Capacidade ALE'!E20)) -> 360 | O20: =IF(RIGHT(F20,5)="Total",VLOOKUP(F20,'BD Cap Venda ALE'!$D:$K,8,0),SUMIFS('BD Cap Venda ALE'!K:K,'BD Cap Venda ALE'!E:E,'Capacidade ALE'!G20,'BD Cap Venda ALE'!C:C,'Capacidade ALE'!E20)) -> 0 | P20: =IF(RIGHT(F20,5)="Total",VLOOKUP(F20,'Expedição Rodo - ALE'!$A:$H,8,0),"") | Q20: =IF(P26<O26,"capacidade de expedição rodoviária abaixo da capacidade de venda mensal, prevalece a capacidade de venda mensal em virtude do terminal ter a obrigatoriedade de garantia do giro dos espaços contratados em linha com a logística da filial.","") | T20: =IFERROR(SUMIFS('BD Cap Venda ALE'!M:M,'BD Cap Venda ALE'!E:E,'Capacidade ALE'!G20,'BD Cap Venda ALE'!C:C,'Capacidade ALE'!E20),0) -> 5 | U20: =IFERROR(SUMIFS('BD Cap Venda ALE'!N:N,'BD Cap Venda ALE'!E:E,'Capacidade ALE'!G20,'BD Cap Venda ALE'!C:C,'Capacidade ALE'!E20),0) -> 7.5416667
A21: =IF(RIGHT(F21,5)="Total",O21,0) -> 0 | B21: =RIGHT(F21,5) -> BAURU | C21: =CONCATENATE(D21,RIGHT(F21,5)) -> TerceirosBAURU | D21: Terceiros | E21: 47 | F21: BAURU | G21: Diesel A S10 | I21: =IF(RIGHT(F21,5)="Total",VLOOKUP(F21,'BD Cap Venda ALE'!$D:$K,4,0),SUMIFS('BD Cap Venda ALE'!G:G,'BD Cap Venda ALE'!E:E,'Capacidade ALE'!G21,'BD Cap Venda ALE'!C:C,'Capacidade ALE'!E21)) -> 150 | K21: =IF(RIGHT(F21,5)="Total",VLOOKUP(F21,'Recebimento Rodo - ALE'!$I:$P,8,0),SUMIFS('Recebimento Rodo - ALE'!P:P,'Recebimento Rodo - ALE'!I:I,'Capacidade ALE'!F21,'Recebimento Rodo - ALE'!K:K,'Capacidade ALE'!G21)) -> 3034.8035 | L21: =IF(RIGHT(F21,5)="Total",VLOOKUP(F21,'BD Cap Venda ALE'!$D:$K,5,0),SUMIFS('BD Cap Venda ALE'!H:H,'BD Cap Venda ALE'!E:E,'Capacidade ALE'!G21,'BD Cap Venda ALE'!C:C,'Capacidade ALE'!E21)) -> 1309.0909 | N21: Diesel B S10 | O21: =IF(RIGHT(F21,5)="Total",VLOOKUP(F21,'BD Cap Venda ALE'!$D:$K,8,0),SUMIFS('BD Cap Venda ALE'!K:K,'BD Cap Venda ALE'!E:E,'Capacidade ALE'!G21,'BD Cap Venda ALE'!C:C,'Capacidade ALE'!E21)) -> 1125 | P21: =IF(RIGHT(F21,5)="Total",VLOOKUP(F21,'Expedição Rodo - ALE'!$A:$H,8,0),"") | S21: Diesel B S10 | T21: =IFERROR(SUMIFS('BD Cap Venda ALE'!M:M,'BD Cap Venda ALE'!E:E,'Capacidade ALE'!G21,'BD Cap Venda ALE'!C:C,'Capacidade ALE'!E21),0) -> 11.25 | U21: =IFERROR(SUMIFS('BD Cap Venda ALE'!N:N,'BD Cap Venda ALE'!E:E,'Capacidade ALE'!G21,'BD Cap Venda ALE'!C:C,'Capacidade ALE'!E21),0) -> 29.625
A22: =IF(RIGHT(F22,5)="Total",O22,0) -> 0 | B22: =RIGHT(F22,5) -> BAURU | C22: =CONCATENATE(D22,RIGHT(F22,5)) -> TerceirosBAURU | D22: Terceiros | E22: 47 | F22: BAURU | G22: Diesel A S500 | I22: =IF(RIGHT(F22,5)="Total",VLOOKUP(F22,'BD Cap Venda ALE'!$D:$K,4,0),SUMIFS('BD Cap Venda ALE'!G:G,'BD Cap Venda ALE'!E:E,'Capacidade ALE'!G22,'BD Cap Venda ALE'!C:C,'Capacidade ALE'!E22)) -> 250 | K22: =IF(RIGHT(F22,5)="Total",VLOOKUP(F22,'Recebimento Rodo - ALE'!$I:$P,8,0),SUMIFS('Recebimento Rodo - ALE'!P:P,'Recebimento Rodo - ALE'!I:I,'Capacidade ALE'!F22,'Recebimento Rodo - ALE'!K:K,'Capacidade ALE'!G22)) -> 4046.4046 | L22: =IF(RIGHT(F22,5)="Total",VLOOKUP(F22,'BD Cap Venda ALE'!$D:$K,5,0),SUMIFS('BD Cap Venda ALE'!H:H,'BD Cap Venda ALE'!E:E,'Capacidade ALE'!G22,'BD Cap Venda ALE'!C:C,'Capacidade ALE'!E22)) -> 2181.8182 | N22: Diesel B S500 | O22: =IF(RIGHT(F22,5)="Total",VLOOKUP(F22,'BD Cap Venda ALE'!$D:$K,8,0),SUMIFS('BD Cap Venda ALE'!K:K,'BD Cap Venda ALE'!E:E,'Capacidade ALE'!G22,'BD Cap Venda ALE'!C:C,'Capacidade ALE'!E22)) -> 1875 | P22: =P26 -> 7680 | S22: Diesel B S500 | T22: =IFERROR(SUMIFS('BD Cap Venda ALE'!M:M,'BD Cap Venda ALE'!E:E,'Capacidade ALE'!G22,'BD Cap Venda ALE'!C:C,'Capacidade ALE'!E22),0) -> 33.75 | U22: =IFERROR(SUMIFS('BD Cap Venda ALE'!N:N,'BD Cap Venda ALE'!E:E,'Capacidade ALE'!G22,'BD Cap Venda ALE'!C:C,'Capacidade ALE'!E22),0) -> 38.25
A23: =IF(RIGHT(F23,5)="Total",O23,0) -> 0 | B23: =RIGHT(F23,5) -> BAURU | C23: =CONCATENATE(D23,RIGHT(F23,5)) -> TerceirosBAURU | D23: Terceiros | E23: 47 | F23: BAURU | G23: Etanol Anidro | I23: =IF(RIGHT(F23,5)="Total",VLOOKUP(F23,'BD Cap Venda ALE'!$D:$K,4,0),SUMIFS('BD Cap Venda ALE'!G:G,'BD Cap Venda ALE'!E:E,'Capacidade ALE'!G23,'BD Cap Venda ALE'!C:C,'Capacidade ALE'!E23)) -> 90 | K23: =IF(RIGHT(F23,5)="Total",VLOOKUP(F23,'Recebimento Rodo - ALE'!$I:$P,8,0),SUMIFS('Recebimento Rodo - ALE'!P:P,'Recebimento Rodo - ALE'!I:I,'Capacidade ALE'!F23,'Recebimento Rodo - ALE'!K:K,'Capacidade ALE'!G23)) -> 4046.4046 | L23: =IF(RIGHT(F23,5)="Total",VLOOKUP(F23,'BD Cap Venda ALE'!$D:$K,5,0),SUMIFS('BD Cap Venda ALE'!H:H,'BD Cap Venda ALE'!E:E,'Capacidade ALE'!G23,'BD Cap Venda ALE'!C:C,'Capacidade ALE'!E23)) -> 720 | O23: =IF(RIGHT(F23,5)="Total",VLOOKUP(F23,'BD Cap Venda ALE'!$D:$K,8,0),SUMIFS('BD Cap Venda ALE'!K:K,'BD Cap Venda ALE'!E:E,'Capacidade ALE'!G23,'BD Cap Venda ALE'!C:C,'Capacidade ALE'!E23)) -> 0 | P23: =IF(RIGHT(F23,5)="Total",VLOOKUP(F23,'Expedição Rodo - ALE'!$A:$H,8,0),"") | T23: =IFERROR(SUMIFS('BD Cap Venda ALE'!M:M,'BD Cap Venda ALE'!E:E,'Capacidade ALE'!G23,'BD Cap Venda ALE'!C:C,'Capacidade ALE'!E23),0) -> 37.35 | U23: =IFERROR(SUMIFS('BD Cap Venda ALE'!N:N,'BD Cap Venda ALE'!E:E,'Capacidade ALE'!G23,'BD Cap Venda ALE'!C:C,'Capacidade ALE'!E23),0) -> 30.9375
A24: =IF(RIGHT(F24,5)="Total",O24,0) -> 0 | B24: =RIGHT(F24,5) -> BAURU | C24: =CONCATENATE(D24,RIGHT(F24,5)) -> TerceirosBAURU | D24: Terceiros | E24: 47 | F24: BAURU | G24: Etanol Hidratado | I24: =IF(RIGHT(F24,5)="Total",VLOOKUP(F24,'BD Cap Venda ALE'!$D:$K,4,0),SUMIFS('BD Cap Venda ALE'!G:G,'BD Cap Venda ALE'!E:E,'Capacidade ALE'!G24,'BD Cap Venda ALE'!C:C,'Capacidade ALE'!E24)) -> 90 | K24: =IF(RIGHT(F24,5)="Total",VLOOKUP(F24,'Recebimento Rodo - ALE'!$I:$P,8,0),SUMIFS('Recebimento Rodo - ALE'!P:P,'Recebimento Rodo - ALE'!I:I,'Capacidade ALE'!F24,'Recebimento Rodo - ALE'!K:K,'Capacidade ALE'!G24)) -> 4046.4046 | L24: =IF(RIGHT(F24,5)="Total",VLOOKUP(F24,'BD Cap Venda ALE'!$D:$K,5,0),SUMIFS('BD Cap Venda ALE'!H:H,'BD Cap Venda ALE'!E:E,'Capacidade ALE'!G24,'BD Cap Venda ALE'!C:C,'Capacidade ALE'!E24)) -> 720 | N24: Álcool | O24: =IF(RIGHT(F24,5)="Total",VLOOKUP(F24,'BD Cap Venda ALE'!$D:$K,8,0),SUMIFS('BD Cap Venda ALE'!K:K,'BD Cap Venda ALE'!E:E,'Capacidade ALE'!G24,'BD Cap Venda ALE'!C:C,'Capacidade ALE'!E24)) -> 720 | P24: =IF(RIGHT(F24,5)="Total",VLOOKUP(F24,'Expedição Rodo - ALE'!$A:$H,8,0),"") | S24: Álcool | T24: =IFERROR(SUMIFS('BD Cap Venda ALE'!M:M,'BD Cap Venda ALE'!E:E,'Capacidade ALE'!G24,'BD Cap Venda ALE'!C:C,'Capacidade ALE'!E24),0) -> 88.333333 | U24: =IFERROR(SUMIFS('BD Cap Venda ALE'!N:N,'BD Cap Venda ALE'!E:E,'Capacidade ALE'!G24,'BD Cap Venda ALE'!C:C,'Capacidade ALE'!E24),0) -> 70
A25: =IF(RIGHT(F25,5)="Total",O25,0) -> 0 | B25: =RIGHT(F25,5) -> BAURU | C25: =CONCATENATE(D25,RIGHT(F25,5)) -> TerceirosBAURU | D25: Terceiros | E25: 47 | F25: BAURU | G25: Gasolina A | I25: =IF(RIGHT(F25,5)="Total",VLOOKUP(F25,'BD Cap Venda ALE'!$D:$K,4,0),SUMIFS('BD Cap Venda ALE'!G:G,'BD Cap Venda ALE'!E:E,'Capacidade ALE'!G25,'BD Cap Venda ALE'!C:C,'Capacidade ALE'!E25)) -> 200 | K25: =IF(RIGHT(F25,5)="Total",VLOOKUP(F25,'Recebimento Rodo - ALE'!$I:$P,8,0),SUMIFS('Recebimento Rodo - ALE'!P:P,'Recebimento Rodo - ALE'!I:I,'Capacidade ALE'!F25,'Recebimento Rodo - ALE'!K:K,'Capacidade ALE'!G25)) -> 2023.2023 | L25: =IF(RIGHT(F25,5)="Total",VLOOKUP(F25,'BD Cap Venda ALE'!$D:$K,5,0),SUMIFS('BD Cap Venda ALE'!H:H,'BD Cap Venda ALE'!E:E,'Capacidade ALE'!G25,'BD Cap Venda ALE'!C:C,'Capacidade ALE'!E25)) -> 1745.4545 | N25: Gasolina C | O25: =IF(RIGHT(F25,5)="Total",VLOOKUP(F25,'BD Cap Venda ALE'!$D:$K,8,0),SUMIFS('BD Cap Venda ALE'!K:K,'BD Cap Venda ALE'!E:E,'Capacidade ALE'!G25,'BD Cap Venda ALE'!C:C,'Capacidade ALE'!E25)) -> 2391.0336 | P25: =IF(RIGHT(F25,5)="Total",VLOOKUP(F25,'Expedição Rodo - ALE'!$A:$H,8,0),"") | S25: Gasolina C | T25: =IFERROR(SUMIFS('BD Cap Venda ALE'!M:M,'BD Cap Venda ALE'!E:E,'Capacidade ALE'!G25,'BD Cap Venda ALE'!C:C,'Capacidade ALE'!E25),0) -> 100.98333 | U25: =IFERROR(SUMIFS('BD Cap Venda ALE'!N:N,'BD Cap Venda ALE'!E:E,'Capacidade ALE'!G25,'BD Cap Venda ALE'!C:C,'Capacidade ALE'!E25),0) -> 83.645833
A26: =IF(RIGHT(F26,5)="Total",O26,0) -> 6111.0336 | B26: =RIGHT(F26,5) -> Total | C26: =CONCATENATE(D26,RIGHT(F26,5)) -> TerceirosTotal | D26: Terceiros | E26: 47 | F26: BAURU Total | I26: =IF(RIGHT(F26,5)="Total",VLOOKUP(F26,'BD Cap Venda ALE'!$D:$K,4,0),SUMIFS('BD Cap Venda ALE'!G:G,'BD Cap Venda ALE'!E:E,'Capacidade ALE'!G26,'BD Cap Venda ALE'!C:C,'Capacidade ALE'!E26)) -> 825 | K26: =IF(RIGHT(F26,5)="Total",VLOOKUP(F26,'Recebimento Rodo - ALE'!$I:$P,8,0),SUMIFS('Recebimento Rodo - ALE'!P:P,'Recebimento Rodo - ALE'!I:I,'Capacidade ALE'!F26,'Recebimento Rodo - ALE'!K:K,'Capacidade ALE'!G26)) -> 20232.023 | L26: =IF(RIGHT(F26,5)="Total",VLOOKUP(F26,'BD Cap Venda ALE'!$D:$K,5,0),SUMIFS('BD Cap Venda ALE'!H:H,'BD Cap Venda ALE'!E:E,'Capacidade ALE'!G26,'BD Cap Venda ALE'!C:C,'Capacidade ALE'!E26)) -> 7036.3636 | O26: =IF(RIGHT(F26,5)="Total",VLOOKUP(F26,'BD Cap Venda ALE'!$D:$K,8,0),SUMIFS('BD Cap Venda ALE'!K:K,'BD Cap Venda ALE'!E:E,'Capacidade ALE'!G26,'BD Cap Venda ALE'!C:C,'Capacidade ALE'!E26)) -> 6111.0336 | P26: =IF(RIGHT(F26,5)="Total",VLOOKUP(F26,'Expedição Rodo - ALE'!$A:$H,8,0),"") -> 7680 | T26: =IFERROR(SUMIFS('BD Cap Venda ALE'!M:M,'BD Cap Venda ALE'!E:E,'Capacidade ALE'!G26,'BD Cap Venda ALE'!C:C,'Capacidade ALE'!E26),0) -> 0 | U26: =IFERROR(SUMIFS('BD Cap Venda ALE'!N:N,'BD Cap Venda ALE'!E:E,'Capacidade ALE'!G26,'BD Cap Venda ALE'!C:C,'Capacidade ALE'!E26),0) -> 0
A27: =IF(RIGHT(F27,5)="Total",O27,0) -> 0 | B27: =RIGHT(F27,5) -> BELEM | C27: =CONCATENATE(D27,RIGHT(F27,5)) -> TerceirosBELEM | D27: Terceiros | E27: 35 | F27: BELEM | G27: B100 | I27: =IF(RIGHT(F27,5)="Total",VLOOKUP(F27,'BD Cap Venda ALE'!$D:$K,4,0),SUMIFS('BD Cap Venda ALE'!G:G,'BD Cap Venda ALE'!E:E,'Capacidade ALE'!G27,'BD Cap Venda ALE'!C:C,'Capacidade ALE'!E27)) -> 200 | K27: =IF(RIGHT(F27,5)="Total",VLOOKUP(F27,'Recebimento Rodo - ALE'!$I:$P,8,0),SUMIFS('Recebimento Rodo - ALE'!P:P,'Recebimento Rodo - ALE'!I:I,'Capacidade ALE'!F27,'Recebimento Rodo - ALE'!K:K,'Capacidade ALE'!G27)) -> 2106.5 | L27: =IF(RIGHT(F27,5)="Total",VLOOKUP(F27,'BD Cap Venda ALE'!$D:$K,5,0),SUMIFS('BD Cap Venda ALE'!H:H,'BD Cap Venda ALE'!E:E,'Capacidade ALE'!G27,'BD Cap Venda ALE'!C:C,'Capacidade ALE'!E27)) -> 480 | O27: =IF(RIGHT(F27,5)="Total",VLOOKUP(F27,'BD Cap Venda ALE'!$D:$K,8,0),SUMIFS('BD Cap Venda ALE'!K:K,'BD Cap Venda ALE'!E:E,'Capacidade ALE'!G27,'BD Cap Venda ALE'!C:C,'Capacidade ALE'!E27)) -> 0 | P27: =IF(RIGHT(F27,5)="Total",VLOOKUP(F27,'Expedição Rodo - ALE'!$A:$H,8,0),"") | Q27: =IF(P33<O33,"capacidade de expedição rodoviária abaixo da capacidade de venda mensal, prevalece a capacidade de venda mensal em virtude do terminal ter a obrigatoriedade de garantia do giro dos espaços contratados em linha com a logística da filial.","") | T27: =IFERROR(SUMIFS('BD Cap Venda ALE'!M:M,'BD Cap Venda ALE'!E:E,'Capacidade ALE'!G27,'BD Cap Venda ALE'!C:C,'Capacidade ALE'!E27),0) -> 157.81667 | U27: =IFERROR(SUMIFS('BD Cap Venda ALE'!N:N,'BD Cap Venda ALE'!E:E,'Capacidade ALE'!G27,'BD Cap Venda ALE'!C:C,'Capacidade ALE'!E27),0) -> 143.76667
A28: =IF(RIGHT(F28,5)="Total",O28,0) -> 0 | B28: =RIGHT(F28,5) -> BELEM | C28: =CONCATENATE(D28,RIGHT(F28,5)) -> TerceirosBELEM | D28: Terceiros | E28: 35 | F28: BELEM | G28: Diesel A S10 | I28: =IF(RIGHT(F28,5)="Total",VLOOKUP(F28,'BD Cap Venda ALE'!$D:$K,4,0),SUMIFS('BD Cap Venda ALE'!G:G,'BD Cap Venda ALE'!E:E,'Capacidade ALE'!G28,'BD Cap Venda ALE'!C:C,'Capacidade ALE'!E28)) -> 1400 | K28: =IF(RIGHT(F28,5)="Total",VLOOKUP(F28,'Recebimento Rodo - ALE'!$I:$P,8,0),SUMIFS('Recebimento Rodo - ALE'!P:P,'Recebimento Rodo - ALE'!I:I,'Capacidade ALE'!F28,'Recebimento Rodo - ALE'!K:K,'Capacidade ALE'!G28)) -> 305 | L28: =IF(RIGHT(F28,5)="Total",VLOOKUP(F28,'BD Cap Venda ALE'!$D:$K,5,0),SUMIFS('BD Cap Venda ALE'!H:H,'BD Cap Venda ALE'!E:E,'Capacidade ALE'!G28,'BD Cap Venda ALE'!C:C,'Capacidade ALE'!E28)) -> 2240 | N28: Diesel B S10 | O28: =IF(RIGHT(F28,5)="Total",VLOOKUP(F28,'BD Cap Venda ALE'!$D:$K,8,0),SUMIFS('BD Cap Venda ALE'!K:K,'BD Cap Venda ALE'!E:E,'Capacidade ALE'!G28,'BD Cap Venda ALE'!C:C,'Capacidade ALE'!E28)) -> 2545.4545 | P28: =IF(RIGHT(F28,5)="Total",VLOOKUP(F28,'Expedição Rodo - ALE'!$A:$H,8,0),"") | S28: Diesel B S10 | T28: =IFERROR(SUMIFS('BD Cap Venda ALE'!M:M,'BD Cap Venda ALE'!E:E,'Capacidade ALE'!G28,'BD Cap Venda ALE'!C:C,'Capacidade ALE'!E28),0) -> 1098.45 | U28: =IFERROR(SUMIFS('BD Cap Venda ALE'!N:N,'BD Cap Venda ALE'!E:E,'Capacidade ALE'!G28,'BD Cap Venda ALE'!C:C,'Capacidade ALE'!E28),0) -> 1003.725
A29: =IF(RIGHT(F29,5)="Total",O29,0) -> 0 | B29: =RIGHT(F29,5) -> BELEM | C29: =CONCATENATE(D29,RIGHT(F29,5)) -> TerceirosBELEM | D29: Terceiros | E29: 35 | F29: BELEM | G29: Diesel A S500 | I29: =IF(RIGHT(F29,5)="Total",VLOOKUP(F29,'BD Cap Venda ALE'!$D:$K,4,0),SUMIFS('BD Cap Venda ALE'!G:G,'BD Cap Venda ALE'!E:E,'Capacidade ALE'!G29,'BD Cap Venda ALE'!C:C,'Capacidade ALE'!E29)) -> 255 | K29: =IF(RIGHT(F29,5)="Total",VLOOKUP(F29,'Recebimento Rodo - ALE'!$I:$P,8,0),SUMIFS('Recebimento Rodo - ALE'!P:P,'Recebimento Rodo - ALE'!I:I,'Capacidade ALE'!F29,'Recebimento Rodo - ALE'!K:K,'Capacidade ALE'!G29)) -> 0 | L29: =IF(RIGHT(F29,5)="Total",VLOOKUP(F29,'BD Cap Venda ALE'!$D:$K,5,0),SUMIFS('BD Cap Venda ALE'!H:H,'BD Cap Venda ALE'!E:E,'Capacidade ALE'!G29,'BD Cap Venda ALE'!C:C,'Capacidade ALE'!E29)) -> 0 | N29: Diesel B S500 | O29: =IF(RIGHT(F29,5)="Total",VLOOKUP(F29,'BD Cap Venda ALE'!$D:$K,8,0),SUMIFS('BD Cap Venda ALE'!K:K,'BD Cap Venda ALE'!E:E,'Capacidade ALE'!G29,'BD Cap Venda ALE'!C:C,'Capacidade ALE'!E29)) -> 0 | P29: =P33 -> 17820 | S29: Diesel B S500 | T29: =IFERROR(SUMIFS('BD Cap Venda ALE'!M:M,'BD Cap Venda ALE'!E:E,'Capacidade ALE'!G29,'BD Cap Venda ALE'!C:C,'Capacidade ALE'!E29),0) -> 321.9 | U29: =IFERROR(SUMIFS('BD Cap Venda ALE'!N:N,'BD Cap Venda ALE'!E:E,'Capacidade ALE'!G29,'BD Cap Venda ALE'!C:C,'Capacidade ALE'!E29),0) -> 290.175
A30: =IF(RIGHT(F30,5)="Total",O30,0) -> 0 | B30: =RIGHT(F30,5) -> BELEM | C30: =CONCATENATE(D30,RIGHT(F30,5)) -> TerceirosBELEM | D30: Terceiros | E30: 35 | F30: BELEM | G30: Etanol Anidro | I30: =IF(RIGHT(F30,5)="Total",VLOOKUP(F30,'BD Cap Venda ALE'!$D:$K,4,0),SUMIFS('BD Cap Venda ALE'!G:G,'BD Cap Venda ALE'!E:E,'Capacidade ALE'!G30,'BD Cap Venda ALE'!C:C,'Capacidade ALE'!E30)) -> 260 | K30: =IF(RIGHT(F30,5)="Total",VLOOKUP(F30,'Recebimento Rodo - ALE'!$I:$P,8,0),SUMIFS('Recebimento Rodo - ALE'!P:P,'Recebimento Rodo - ALE'!I:I,'Capacidade ALE'!F30,'Recebimento Rodo - ALE'!K:K,'Capacidade ALE'!G30)) -> 2106.5 | L30: =IF(RIGHT(F30,5)="Total",VLOOKUP(F30,'BD Cap Venda ALE'!$D:$K,5,0),SUMIFS('BD Cap Venda ALE'!H:H,'BD Cap Venda ALE'!E:E,'Capacidade ALE'!G30,'BD Cap Venda ALE'!C:C,'Capacidade ALE'!E30)) -> 2080 | O30: =IF(RIGHT(F30,5)="Total",VLOOKUP(F30,'BD Cap Venda ALE'!$D:$K,8,0),SUMIFS('BD Cap Venda ALE'!K:K,'BD Cap Venda ALE'!E:E,'Capacidade ALE'!G30,'BD Cap Venda ALE'!C:C,'Capacidade ALE'!E30)) -> 0 | P30: =IF(RIGHT(F30,5)="Total",VLOOKUP(F30,'Expedição Rodo - ALE'!$A:$H,8,0),"") | T30: =IFERROR(SUMIFS('BD Cap Venda ALE'!M:M,'BD Cap Venda ALE'!E:E,'Capacidade ALE'!G30,'BD Cap Venda ALE'!C:C,'Capacidade ALE'!E30),0) -> 453.98833 | U30: =IFERROR(SUMIFS('BD Cap Venda ALE'!N:N,'BD Cap Venda ALE'!E:E,'Capacidade ALE'!G30,'BD Cap Venda ALE'!C:C,'Capacidade ALE'!E30),0) -> 437.75167
A31: =IF(RIGHT(F31,5)="Total",O31,0) -> 0 | B31: =RIGHT(F31,5) -> BELEM | C31: =CONCATENATE(D31,RIGHT(F31,5)) -> TerceirosBELEM | D31: Terceiros | E31: 35 | F31: BELEM | G31: Etanol Hidratado | I31: =IF(RIGHT(F31,5)="Total",VLOOKUP(F31,'BD Cap Venda ALE'!$D:$K,4,0),SUMIFS('BD Cap Venda ALE'!G:G,'BD Cap Venda ALE'!E:E,'Capacidade ALE'!G31,'BD Cap Venda ALE'!C:C,'Capacidade ALE'!E31)) -> 50 | K31: =IF(RIGHT(F31,5)="Total",VLOOKUP(F31,'Recebimento Rodo - ALE'!$I:$P,8,0),SUMIFS('Recebimento Rodo - ALE'!P:P,'Recebimento Rodo - ALE'!I:I,'Capacidade ALE'!F31,'Recebimento Rodo - ALE'!K:K,'Capacidade ALE'!G31)) -> 1053.25 | L31: =IF(RIGHT(F31,5)="Total",VLOOKUP(F31,'BD Cap Venda ALE'!$D:$K,5,0),SUMIFS('BD Cap Venda ALE'!H:H,'BD Cap Venda ALE'!E:E,'Capacidade ALE'!G31,'BD Cap Venda ALE'!C:C,'Capacidade ALE'!E31)) -> 171.42857 | N31: Álcool | O31: =IF(RIGHT(F31,5)="Total",VLOOKUP(F31,'BD Cap Venda ALE'!$D:$K,8,0),SUMIFS('BD Cap Venda ALE'!K:K,'BD Cap Venda ALE'!E:E,'Capacidade ALE'!G31,'BD Cap Venda ALE'!C:C,'Capacidade ALE'!E31)) -> 171.42857 | P31: =IF(RIGHT(F31,5)="Total",VLOOKUP(F31,'Expedição Rodo - ALE'!$A:$H,8,0),"") | S31: Álcool | T31: =IFERROR(SUMIFS('BD Cap Venda ALE'!M:M,'BD Cap Venda ALE'!E:E,'Capacidade ALE'!G31,'BD Cap Venda ALE'!C:C,'Capacidade ALE'!E31),0) -> 21.666667 | U31: =IFERROR(SUMIFS('BD Cap Venda ALE'!N:N,'BD Cap Venda ALE'!E:E,'Capacidade ALE'!G31,'BD Cap Venda ALE'!C:C,'Capacidade ALE'!E31),0) -> 20.416667
A32: =IF(RIGHT(F32,5)="Total",O32,0) -> 0 | B32: =RIGHT(F32,5) -> BELEM | C32: =CONCATENATE(D32,RIGHT(F32,5)) -> TerceirosBELEM | D32: Terceiros | E32: 35 | F32: BELEM | G32: Gasolina A | I32: =IF(RIGHT(F32,5)="Total",VLOOKUP(F32,'BD Cap Venda ALE'!$D:$K,4,0),SUMIFS('BD Cap Venda ALE'!G:G,'BD Cap Venda ALE'!E:E,'Capacidade ALE'!G32,'BD Cap Venda ALE'!C:C,'Capacidade ALE'!E32)) -> 1150 | K32: =IF(RIGHT(F32,5)="Total",VLOOKUP(F32,'Recebimento Rodo - ALE'!$I:$P,8,0),SUMIFS('Recebimento Rodo - ALE'!P:P,'Recebimento Rodo - ALE'!I:I,'Capacidade ALE'!F32,'Recebimento Rodo - ALE'!K:K,'Capacidade ALE'!G32)) -> 406.66667 | L32: =IF(RIGHT(F32,5)="Total",VLOOKUP(F32,'BD Cap Venda ALE'!$D:$K,5,0),SUMIFS('BD Cap Venda ALE'!H:H,'BD Cap Venda ALE'!E:E,'Capacidade ALE'!G32,'BD Cap Venda ALE'!C:C,'Capacidade ALE'!E32)) -> 1840 | N32: Gasolina C | O32: =IF(RIGHT(F32,5)="Total",VLOOKUP(F32,'BD Cap Venda ALE'!$D:$K,8,0),SUMIFS('BD Cap Venda ALE'!K:K,'BD Cap Venda ALE'!E:E,'Capacidade ALE'!G32,'BD Cap Venda ALE'!C:C,'Capacidade ALE'!E32)) -> 2520.5479 | P32: =IF(RIGHT(F32,5)="Total",VLOOKUP(F32,'Expedição Rodo - ALE'!$A:$H,8,0),"") | S32: Gasolina C | T32: =IFERROR(SUMIFS('BD Cap Venda ALE'!M:M,'BD Cap Venda ALE'!E:E,'Capacidade ALE'!G32,'BD Cap Venda ALE'!C:C,'Capacidade ALE'!E32),0) -> 1199.5117 | U32: =IFERROR(SUMIFS('BD Cap Venda ALE'!N:N,'BD Cap Venda ALE'!E:E,'Capacidade ALE'!G32,'BD Cap Venda ALE'!C:C,'Capacidade ALE'!E32),0) -> 1169.5817
A33: =IF(RIGHT(F33,5)="Total",O33,0) -> 5237.4311 | B33: =RIGHT(F33,5) -> Total | C33: =CONCATENATE(D33,RIGHT(F33,5)) -> TerceirosTotal | D33: Terceiros | E33: 35 | F33: BELEM Total | I33: =IF(RIGHT(F33,5)="Total",VLOOKUP(F33,'BD Cap Venda ALE'!$D:$K,4,0),SUMIFS('BD Cap Venda ALE'!G:G,'BD Cap Venda ALE'!E:E,'Capacidade ALE'!G33,'BD Cap Venda ALE'!C:C,'Capacidade ALE'!E33)) -> 3315 | K33: =IF(RIGHT(F33,5)="Total",VLOOKUP(F33,'Recebimento Rodo - ALE'!$I:$P,8,0),SUMIFS('Recebimento Rodo - ALE'!P:P,'Recebimento Rodo - ALE'!I:I,'Capacidade ALE'!F33,'Recebimento Rodo - ALE'!K:K,'Capacidade ALE'!G33)) -> 5977.9167 | L33: =IF(RIGHT(F33,5)="Total",VLOOKUP(F33,'BD Cap Venda ALE'!$D:$K,5,0),SUMIFS('BD Cap Venda ALE'!H:H,'BD Cap Venda ALE'!E:E,'Capacidade ALE'!G33,'BD Cap Venda ALE'!C:C,'Capacidade ALE'!E33)) -> 6811.4286 | O33: =IF(RIGHT(F33,5)="Total",VLOOKUP(F33,'BD Cap Venda ALE'!$D:$K,8,0),SUMIFS('BD Cap Venda ALE'!K:K,'BD Cap Venda ALE'!E:E,'Capacidade ALE'!G33,'BD Cap Venda ALE'!C:C,'Capacidade ALE'!E33)) -> 5237.4311 | P33: =IF(RIGHT(F33,5)="Total",VLOOKUP(F33,'Expedição Rodo - ALE'!$A:$H,8,0),"") -> 17820 | T33: =IFERROR(SUMIFS('BD Cap Venda ALE'!M:M,'BD Cap Venda ALE'!E:E,'Capacidade ALE'!G33,'BD Cap Venda ALE'!C:C,'Capacidade ALE'!E33),0) -> 0 | U33: =IFERROR(SUMIFS('BD Cap Venda ALE'!N:N,'BD Cap Venda ALE'!E:E,'Capacidade ALE'!G33,'BD Cap Venda ALE'!C:C,'Capacidade ALE'!E33),0) -> 0
A34: =IF(RIGHT(F34,5)="Total",O34,0) -> 0 | B34: =RIGHT(F34,5) -> BETIM | C34: =CONCATENATE(D34,RIGHT(F34,5)) -> PrópriaBETIM | D34: Própria | E34: 1 | F34: BETIM | G34: B100 | I34: =IF(RIGHT(F34,5)="Total",VLOOKUP(F34,'BD Cap Venda ALE'!$D:$K,4,0),SUMIFS('BD Cap Venda ALE'!G:G,'BD Cap Venda ALE'!E:E,'Capacidade ALE'!G34,'BD Cap Venda ALE'!C:C,'Capacidade ALE'!E34)) -> 382.31648 | K34: =IF(RIGHT(F34,5)="Total",VLOOKUP(F34,'Recebimento Rodo - ALE'!$I:$P,8,0),SUMIFS('Recebimento Rodo - ALE'!P:P,'Recebimento Rodo - ALE'!I:I,'Capacidade ALE'!F34,'Recebimento Rodo - ALE'!K:K,'Capacidade ALE'!G34)) -> 3950.9109 | L34: =IF(RIGHT(F34,5)="Total",VLOOKUP(F34,'BD Cap Venda ALE'!$D:$K,5,0),SUMIFS('BD Cap Venda ALE'!H:H,'BD Cap Venda ALE'!E:E,'Capacidade ALE'!G34,'BD Cap Venda ALE'!C:C,'Capacidade ALE'!E34)) -> 1310.7993 | O34: =IF(RIGHT(F34,5)="Total",VLOOKUP(F34,'BD Cap Venda ALE'!$D:$K,8,0),SUMIFS('BD Cap Venda ALE'!K:K,'BD Cap Venda ALE'!E:E,'Capacidade ALE'!G34,'BD Cap Venda ALE'!C:C,'Capacidade ALE'!E34)) -> 0 | P34: =IF(RIGHT(F34,5)="Total",VLOOKUP(F34,'Expedição Rodo - ALE'!$A:$H,8,0),"") | Q34: As capacidades de recebimento rodoviário foram diluídas conforme a participação identificada pelo Ale 738. Entretanto, estas podem ser alteradas entre os produtos, respeitando a capacidade total da base, em função do modelo de recebimento rodoviário. | T34: =IFERROR(SUMIFS('BD Cap Venda ALE'!M:M,'BD Cap Venda ALE'!E:E,'Capacidade ALE'!G34,'BD Cap Venda ALE'!C:C,'Capacidade ALE'!E34),0) -> 2212.6667 | U34: =IFERROR(SUMIFS('BD Cap Venda ALE'!N:N,'BD Cap Venda ALE'!E:E,'Capacidade ALE'!G34,'BD Cap Venda ALE'!C:C,'Capacidade ALE'!E34),0) -> 2396.9083
A35: =IF(RIGHT(F35,5)="Total",O35,0) -> 0 | B35: =RIGHT(F35,5) -> BETIM | C35: =CONCATENATE(D35,RIGHT(F35,5)) -> PrópriaBETIM | D35: Própria | E35: 1 | F35: BETIM | G35: Diesel A S10 | I35: =IF(RIGHT(F35,5)="Total",VLOOKUP(F35,'BD Cap Venda ALE'!$D:$K,4,0),SUMIFS('BD Cap Venda ALE'!G:G,'BD Cap Venda ALE'!E:E,'Capacidade ALE'!G35,'BD Cap Venda ALE'!C:C,'Capacidade ALE'!E35)) -> 1333.4326 | K35: =IF(RIGHT(F35,5)="Total",VLOOKUP(F35,'Recebimento Rodo - ALE'!$I:$P,8,0),SUMIFS('Recebimento Rodo - ALE'!P:P,'Recebimento Rodo - ALE'!I:I,'Capacidade ALE'!F35,'Recebimento Rodo - ALE'!K:K,'Capacidade ALE'!G35)) -> 4169.0181 | L35: =IF(RIGHT(F35,5)="Total",VLOOKUP(F35,'BD Cap Venda ALE'!$D:$K,5,0),SUMIFS('BD Cap Venda ALE'!H:H,'BD Cap Venda ALE'!E:E,'Capacidade ALE'!G35,'BD Cap Venda ALE'!C:C,'Capacidade ALE'!E35)) -> 32002.383 | N35: Diesel B S10 | O35: =IF(RIGHT(F35,5)="Total",VLOOKUP(F35,'BD Cap Venda ALE'!$D:$K,8,0),SUMIFS('BD Cap Venda ALE'!K:K,'BD Cap Venda ALE'!E:E,'Capacidade ALE'!G35,'BD Cap Venda ALE'!C:C,'Capacidade ALE'!E35)) -> 5707.2716 | P35: =IF(RIGHT(F35,5)="Total",VLOOKUP(F35,'Expedição Rodo - ALE'!$A:$H,8,0),"") | S35: Diesel B S10 | T35: =IFERROR(SUMIFS('BD Cap Venda ALE'!M:M,'BD Cap Venda ALE'!E:E,'Capacidade ALE'!G35,'BD Cap Venda ALE'!C:C,'Capacidade ALE'!E35),0) -> 12319.817 | U35: =IFERROR(SUMIFS('BD Cap Venda ALE'!N:N,'BD Cap Venda ALE'!E:E,'Capacidade ALE'!G35,'BD Cap Venda ALE'!C:C,'Capacidade ALE'!E35),0) -> 12677.108
