Workbook

Sheet Folha1
A1: CNPJ | B1: Razão Social | C1: NOME REDUZIDO | D1: Tipo de Instalação | E1: CLASSIFICAÇÃO | F1: Endereço da Matriz | G1: Número | H1: Bairro | I1: Complemento | J1: Município | K1: UF | L1: Capacidade Total | M1: Participação (%) | N1: TIPO | O1: Número Autorização | P1: Data Publicação
A2: 00175884000204 | B2: PETROSUL DISTRIBUIDORA TRANSPORTADORA E COMÉRCIO DE COMBUSTÍVEIS LTDA | C2: =VLOOKUP(folha1[[#This Row],[Razão Social]],Planilha1!A:C,2,0) -> PETROSUL TRANSPORTADORA E COMÉRCIO DE COMBUSTÍVEIS | D2: BASES DO RAMO DE COMBUSTÍVEIS | E2: =VLOOKUP(folha1[[#This Row],[Razão Social]],Planilha1!A:C,3,0) -> REGIONAL | F2: RUA SIDNEY CARDON DE OLIVEIRA | G2: 1723 | H2: CASCATA | J2: PAULINIA | K2: SP | L2: 11718.58 | M2: 61.6 | N2: =IF(folha1[[#This Row],[Participação (%)]]=100,"BASE PRÓPRIA","BASE POOL") -> BASE POOL | O2: 464 | P2: 41949
A3: 00175884001006 | B3: PETROSUL DISTRIBUIDORA TRANSPORTADORA E COMÉRCIO DE COMBUSTÍVEIS LTDA | C3: =VLOOKUP(folha1[[#This Row],[Razão Social]],Planilha1!A:C,2,0) -> PETROSUL TRANSPORTADORA E COMÉRCIO DE COMBUSTÍVEIS | D3: BASES DO RAMO DE COMBUSTÍVEIS | E3: =VLOOKUP(folha1[[#This Row],[Razão Social]],Planilha1!A:C,3,0) -> REGIONAL | F3: Avenida Tropical | G3: S/Nº | H3: Distrito Industrial Brasil Central | I3: LOTE 5 E 6 A | J3: SENADOR CANEDO | K3: GO | L3: 12289 | M3: 81.7 | N3: =IF(folha1[[#This Row],[Participação (%)]]=100,"BASE PRÓPRIA","BASE POOL") -> BASE POOL | O3: 5 | P3: 45296
A4: 00209895000250 | B4: RDP ENERGIA LTDA | C4: =VLOOKUP(folha1[[#This Row],[Razão Social]],Planilha1!A:C,2,0) -> RDP ENERGIA | D4: BASES DO RAMO DE COMBUSTÍVEIS | E4: =VLOOKUP(folha1[[#This Row],[Razão Social]],Planilha1!A:C,3,0) -> REGIONAL | F4: RUA BENJAMIM DAGNONI | G4: 705 | H4: RESSACADA | I4: TERREO | J4: ITAJAI | K4: SC | L4: 6493.18 | M4: 100 | N4: =IF(folha1[[#This Row],[Participação (%)]]=100,"BASE PRÓPRIA","BASE POOL") -> BASE PRÓPRIA | O4: 293 | P4: 41073
A5: 00209895000330 | B5: RDP ENERGIA LTDA | C5: =VLOOKUP(folha1[[#This Row],[Razão Social]],Planilha1!A:C,2,0) -> RDP ENERGIA | D5: BASES DO RAMO DE COMBUSTÍVEIS | E5: =VLOOKUP(folha1[[#This Row],[Razão Social]],Planilha1!A:C,3,0) -> REGIONAL | F5: RUA EDSON QUEIROZ | G5: 215 | H5: CHAPADA | J5: ARAUCARIA | K5: PR | L5: 12121.62 | M5: 100 | N5: =IF(folha1[[#This Row],[Participação (%)]]=100,"BASE PRÓPRIA","BASE POOL") -> BASE PRÓPRIA | O5: 87 | P5: 42803
A6: 00326969000157 | B6: MAXSUL DISTRIBUIDORA DE COMBUSTÍVEIS LTDA. | C6: =VLOOKUP(folha1[[#This Row],[Razão Social]],Planilha1!A:C,2,0) -> MAXSUL . | D6: BASES DO RAMO DE COMBUSTÍVEIS | E6: =VLOOKUP(folha1[[#This Row],[Razão Social]],Planilha1!A:C,3,0) -> REGIONAL | F6: ROD SC 480, KM 5,8 | G6: 4445 E | H6: Centro (Marechal Bormann) | J6: CHAPECO | K6: SC | L6: 12392.43 | M6: 100 | N6: =IF(folha1[[#This Row],[Participação (%)]]=100,"BASE PRÓPRIA","BASE POOL") -> BASE PRÓPRIA | O6: 207 | P6: 45764
A7: 00401560000158 | B7: JOAPI DISTRIBUIDORA DE COMBUSTÍVEIS S.A. | C7: =VLOOKUP(folha1[[#This Row],[Razão Social]],Planilha1!A:C,2,0) -> JOAPI | D7: BASES DO RAMO DE COMBUSTÍVEIS | E7: =VLOOKUP(folha1[[#This Row],[Razão Social]],Planilha1!A:C,3,0) -> REGIONAL | F7: ESTRADA PORTO DA FARINHA | G7: 256 | H7: CAJU | J7: NOVA SANTA RITA | K7: RS | L7: 840 | M7: 100 | N7: =IF(folha1[[#This Row],[Participação (%)]]=100,"BASE PRÓPRIA","BASE POOL") -> BASE PRÓPRIA | O7: 677 | P7: 45964
A8: 00466187000113 | B8: FÉLIX DISTRIBUIDORA DE COMBUSTÍVEIS LTDA | C8: =VLOOKUP(folha1[[#This Row],[Razão Social]],Planilha1!A:C,2,0) -> FÉLIX | D8: BASES DO RAMO DE COMBUSTÍVEIS | E8: =VLOOKUP(folha1[[#This Row],[Razão Social]],Planilha1!A:C,3,0) -> REGIONAL | F8: ROD DA BALSINHA | G8: S/N | H8: ZONA RURAL | I8: KM 18 A DIREITA 04 KM SALA 18 | J8: IGUATEMI | K8: MS | L8: 20120 | M8: 3.72 | N8: =IF(folha1[[#This Row],[Participação (%)]]=100,"BASE PRÓPRIA","BASE POOL") -> BASE POOL | O8: 486 | P8: 45106
A9: 00756149000103 | B9: RUFF CJ DISTRIBUIDORA DE PETRÓLEO LTDA | C9: =VLOOKUP(folha1[[#This Row],[Razão Social]],Planilha1!A:C,2,0) -> RUFF CJ | D9: BASES DO RAMO DE COMBUSTÍVEIS | E9: =VLOOKUP(folha1[[#This Row],[Razão Social]],Planilha1!A:C,3,0) -> REGIONAL | F9: AVENIDA ERNESTO IGEL | G9: 3714 | H9: CASCATA | J9: PAULINIA | K9: SP | L9: 12900 | M9: 100 | N9: =IF(folha1[[#This Row],[Participação (%)]]=100,"BASE PRÓPRIA","BASE POOL") -> BASE PRÓPRIA | O9: 249 | P9: 37939
A10: 00756149001177 | B10: RUFF CJ DISTRIBUIDORA DE PETRÓLEO LTDA | C10: =VLOOKUP(folha1[[#This Row],[Razão Social]],Planilha1!A:C,2,0) -> RUFF CJ | D10: BASES DO RAMO DE COMBUSTÍVEIS | E10: =VLOOKUP(folha1[[#This Row],[Razão Social]],Planilha1!A:C,3,0) -> REGIONAL | F10: RODOVIA VIA JOSÉ LUIZ GALVÃO | G10: 2100 | H10: SITIO BOM JESUS | I10: SETOR OESTE SS-O-16 | J10: RIBEIRAO PRETO | K10: SP | L10: 9940 | M10: 100 | N10: =IF(folha1[[#This Row],[Participação (%)]]=100,"BASE PRÓPRIA","BASE POOL") -> BASE PRÓPRIA | O10: 358 | P10: 43983
A11: 00756149001762 | B11: RUFF CJ DISTRIBUIDORA DE PETRÓLEO LTDA | C11: =VLOOKUP(folha1[[#This Row],[Razão Social]],Planilha1!A:C,2,0) -> RUFF CJ | D11: BASES DO RAMO DE COMBUSTÍVEIS | E11: =VLOOKUP(folha1[[#This Row],[Razão Social]],Planilha1!A:C,3,0) -> REGIONAL | F11: RUA DO VALE | G11: 155 | H11: CENTRO | J11: CAREACU | K11: MG | L11: 833.27 | M11: 100 | N11: =IF(folha1[[#This Row],[Participação (%)]]=100,"BASE PRÓPRIA","BASE POOL") -> BASE PRÓPRIA | O11: 606 | P11: 44468
A12: 00756149002491 | B12: RUFF CJ DISTRIBUIDORA DE PETRÓLEO LTDA | C12: =VLOOKUP(folha1[[#This Row],[Razão Social]],Planilha1!A:C,2,0) -> RUFF CJ | D12: BASES DO RAMO DE COMBUSTÍVEIS | E12: =VLOOKUP(folha1[[#This Row],[Razão Social]],Planilha1!A:C,3,0) -> REGIONAL | F12: R JOAQUIM PEDRO RIBEIRO | G12: 834 | H12: Centro | J12: GUAXUPE | K12: MG | L12: 1563.5 | M12: 100 | N12: =IF(folha1[[#This Row],[Participação (%)]]=100,"BASE PRÓPRIA","BASE POOL") -> BASE PRÓPRIA | O12: 761 | P12: 44531
A13: 00828887000372 | B13: PELIKANO DISTRIBUIDORA DE PETRÓLEO LTDA | C13: =VLOOKUP(folha1[[#This Row],[Razão Social]],Planilha1!A:C,2,0) -> PELIKANO | D13: BASES DO RAMO DE COMBUSTÍVEIS | E13: =VLOOKUP(folha1[[#This Row],[Razão Social]],Planilha1!A:C,3,0) -> REGIONAL | F13: Rua Luiz Franceschi | G13: 522 | H13: Thomaz Coelho | J13: ARAUCARIA | K13: PR | L13: 1723.05 | M13: 100 | N13: =IF(folha1[[#This Row],[Participação (%)]]=100,"BASE PRÓPRIA","BASE POOL") -> BASE PRÓPRIA
A14: 00942246000263 | B14: SIMARELLI DISTRIBUIDORA DE DERIVADOS DE PETRÓLEO LTDA. | C14: =VLOOKUP(folha1[[#This Row],[Razão Social]],Planilha1!A:C,2,0) -> SIMARELLI . | D14: BASES DO RAMO DE COMBUSTÍVEIS | E14: =VLOOKUP(folha1[[#This Row],[Razão Social]],Planilha1!A:C,3,0) -> REGIONAL | F14: RODOVIA SP 332 | G14: S/N.º | H14: CASCATA | I14: KM 132 | J14: PAULINIA | K14: SP | L14: 9269.22 | M14: 100 | N14: =IF(folha1[[#This Row],[Participação (%)]]=100,"BASE PRÓPRIA","BASE POOL") -> BASE PRÓPRIA | O14: 41 | P14: 40939
A15: 00942246000506 | B15: SIMARELLI DISTRIBUIDORA DE DERIVADOS DE PETRÓLEO LTDA. | C15: =VLOOKUP(folha1[[#This Row],[Razão Social]],Planilha1!A:C,2,0) -> SIMARELLI . | D15: BASES DO RAMO DE COMBUSTÍVEIS | E15: =VLOOKUP(folha1[[#This Row],[Razão Social]],Planilha1!A:C,3,0) -> REGIONAL | F15: RUA ALAN BOA VENTURA | G15: 178 | H15: VILA ELIANE | I15: SALA 02 | J15: CAMPO GRANDE | K15: MS | L15: 950 | M15: 100 | N15: =IF(folha1[[#This Row],[Participação (%)]]=100,"BASE PRÓPRIA","BASE POOL") -> BASE PRÓPRIA | O15: 893 | P15: 44174
A16: 00942246001235 | B16: SIMARELLI DISTRIBUIDORA DE DERIVADOS DE PETRÓLEO LTDA. | C16: =VLOOKUP(folha1[[#This Row],[Razão Social]],Planilha1!A:C,2,0) -> SIMARELLI . | D16: BASES DO RAMO DE COMBUSTÍVEIS | E16: =VLOOKUP(folha1[[#This Row],[Razão Social]],Planilha1!A:C,3,0) -> REGIONAL | F16: Rua N | G16: S/N | H16: Jardim Industriário | I16: LOTE 22 E 23 | J16: CUIABA | K16: MT | L16: 855.41 | M16: 100 | N16: =IF(folha1[[#This Row],[Participação (%)]]=100,"BASE PRÓPRIA","BASE POOL") -> BASE PRÓPRIA | O16: 583 | P16: 44061
A17: 01083568000186 | B17: LIDERPETRO DISTRIBUIDORA DE PETRÓLEO LTDA | C17: =VLOOKUP(folha1[[#This Row],[Razão Social]],Planilha1!A:C,2,0) -> LIDERPETRO | D17: BASES DO RAMO DE COMBUSTÍVEIS | E17: =VLOOKUP(folha1[[#This Row],[Razão Social]],Planilha1!A:C,3,0) -> REGIONAL | F17: Avenida Aldo Borges Leão | G17: 4911 | H17: MORADA NOVA | I17: SALA SEM INSC. MUNIC | J17: UBERLANDIA | K17: MG | L17: 6123.7 | M17: 30.55 | N17: =IF(folha1[[#This Row],[Participação (%)]]=100,"BASE PRÓPRIA","BASE POOL") -> BASE POOL | O17: 153 | P17: 46104
A18: 01083568000348 | B18: LIDERPETRO DISTRIBUIDORA DE PETRÓLEO LTDA | C18: =VLOOKUP(folha1[[#This Row],[Razão Social]],Planilha1!A:C,2,0) -> LIDERPETRO | D18: BASES DO RAMO DE COMBUSTÍVEIS | E18: =VLOOKUP(folha1[[#This Row],[Razão Social]],Planilha1!A:C,3,0) -> REGIONAL | F18: RUA NITEROI, ESQUINA COM RUA COPACABANA, | G18: S/Nº | H18: SETOR COMERCIAL CANEDO | I18: QUADRA 04 - LOTE 1/19 - COND. POOL PETROBALL | J18: SENADOR CANEDO | K18: GO | L18: 13681.7 | M18: 6 | N18: =IF(folha1[[#This Row],[Participação (%)]]=100,"BASE PRÓPRIA","BASE POOL") -> BASE POOL | O18: 324 | P18: 45817
A19: 01125282000388 | B19: PETROBAHIA S/A | C19: =VLOOKUP(folha1[[#This Row],[Razão Social]],Planilha1!A:C,2,0) -> PETROBAHIA | D19: BASES DO RAMO DE COMBUSTÍVEIS | E19: =VLOOKUP(folha1[[#This Row],[Razão Social]],Planilha1!A:C,3,0) -> REGIONAL | F19: RODOVIA BR 415 | G19: S/N | H19: Centro Industrial | I19: KM 5 | J19: ITABUNA | K19: BA | L19: 5426.63 | M19: 100 | N19: =IF(folha1[[#This Row],[Participação (%)]]=100,"BASE PRÓPRIA","BASE POOL") -> BASE PRÓPRIA | O19: 355 | P19: 43983
A20: 01125282000620 | B20: PETROBAHIA S/A | C20: =VLOOKUP(folha1[[#This Row],[Razão Social]],Planilha1!A:C,2,0) -> PETROBAHIA | D20: BASES DO RAMO DE COMBUSTÍVEIS | E20: =VLOOKUP(folha1[[#This Row],[Razão Social]],Planilha1!A:C,3,0) -> REGIONAL | F20: RUA GLAUBER ROCHA | G20: S/Nº | H20: Jardim Paraíso | J20: LUIS EDUARDO MAGALHAES | K20: BA | L20: 2024.6 | M20: 100 | N20: =IF(folha1[[#This Row],[Participação (%)]]=100,"BASE PRÓPRIA","BASE POOL") -> BASE PRÓPRIA | O20: 300 | P20: 43601
A21: 01125282000701 | B21: PETROBAHIA S/A | C21: =VLOOKUP(folha1[[#This Row],[Razão Social]],Planilha1!A:C,2,0) -> PETROBAHIA | D21: BASES DO RAMO DE COMBUSTÍVEIS | E21: =VLOOKUP(folha1[[#This Row],[Razão Social]],Planilha1!A:C,3,0) -> REGIONAL | F21: QUADRA A - LOTES 12 E 13 | G21: . | H21: DISTRITO INDUSTRIAL | J21: JUAZEIRO | K21: BA | L21: 3399.75 | M21: 100 | N21: =IF(folha1[[#This Row],[Participação (%)]]=100,"BASE PRÓPRIA","BASE POOL") -> BASE PRÓPRIA | O21: 796 | P21: 45644
A22: 01125282001198 | B22: PETROBAHIA S/A | C22: =VLOOKUP(folha1[[#This Row],[Razão Social]],Planilha1!A:C,2,0) -> PETROBAHIA | D22: BASES DO RAMO DE COMBUSTÍVEIS | E22: =VLOOKUP(folha1[[#This Row],[Razão Social]],Planilha1!A:C,3,0) -> REGIONAL | F22: ROD BA 523 (RODOVIA CANDEIAS - MADRE DE DEUS) | G22: S/N | H22: MATARIPE | I22: KM 07 | J22: SAO FRANCISCO DO CONDE | K22: BA | L22: 15864.46 | M22: 100 | N22: =IF(folha1[[#This Row],[Participação (%)]]=100,"BASE PRÓPRIA","BASE POOL") -> BASE PRÓPRIA | O22: 88 | P22: 44606
A23: 01125282001945 | B23: PETROBAHIA S/A | C23: =VLOOKUP(folha1[[#This Row],[Razão Social]],Planilha1!A:C,2,0) -> PETROBAHIA | D23: BASES DO RAMO DE COMBUSTÍVEIS | E23: =VLOOKUP(folha1[[#This Row],[Razão Social]],Planilha1!A:C,3,0) -> REGIONAL | F23: RUA PROJETADA | G23: S/N | H23: Centro | I23: SETOR 19 QUADRA02 LOTE 12 | J23: BALSAS | K23: MA | L23: 1140 | M23: 100 | N23: =IF(folha1[[#This Row],[Participação (%)]]=100,"BASE PRÓPRIA","BASE POOL") -> BASE PRÓPRIA | O23: 313 | P23: 45048
A24: 01125282002160 | B24: PETROBAHIA S/A | C24: =VLOOKUP(folha1[[#This Row],[Razão Social]],Planilha1!A:C,2,0) -> PETROBAHIA | D24: BASES DO RAMO DE COMBUSTÍVEIS | E24: =VLOOKUP(folha1[[#This Row],[Razão Social]],Planilha1!A:C,3,0) -> REGIONAL | F24: RUA NITEROI, ESQUINA COM RUA COPACABANA, | G24: S/Nº | H24: SETOR COMERCIAL CANEDO | I24: QUADRA 04 - LOTE 1/19 - COND. POOL PETROBALL | J24: SENADOR CANEDO | K24: GO | L24: 13681.7 | M24: 6 | N24: =IF(folha1[[#This Row],[Participação (%)]]=100,"BASE PRÓPRIA","BASE POOL") -> BASE POOL | O24: 324 | P24: 45817
A25: 01136600000144 | B25: TRANSO COMBUSTÍVEIS LTDA | C25: =VLOOKUP(folha1[[#This Row],[Razão Social]],Planilha1!A:C,2,0) -> TRANSO COMBUSTÍVEIS | D25: BASES DO RAMO DE COMBUSTÍVEIS | E25: =VLOOKUP(folha1[[#This Row],[Razão Social]],Planilha1!A:C,3,0) -> REGIONAL | F25: Avenida Estocolmo | G25: 1438 | H25: Cascata | J25: PAULINIA | K25: SP | L25: 19710 | M25: 69.9 | N25: =IF(folha1[[#This Row],[Participação (%)]]=100,"BASE PRÓPRIA","BASE POOL") -> BASE POOL | O25: 935 | P25: 43810
A26: 01228749000153 | B26: PETRO DALLAS DO BRASIL LTDA. | C26: =VLOOKUP(folha1[[#This Row],[Razão Social]],Planilha1!A:C,2,0) -> PETRO DALLAS DO BRASIL . | D26: BASES DO RAMO DE COMBUSTÍVEIS | E26: =VLOOKUP(folha1[[#This Row],[Razão Social]],Planilha1!A:C,3,0) -> REGIONAL | F26: Avenida Airton Borges da Silva | G26: 1279 | H26: Distrito Industrial | J26: UBERLANDIA | K26: MG | L26: 5531.92 | M26: 86.44 | N26: =IF(folha1[[#This Row],[Participação (%)]]=100,"BASE PRÓPRIA","BASE POOL") -> BASE POOL | O26: 250 | P26: 46162
A27: 01241994000443 | B27: TDC DISTRIBUIDORA DE COMBUSTÍVEIS S/A. | C27: =VLOOKUP(folha1[[#This Row],[Razão Social]],Planilha1!A:C,2,0) -> TDC . | D27: BASES DO RAMO DE COMBUSTÍVEIS | E27: =VLOOKUP(folha1[[#This Row],[Razão Social]],Planilha1!A:C,3,0) -> REGIONAL | F27: VIA MADRE DE DEUS | G27: S/N | H27: CAIPÉ | I27: KM 42,5 | J27: SAO FRANCISCO DO CONDE | K27: BA | L27: 7172 | M27: 100 | N27: =IF(folha1[[#This Row],[Participação (%)]]=100,"BASE PRÓPRIA","BASE POOL") -> BASE PRÓPRIA | O27: 638 | P27: 45575
A28: 01241994000605 | B28: TDC DISTRIBUIDORA DE COMBUSTÍVEIS S/A. | C28: =VLOOKUP(folha1[[#This Row],[Razão Social]],Planilha1!A:C,2,0) -> TDC . | D28: BASES DO RAMO DE COMBUSTÍVEIS | E28: =VLOOKUP(folha1[[#This Row],[Razão Social]],Planilha1!A:C,3,0) -> REGIONAL | F28: RUA NITEROI, ESQUINA COM RUA COPACABANA, | G28: S/Nº | H28: SETOR COMERCIAL CANEDO | I28: QUADRA 04 - LOTE 1/19 - COND. POOL PETROBALL | J28: SENADOR CANEDO | K28: GO | L28: 13681.7 | M28: 21.98 | N28: =IF(folha1[[#This Row],[Participação (%)]]=100,"BASE PRÓPRIA","BASE POOL") -> BASE POOL | O28: 324 | P28: 45817
A29: 01241994001172 | B29: TDC DISTRIBUIDORA DE COMBUSTÍVEIS S/A. | C29: =VLOOKUP(folha1[[#This Row],[Razão Social]],Planilha1!A:C,2,0) -> TDC . | D29: BASES DO RAMO DE COMBUSTÍVEIS | E29: =VLOOKUP(folha1[[#This Row],[Razão Social]],Planilha1!A:C,3,0) -> REGIONAL | F29: SETOR INDUSTRIAL SUL -SIN/SUL | G29: S/N | H29: ZONA INDUSTRIAL (GUARÁ) | I29: LOTE 02 A - SETOR INFLAMÁVEIS | J29: BRASILIA | K29: DF | L29: 6329.87 | M29: 33.33 | N29: =IF(folha1[[#This Row],[Participação (%)]]=100,"BASE PRÓPRIA","BASE POOL") -> BASE POOL | O29: 793 | P29: 44141
A30: 01241994001415 | B30: TDC DISTRIBUIDORA DE COMBUSTÍVEIS S/A. | C30: =VLOOKUP(folha1[[#This Row],[Razão Social]],Planilha1!A:C,2,0) -> TDC . | D30: BASES DO RAMO DE COMBUSTÍVEIS | E30: =VLOOKUP(folha1[[#This Row],[Razão Social]],Planilha1!A:C,3,0) -> REGIONAL | F30: Rodovia BA 523 | G30: S/Nº | H30: . | J30: SAO FRANCISCO DO CONDE | K30: BA | L30: 6747.18 | M30: 100 | N30: =IF(folha1[[#This Row],[Participação (%)]]=100,"BASE PRÓPRIA","BASE POOL") -> BASE PRÓPRIA | O30: 99 | P30: 42814
A31: 01241994001504 | B31: TDC DISTRIBUIDORA DE COMBUSTÍVEIS S/A. | C31: =VLOOKUP(folha1[[#This Row],[Razão Social]],Planilha1!A:C,2,0) -> TDC . | D31: BASES DO RAMO DE COMBUSTÍVEIS | E31: =VLOOKUP(folha1[[#This Row],[Razão Social]],Planilha1!A:C,3,0) -> REGIONAL | F31: Avenida Aldo Borges Leão | G31: 4911 | H31: MORADA NOVA | I31: SALA SEM INSC. MUNIC | J31: UBERLANDIA | K31: MG | L31: 6123.7 | M31: 12.25 | N31: =IF(folha1[[#This Row],[Participação (%)]]=100,"BASE PRÓPRIA","BASE POOL") -> BASE POOL | O31: 153 | P31: 46104
A32: 01241994001687 | B32: TDC DISTRIBUIDORA DE COMBUSTÍVEIS S/A. | C32: =VLOOKUP(folha1[[#This Row],[Razão Social]],Planilha1!A:C,2,0) -> TDC . | D32: BASES DO RAMO DE COMBUSTÍVEIS | E32: =VLOOKUP(folha1[[#This Row],[Razão Social]],Planilha1!A:C,3,0) -> REGIONAL | F32: ROD PATIO DE INTEGRACAO INTERMODAL DA FERROVIANORTE -SUL, RODOV | G32: S/N | H32: Setor Central | J32: PORTO NACIONAL | K32: TO | L32: 10685.25 | M32: 100 | N32: =IF(folha1[[#This Row],[Participação (%)]]=100,"BASE PRÓPRIA","BASE POOL") -> BASE PRÓPRIA | O32: 165 | P32: 44280
A33: 01256137000174 | B33: DISTRIBUIDORA RIO BRANCO DE PETRÓLEO LTDA. | C33: =VLOOKUP(folha1[[#This Row],[Razão Social]],Planilha1!A:C,2,0) -> RIO BRANCO DE PETRÓLEO . | D33: BASES DO RAMO DE COMBUSTÍVEIS | E33: =VLOOKUP(folha1[[#This Row],[Razão Social]],Planilha1!A:C,3,0) -> REGIONAL | F33: AVENIDA RIO GRANDE | G33: 5000 | H33: BAIRRO INDUSTRIAL III | J33: UBERABA | K33: MG | L33: 790.05 | M33: 100 | N33: =IF(folha1[[#This Row],[Participação (%)]]=100,"BASE PRÓPRIA","BASE POOL") -> BASE PRÓPRIA | O33: 76 | P33: 43873
A34: 01256137000417 | B34: DISTRIBUIDORA RIO BRANCO DE PETRÓLEO LTDA. | C34: =VLOOKUP(folha1[[#This Row],[Razão Social]],Planilha1!A:C,2,0) -> RIO BRANCO DE PETRÓLEO . | D34: BASES DO RAMO DE COMBUSTÍVEIS | E34: =VLOOKUP(folha1[[#This Row],[Razão Social]],Planilha1!A:C,3,0) -> REGIONAL | F34: RUA NITEROI, ESQUINA COM RUA COPACABANA, | G34: S/Nº | H34: SETOR COMERCIAL CANEDO | I34: QUADRA 04 - LOTE 1/19 - COND. POOL PETROBALL | J34: SENADOR CANEDO | K34: GO | L34: 13681.7 | M34: 6 | N34: =IF(folha1[[#This Row],[Participação (%)]]=100,"BASE PRÓPRIA","BASE POOL") -> BASE POOL | O34: 324 | P34: 45817
A35: 01256137000506 | B35: DISTRIBUIDORA RIO BRANCO DE PETRÓLEO LTDA. | C35: =VLOOKUP(folha1[[#This Row],[Razão Social]],Planilha1!A:C,2,0) -> RIO BRANCO DE PETRÓLEO . | D35: BASES DO RAMO DE COMBUSTÍVEIS | E35: =VLOOKUP(folha1[[#This Row],[Razão Social]],Planilha1!A:C,3,0) -> REGIONAL | F35: Avenida Aldo Borges Leão | G35: 4911 | H35: MORADA NOVA | I35: SALA SEM INSC. MUNIC | J35: UBERLANDIA | K35: MG | L35: 6123.7 | M35: 12.25 | N35: =IF(folha1[[#This Row],[Participação (%)]]=100,"BASE PRÓPRIA","BASE POOL") -> BASE POOL | O35: 153 | P35: 46104
A36: 01256137000689 | B36: DISTRIBUIDORA RIO BRANCO DE PETRÓLEO LTDA. | C36: =VLOOKUP(folha1[[#This Row],[Razão Social]],Planilha1!A:C,2,0) -> RIO BRANCO DE PETRÓLEO . | D36: BASES DO RAMO DE COMBUSTÍVEIS | E36: =VLOOKUP(folha1[[#This Row],[Razão Social]],Planilha1!A:C,3,0) -> REGIONAL | F36: RODOVIA BR-381 FERNAO DIAS KM 483,8 | G36: A/N | H36: DISTRITO INDUSTRIAL JARDIM PIEMONT SUL | I36: SALAS 06, 07 E 08 | J36: BETIM | K36: MG | L36: 8187.78 | M36: 30 | N36: =IF(folha1[[#This Row],[Participação (%)]]=100,"BASE PRÓPRIA","BASE POOL") -> BASE POOL | O36: 893 | P36: 43801
A37: 01256137000760 | B37: DISTRIBUIDORA RIO BRANCO DE PETRÓLEO LTDA. | C37: =VLOOKUP(folha1[[#This Row],[Razão Social]],Planilha1!A:C,2,0) -> RIO BRANCO DE PETRÓLEO . | D37: BASES DO RAMO DE COMBUSTÍVEIS | E37: =VLOOKUP(folha1[[#This Row],[Razão Social]],Planilha1!A:C,3,0) -> REGIONAL | F37: Via José Luiz Galvão | G37: 2200 | H37: Bom Jesus | J37: RIBEIRAO PRETO | K37: SP | L37: 11732.83 | M37: 5.95 | N37: =IF(folha1[[#This Row],[Participação (%)]]=100,"BASE PRÓPRIA","BASE POOL") -> BASE POOL | O37: 717 | P37: 45183
A38: 01317309000253 | B38: DISTRIBUIDORA DE PRODUTOS DE PETRÓLEO CHARRUA LTDA | C38: =VLOOKUP(folha1[[#This Row],[Razão Social]],Planilha1!A:C,2,0) -> CHARRUA | D38: BASES DO RAMO DE COMBUSTÍVEIS | E38: =VLOOKUP(folha1[[#This Row],[Razão Social]],Planilha1!A:C,3,0) -> REGIONAL | F38: Rua João Luiz da Rocha | G38: 136 | H38: Santo André | J38: LAJEADO | K38: RS | L38: 1807.87 | M38: 100 | N38: =IF(folha1[[#This Row],[Participação (%)]]=100,"BASE PRÓPRIA","BASE POOL") -> BASE PRÓPRIA | O38: 172 | P38: 37834
A39: 01317309000768 | B39: DISTRIBUIDORA DE PRODUTOS DE PETRÓLEO CHARRUA LTDA | C39: =VLOOKUP(folha1[[#This Row],[Razão Social]],Planilha1!A:C,2,0) -> CHARRUA | D39: BASES DO RAMO DE COMBUSTÍVEIS | E39: =VLOOKUP(folha1[[#This Row],[Razão Social]],Planilha1!A:C,3,0) -> REGIONAL | F39: RODOVIA BR 285 | G39: S/N | H39: INTERIOR | I39: KM 477 - MAIS 150 METROS | J39: CORONEL BARROS | K39: RS | L39: 4441.44 | M39: 100 | N39: =IF(folha1[[#This Row],[Participação (%)]]=100,"BASE PRÓPRIA","BASE POOL") -> BASE PRÓPRIA | O39: 325 | P39: 44355
A40: 01349764000400 | B40: ROYAL FIC DISTRIBUIDORA DE DERIVADOS DE PETRÓLEO S/A | C40: =VLOOKUP(folha1[[#This Row],[Razão Social]],Planilha1!A:C,2,0) -> ROYAL FIC | D40: BASES DO RAMO DE COMBUSTÍVEIS | E40: =VLOOKUP(folha1[[#This Row],[Razão Social]],Planilha1!A:C,3,0) -> REGIONAL | F40: Avenida Senador Onofre Quinan | G40: 415 | H40: Bonfim | I40: SÍTIO BONFIM | J40: PAULINIA | K40: SP | L40: 11741.72 | M40: 100 | N40: =IF(folha1[[#This Row],[Participação (%)]]=100,"BASE PRÓPRIA","BASE POOL") -> BASE PRÓPRIA | O40: 747 | P40: 44525
...

Sheet Planilha1
A1: Razão Social | B1: Razão Social | C1: TIPO
A2: 76 OIL DISTRIBUIDORA DE COMBUSTÍVEIS S/A | B2: 76 OIL | C2: REGIONAL
A3: ACAI PARA COMERCIO DE PETROLEO LTDA | B3: ACAI PARA COMERCIO DE PETROLEO | C3: REGIONAL
A4: ACAI PETROLEO MATO GROSSO LTDA | B4: ACAI PETROLEO MATO GROSSO | C4: REGIONAL
A5: ACOL DISTRIBUIDORA DE COMBUSTÍVEIS LTDA. | B5: ACOL . | C5: REGIONAL
A6: AGILE LOGISTICA E DISTRIBUIÇÃO DE COMBUSTÍVEIS LTDA | B6: AGILE LOGISTICA E | C6: REGIONAL
A7: ALCOOLBRAS - ÁLCOOL DO BRASIL DISTRIBUIDORA DE COMBUSTÍVEIS LTDA. | B7: ALCOOLBRAS - ÁLCOOL DO BRASIL . | C7: REGIONAL
A8: ALE COMBUSTIVEIS S.A. | B8: ALE COMBUSTIVEIS | C8: REGIONAL
A9: ALFA DISTRIBUIDORA DE PETRÓLEO LTDA. | B9: ALFA . | C9: REGIONAL
A10: ALL DISTRIBUIDORA DE COMBUSTÍVEIS EIRELI | B10: ALL EIRELI | C10: REGIONAL
A11: ALLGREEN DISTRIBUIDORA DE COMBUSTÍVEIS LTDA. | B11: ALLGREEN . | C11: REGIONAL
A12: ALPES DISTRIBUIDORA DE PETRÓLEO LTDA. | B12: ALPES . | C12: REGIONAL
... A182: YPETRO DISTRIBUIDORA DE COMBUSTIVEIS S.A. | B182: YPETRO | C182: REGIONAL
