Workbook

Sheet BaseRelatório
A1: ID | B1: DATA CONTABIL | C1: COD.FILIAL | D1: FILIAL | E1: CONGENERE | F1: TIPO DE COBRANÇA | G1: Valor Orçado | H1: Volume Orçado
A2: 1503 | B2: 45658 | C2: 1 | D2: Betim | E2: Atlantica | F2: Avanço Espaço | G2: 0 | H2: 0
A3: 1503 | B3: 45658 | C3: 1 | D3: Betim | E3: Atlantica | F3: Avanço Horário | G3: 0 | H3: 0
A4: 1503 | B4: 45658 | C4: 1 | D4: Betim | E4: Atlantica | F4: Operação Normal | G4: 89789.37 | H4: 2040
A5: 1503 | B5: 45658 | C5: 1 | D5: Betim | E5: Atlantica | F5: Outras Receitas | G5: 0 | H5: 0
A6: 1102 | B6: 45658 | C6: 1 | D6: Betim | E6: Ciapetro | F6: Avanço Espaço | G6: 0 | H6: 0
A7: 1102 | B7: 45658 | C7: 1 | D7: Betim | E7: Ciapetro | F7: Avanço Horário | G7: 0 | H7: 0
A8: 1102 | B8: 45658 | C8: 1 | D8: Betim | E8: Ciapetro | F8: Operação Normal | G8: 28839.059 | H8: 1500
A9: 1102 | B9: 45658 | C9: 1 | D9: Betim | E9: Ciapetro | F9: Outras Receitas | G9: 0 | H9: 0
A10: 16 | B10: 45658 | C10: 1 | D10: Betim | E10: Rede Sol | F10: Avanço Espaço | G10: 0 | H10: 0
A11: 16 | B11: 45658 | C11: 1 | D11: Betim | E11: Rede Sol | F11: Avanço Horário | G11: 0 | H11: 0
A12: 16 | B12: 45658 | C12: 1 | D12: Betim | E12: Rede Sol | F12: Operação Normal | G12: 9355.5094 | H12: 300
A13: 16 | B13: 45658 | C13: 1 | D13: Betim | E13: Rede Sol | F13: Outras Receitas | G13: 0 | H13: 0
... A17: 1401 | B17: 45658 | C17: 1 | D17: Betim | E17: Tobras | F17: Outras Receitas | G17: 0 | H17: 0
A18: 115 | B18: 45658 | C18: 11 | D18: Duque de Caxias | E18: =_xlfn.XLOOKUP(TabReceitas[[#This Row],[ID]],TabCondicoesComerciais[ID],TabCondicoesComerciais[Congênere],"Verificar") -> Rede Sol | F18: Avanço Espaço | G18: 0 | H18: 0
A19: 115 | B19: 45658 | C19: 11 | D19: Duque de Caxias | E19: =_xlfn.XLOOKUP(TabReceitas[[#This Row],[ID]],TabCondicoesComerciais[ID],TabCondicoesComerciais[Congênere],"Verificar") -> Rede Sol | F19: Avanço Horário | G19: 0 | H19: 0
A20: 115 | B20: 45658 | C20: 11 | D20: Duque de Caxias | E20: =_xlfn.XLOOKUP(TabReceitas[[#This Row],[ID]],TabCondicoesComerciais[ID],TabCondicoesComerciais[Congênere],"Verificar") -> Rede Sol | F20: Operação Normal | G20: 56842.105 | H20: 2000
A21: 115 | B21: 45658 | C21: 11 | D21: Duque de Caxias | E21: =_xlfn.XLOOKUP(TabReceitas[[#This Row],[ID]],TabCondicoesComerciais[ID],TabCondicoesComerciais[Congênere],"Verificar") -> Rede Sol | F21: Outras Receitas | G21: 0 | H21: 0
A22: 11104 | B22: 45658 | C22: 11 | D22: Duque de Caxias | E22: =_xlfn.XLOOKUP(TabReceitas[[#This Row],[ID]],TabCondicoesComerciais[ID],TabCondicoesComerciais[Congênere],"Verificar") -> Ruff | F22: Avanço Espaço | G22: 0 | H22: 0
A23: 11104 | B23: 45658 | C23: 11 | D23: Duque de Caxias | E23: =_xlfn.XLOOKUP(TabReceitas[[#This Row],[ID]],TabCondicoesComerciais[ID],TabCondicoesComerciais[Congênere],"Verificar") -> Ruff | F23: Avanço Horário | G23: 0 | H23: 0
A24: 11104 | B24: 45658 | C24: 11 | D24: Duque de Caxias | E24: =_xlfn.XLOOKUP(TabReceitas[[#This Row],[ID]],TabCondicoesComerciais[ID],TabCondicoesComerciais[Congênere],"Verificar") -> Ruff | F24: Operação Normal | G24: 0 | H24: 0
A25: 11104 | B25: 45658 | C25: 11 | D25: Duque de Caxias | E25: =_xlfn.XLOOKUP(TabReceitas[[#This Row],[ID]],TabCondicoesComerciais[ID],TabCondicoesComerciais[Congênere],"Verificar") -> Ruff | F25: Outras Receitas | G25: 0 | H25: 0
A26: 13300 | B26: 45658 | C26: 13 | D26: Goiânia | E26: Petrobahia | F26: Avanço Espaço | G26: 0 | H26: 0
A27: 13300 | B27: 45658 | C27: 13 | D27: Goiânia | E27: Petrobahia | F27: Avanço Horário | G27: 0 | H27: 0
A28: 13300 | B28: 45658 | C28: 13 | D28: Goiânia | E28: Petrobahia | F28: Operação Normal | G28: 86210.526 | H28: 4200
A29: 13300 | B29: 45658 | C29: 13 | D29: Goiânia | E29: Petrobahia | F29: Outras Receitas | G29: 0 | H29: 0
A30: 38203 | B30: 45658 | C30: 38 | D30: Guamaré | E30: Raízen | F30: Avanço Espaço | G30: 0 | H30: 0
A31: 38203 | B31: 45658 | C31: 38 | D31: Guamaré | E31: Raízen | F31: Avanço Horário | G31: 0 | H31: 0
A32: 38203 | B32: 45658 | C32: 38 | D32: Guamaré | E32: Raízen | F32: Operação Normal | G32: 137499.16 | H32: 4200
A33: 38203 | B33: 45658 | C33: 38 | D33: Guamaré | E33: Raízen | F33: Outras Receitas | G33: 0 | H33: 0
A34: 16203 | B34: 45658 | C34: 16 | D34: Guarulhos | E34: Raízen | F34: Avanço Espaço | G34: 0 | H34: 0
A35: 16203 | B35: 45658 | C35: 16 | D35: Guarulhos | E35: Raízen | F35: Avanço Horário | G35: 0 | H35: 0
A36: 16203 | B36: 45658 | C36: 16 | D36: Guarulhos | E36: Raízen | F36: Operação Normal | G36: 164947.61 | H36: 6100
A37: 16203 | B37: 45658 | C37: 16 | D37: Guarulhos | E37: Raízen | F37: Outras Receitas | G37: 0 | H37: 0
... A41: 49102 | B41: 45658 | C41: 49 | D41: Luis Eduardo Magalhães | E41: Ipiranga | F41: Outras Receitas | G41: 0 | H41: 0
A42: 20105 | B42: 45658 | C42: 20 | D42: São José do Rio Preto | E42: Ruff | F42: Avanço Espaço | G42: 0 | H42: 0
A43: 20105 | B43: 45658 | C43: 20 | D43: São José do Rio Preto | E43: Ruff | F43: Avanço Horário | G43: 0 | H43: 0
A44: 20105 | B44: 45658 | C44: 20 | D44: São José do Rio Preto | E44: Ruff | F44: Operação Normal | G44: 16282.577 | H44: 545
A45: 20105 | B45: 45658 | C45: 20 | D45: São José do Rio Preto | E45: Ruff | F45: Outras Receitas | G45: 0 | H45: 0
A46: 1503 | B46: 45689 | C46: 1 | D46: Betim | E46: Atlantica | F46: Avanço Espaço | G46: 0 | H46: 0
...

Sheet Receitas
A1: ID | B1: DATA CONTABIL | C1: Gerência | D1: Núcleo | E1: Corredor | F1: COD.FILIAL | G1: FILIAL | H1: CONGENERE | I1: TIPO DE COBRANÇA | J1: Valor Orçado | K1: Volume Orçado | L1: Valor Total R$ | M1: Vol. Movimentado M³ | N1: Nº NF | O1: Justificativas | P1: Volume Mínimo | Q1: Volume 1º Giro | R1: Tarifa 1º Giro | S1: Tarifa 2º Giro | T1: Tarifa Cobrada | U1: Tarifa Efetiva | V1: Valor Contrato | W1: Valor Movimentado | X1: Check Tarifa
A2: 1503 | B2: 45658 | C2: BRASILIA | D2: MG RJ ES | E2: MINAS CENTRAL | F2: 1 | G2: Betim | H2: Atlantica | I2: Avanço Espaço | J2: 0 | K2: 0 | P2: =IF(BD_Receitas[[#This Row],[TIPO DE COBRANÇA]]="Operação Normal", _xlfn.XLOOKUP(BD_Receitas[[#This Row],[ID]],TabCondicoesComerciais[ID],TabCondicoesComerciais[Volume mínimo (m3)],0),"") | Q2: =_xlfn.XLOOKUP(BD_Receitas[[#This Row],[ID]],TabCondicoesComerciais[ID],TabCondicoesComerciais[Vol. 1ºGiro],0) -> 360 | R2: =IF(BD_Receitas[[#This Row],[TIPO DE COBRANÇA]]="Avanço Espaço", _xlfn.XLOOKUP(BD_Receitas[[#This Row],[ID]],TabCondicoesComerciais[ID],TabCondicoesComerciais[Avanço Espaço],0), IF(BD_Receitas[[#This Row],[TIPO DE COBRANÇA]]="Avanço Horário", _xlfn.XLOOKUP(BD_Receitas[[#This Row],[ID]],TabCondicoesComerciais[ID],TabCondicoesComerciais[Avanço Horário],0), IF(BD_Receitas[[#This Row],[TIPO DE COBRANÇA]]="Operação Normal", _xlfn.XLOOKUP(BD_Receitas[[#This Row],[ID]],TabCondicoesComerciais[ID],TabCondicoesComerciais[Tarifa 1º Giro],0),0))) -> 16.364 | S2: =IF(BD_Receitas[[#This Row],[TIPO DE COBRANÇA]]="Operação Normal", _xlfn.XLOOKUP(BD_Receitas[[#This Row],[ID]],TabCondicoesComerciais[ID],TabCondicoesComerciais[Tarifa 2º Giro],0),0) -> 0 | T2: =IFERROR(IF(BD_Receitas[[#This Row],[TIPO DE COBRANÇA]]<>"Operação Normal","",BD_Receitas[[#This Row],[Valor Total R$]]/ MAX(BD_Receitas[[#This Row],[Vol. Movimentado M³]], BD_Receitas[[#This Row],[Volume Mínimo ]]) ),0) | U2: =IFERROR(IF(BD_Receitas[[#This Row],[TIPO DE COBRANÇA]]<>"Operação Normal","", SUMIFS(BD_Receitas[Valor Total R$],BD_Receitas[CONGENERE],BD_Receitas[[#This Row],[CONGENERE]],BD_Receitas[FILIAL],BD_Receitas[[#This Row],[FILIAL]],BD_Receitas[DATA CONTABIL],BD_Receitas[[#This Row],[DATA CONTABIL]]) /BD_Receitas[[#This Row],[Vol. Movimentado M³]] ),0) | V2: =IF(BD_Receitas[[#This Row],[TIPO DE COBRANÇA]]<>"Operação Normal","",(BD_Receitas[[#This Row],[Volume 1º Giro]]*BD_Receitas[[#This Row],[Tarifa 1º Giro]])+(BD_Receitas[[#This Row],[Volume Mínimo ]]-BD_Receitas[[#This Row],[Volume 1º Giro]])*BD_Receitas[[#This Row],[Tarifa 2º Giro]]) | W2: =IF(BD_Receitas[[#This Row],[TIPO DE COBRANÇA]]<>"OPERAÇÃO NORMAL","", IF(BD_Receitas[[#This Row],[Vol. Movimentado M³]]<BD_Receitas[[#This Row],[Volume 1º Giro]],BD_Receitas[[#This Row],[Vol. Movimentado M³]]* BD_Receitas[[#This Row],[Tarifa 1º Giro]], (BD_Receitas[[#This Row],[Volume 1º Giro]]*BD_Receitas[[#This Row],[Tarifa 1º Giro]])+(BD_Receitas[[#This Row],[Vol. Movimentado M³]]-BD_Receitas[[#This Row],[Volume 1º Giro]])*BD_Receitas[[#This Row],[Tarifa 2º Giro]]) ) | X2: =IF(BD_Receitas[[#This Row],[TIPO DE COBRANÇA]] <> "OPERAÇÃO NORMAL","", IF(BD_Receitas[[#This Row],[Vol. Movimentado M³]]= BD_Receitas[[#This Row],[Volume Mínimo ]], "Vol. Movimentado igual ao Vol. Mínimo", IF(ROUND(BD_Receitas[[#This Row],[Tarifa 1º Giro]],3) <> ROUND(BD_Receitas[[#This Row],[Tarifa Cobrada]],3), "Conferir tarifa cobrada", IF(BD_Receitas[[#This Row],[Volume Mínimo ]]=0,"Ok", IF(BD_Receitas[[#This Row],[Vol. Movimentado M³]]<= BD_Receitas[[#This Row],[Volume Mínimo ]], IF(ROUND(BD_Receitas[[#This Row],[Valor Total R$]],2) = ROUND(BD_Receitas[[#This Row],[Valor Total R$]],2), "Ok","Verificar Cobrança"), IF(ROUND(BD_Receitas[[#This Row],[Valor Contrato]],2) = ROUND(BD_Receitas[[#This Row],[Valor Movimentado]],2), "OK","Verificar cobrança") )))))
A3: 1503 | B3: 45658 | C3: BRASILIA | D3: MG RJ ES | E3: MINAS CENTRAL | F3: 1 | G3: Betim | H3: Atlantica | I3: Avanço Horário | J3: 0 | K3: 0 | P3: =IF(BD_Receitas[[#This Row],[TIPO DE COBRANÇA]]="Operação Normal", _xlfn.XLOOKUP(BD_Receitas[[#This Row],[ID]],TabCondicoesComerciais[ID],TabCondicoesComerciais[Volume mínimo (m3)],0),"") | Q3: =_xlfn.XLOOKUP(BD_Receitas[[#This Row],[ID]],TabCondicoesComerciais[ID],TabCondicoesComerciais[Vol. 1ºGiro],0) -> 360 | R3: =IF(BD_Receitas[[#This Row],[TIPO DE COBRANÇA]]="Avanço Espaço", _xlfn.XLOOKUP(BD_Receitas[[#This Row],[ID]],TabCondicoesComerciais[ID],TabCondicoesComerciais[Avanço Espaço],0), IF(BD_Receitas[[#This Row],[TIPO DE COBRANÇA]]="Avanço Horário", _xlfn.XLOOKUP(BD_Receitas[[#This Row],[ID]],TabCondicoesComerciais[ID],TabCondicoesComerciais[Avanço Horário],0), IF(BD_Receitas[[#This Row],[TIPO DE COBRANÇA]]="Operação Normal", _xlfn.XLOOKUP(BD_Receitas[[#This Row],[ID]],TabCondicoesComerciais[ID],TabCondicoesComerciais[Tarifa 1º Giro],0),0))) -> 15 | S3: =IF(BD_Receitas[[#This Row],[TIPO DE COBRANÇA]]="Operação Normal", _xlfn.XLOOKUP(BD_Receitas[[#This Row],[ID]],TabCondicoesComerciais[ID],TabCondicoesComerciais[Tarifa 2º Giro],0),0) -> 0 | T3: =IFERROR(IF(BD_Receitas[[#This Row],[TIPO DE COBRANÇA]]<>"Operação Normal","",BD_Receitas[[#This Row],[Valor Total R$]]/ MAX(BD_Receitas[[#This Row],[Vol. Movimentado M³]], BD_Receitas[[#This Row],[Volume Mínimo ]]) ),0) | U3: =IFERROR(IF(BD_Receitas[[#This Row],[TIPO DE COBRANÇA]]<>"Operação Normal","", SUMIFS(BD_Receitas[Valor Total R$],BD_Receitas[CONGENERE],BD_Receitas[[#This Row],[CONGENERE]],BD_Receitas[FILIAL],BD_Receitas[[#This Row],[FILIAL]],BD_Receitas[DATA CONTABIL],BD_Receitas[[#This Row],[DATA CONTABIL]]) /BD_Receitas[[#This Row],[Vol. Movimentado M³]] ),0) | V3: =IF(BD_Receitas[[#This Row],[TIPO DE COBRANÇA]]<>"Operação Normal","",(BD_Receitas[[#This Row],[Volume 1º Giro]]*BD_Receitas[[#This Row],[Tarifa 1º Giro]])+(BD_Receitas[[#This Row],[Volume Mínimo ]]-BD_Receitas[[#This Row],[Volume 1º Giro]])*BD_Receitas[[#This Row],[Tarifa 2º Giro]]) | W3: =IF(BD_Receitas[[#This Row],[TIPO DE COBRANÇA]]<>"OPERAÇÃO NORMAL","", IF(BD_Receitas[[#This Row],[Vol. Movimentado M³]]<BD_Receitas[[#This Row],[Volume 1º Giro]],BD_Receitas[[#This Row],[Vol. Movimentado M³]]* BD_Receitas[[#This Row],[Tarifa 1º Giro]], (BD_Receitas[[#This Row],[Volume 1º Giro]]*BD_Receitas[[#This Row],[Tarifa 1º Giro]])+(BD_Receitas[[#This Row],[Vol. Movimentado M³]]-BD_Receitas[[#This Row],[Volume 1º Giro]])*BD_Receitas[[#This Row],[Tarifa 2º Giro]]) ) | X3: =IF(BD_Receitas[[#This Row],[TIPO DE COBRANÇA]] <> "OPERAÇÃO NORMAL","", IF(BD_Receitas[[#This Row],[Vol. Movimentado M³]]= BD_Receitas[[#This Row],[Volume Mínimo ]], "Vol. Movimentado igual ao Vol. Mínimo", IF(ROUND(BD_Receitas[[#This Row],[Tarifa 1º Giro]],3) <> ROUND(BD_Receitas[[#This Row],[Tarifa Cobrada]],3), "Conferir tarifa cobrada", IF(BD_Receitas[[#This Row],[Volume Mínimo ]]=0,"Ok", IF(BD_Receitas[[#This Row],[Vol. Movimentado M³]]<= BD_Receitas[[#This Row],[Volume Mínimo ]], IF(ROUND(BD_Receitas[[#This Row],[Valor Total R$]],2) = ROUND(BD_Receitas[[#This Row],[Valor Total R$]],2), "Ok","Verificar Cobrança"), IF(ROUND(BD_Receitas[[#This Row],[Valor Contrato]],2) = ROUND(BD_Receitas[[#This Row],[Valor Movimentado]],2), "OK","Verificar cobrança") )))))
A4: 1503 | B4: 45658 | C4: BRASILIA | D4: MG RJ ES | E4: MINAS CENTRAL | F4: 1 | G4: Betim | H4: Atlantica | I4: Operação Normal | J4: 89789.37 | K4: 2040 | L4: 86753.01 | M4: 671.893 | N4: 17616 | O4: COBRANÇA DE ARMAZENAGEM CONJUNTA REFERENTE A DEZ/2024 | P4: =IF(BD_Receitas[[#This Row],[TIPO DE COBRANÇA]]="Operação Normal", _xlfn.XLOOKUP(BD_Receitas[[#This Row],[ID]],TabCondicoesComerciais[ID],TabCondicoesComerciais[Volume mínimo (m3)],0),"") -> 2040 | Q4: =_xlfn.XLOOKUP(BD_Receitas[[#This Row],[ID]],TabCondicoesComerciais[ID],TabCondicoesComerciais[Vol. 1ºGiro],0) -> 360 | R4: =IF(BD_Receitas[[#This Row],[TIPO DE COBRANÇA]]="Avanço Espaço", _xlfn.XLOOKUP(BD_Receitas[[#This Row],[ID]],TabCondicoesComerciais[ID],TabCondicoesComerciais[Avanço Espaço],0), IF(BD_Receitas[[#This Row],[TIPO DE COBRANÇA]]="Avanço Horário", _xlfn.XLOOKUP(BD_Receitas[[#This Row],[ID]],TabCondicoesComerciais[ID],TabCondicoesComerciais[Avanço Horário],0), IF(BD_Receitas[[#This Row],[TIPO DE COBRANÇA]]="Operação Normal", _xlfn.XLOOKUP(BD_Receitas[[#This Row],[ID]],TabCondicoesComerciais[ID],TabCondicoesComerciais[Tarifa 1º Giro],0),0))) -> 42.64 | S4: =IF(BD_Receitas[[#This Row],[TIPO DE COBRANÇA]]="Operação Normal", _xlfn.XLOOKUP(BD_Receitas[[#This Row],[ID]],TabCondicoesComerciais[ID],TabCondicoesComerciais[Tarifa 2º Giro],0),0) -> 42.64 | T4: =IFERROR(IF(BD_Receitas[[#This Row],[TIPO DE COBRANÇA]]<>"Operação Normal","",BD_Receitas[[#This Row],[Valor Total R$]]/ MAX(BD_Receitas[[#This Row],[Vol. Movimentado M³]], BD_Receitas[[#This Row],[Volume Mínimo ]]) ),0) -> 42.525985 | U4: =IFERROR(IF(BD_Receitas[[#This Row],[TIPO DE COBRANÇA]]<>"Operação Normal","", SUMIFS(BD_Receitas[Valor Total R$],BD_Receitas[CONGENERE],BD_Receitas[[#This Row],[CONGENERE]],BD_Receitas[FILIAL],BD_Receitas[[#This Row],[FILIAL]],BD_Receitas[DATA CONTABIL],BD_Receitas[[#This Row],[DATA CONTABIL]]) /BD_Receitas[[#This Row],[Vol. Movimentado M³]] ),0) -> 129.1173 | V4: =IF(BD_Receitas[[#This Row],[TIPO DE COBRANÇA]]<>"Operação Normal","",(BD_Receitas[[#This Row],[Volume 1º Giro]]*BD_Receitas[[#This Row],[Tarifa 1º Giro]])+(BD_Receitas[[#This Row],[Volume Mínimo ]]-BD_Receitas[[#This Row],[Volume 1º Giro]])*BD_Receitas[[#This Row],[Tarifa 2º Giro]]) -> 86985.6 | W4: =IF(BD_Receitas[[#This Row],[TIPO DE COBRANÇA]]<>"OPERAÇÃO NORMAL","", IF(BD_Receitas[[#This Row],[Vol. Movimentado M³]]<BD_Receitas[[#This Row],[Volume 1º Giro]],BD_Receitas[[#This Row],[Vol. Movimentado M³]]* BD_Receitas[[#This Row],[Tarifa 1º Giro]], (BD_Receitas[[#This Row],[Volume 1º Giro]]*BD_Receitas[[#This Row],[Tarifa 1º Giro]])+(BD_Receitas[[#This Row],[Vol. Movimentado M³]]-BD_Receitas[[#This Row],[Volume 1º Giro]])*BD_Receitas[[#This Row],[Tarifa 2º Giro]]) ) -> 28649.518 | X4: =IF(BD_Receitas[[#This Row],[TIPO DE COBRANÇA]] <> "OPERAÇÃO NORMAL","", IF(BD_Receitas[[#This Row],[Vol. Movimentado M³]]= BD_Receitas[[#This Row],[Volume Mínimo ]], "Vol. Movimentado igual ao Vol. Mínimo", IF(ROUND(BD_Receitas[[#This Row],[Tarifa 1º Giro]],3) <> ROUND(BD_Receitas[[#This Row],[Tarifa Cobrada]],3), "Conferir tarifa cobrada", IF(BD_Receitas[[#This Row],[Volume Mínimo ]]=0,"Ok", IF(BD_Receitas[[#This Row],[Vol. Movimentado M³]]<= BD_Receitas[[#This Row],[Volume Mínimo ]], IF(ROUND(BD_Receitas[[#This Row],[Valor Total R$]],2) = ROUND(BD_Receitas[[#This Row],[Valor Total R$]],2), "Ok","Verificar Cobrança"), IF(ROUND(BD_Receitas[[#This Row],[Valor Contrato]],2) = ROUND(BD_Receitas[[#This Row],[Valor Movimentado]],2), "OK","Verificar cobrança") ))))) -> Conferir tarifa cobrada
A5: 1503 | B5: 45658 | C5: BRASILIA | D5: MG RJ ES | E5: MINAS CENTRAL | F5: 1 | G5: Betim | H5: Atlantica | I5: Outras Receitas | J5: 0 | K5: 0 | P5: =IF(BD_Receitas[[#This Row],[TIPO DE COBRANÇA]]="Operação Normal", _xlfn.XLOOKUP(BD_Receitas[[#This Row],[ID]],TabCondicoesComerciais[ID],TabCondicoesComerciais[Volume mínimo (m3)],0),"") | Q5: =_xlfn.XLOOKUP(BD_Receitas[[#This Row],[ID]],TabCondicoesComerciais[ID],TabCondicoesComerciais[Vol. 1ºGiro],0) -> 360 | R5: =IF(BD_Receitas[[#This Row],[TIPO DE COBRANÇA]]="Avanço Espaço", _xlfn.XLOOKUP(BD_Receitas[[#This Row],[ID]],TabCondicoesComerciais[ID],TabCondicoesComerciais[Avanço Espaço],0), IF(BD_Receitas[[#This Row],[TIPO DE COBRANÇA]]="Avanço Horário", _xlfn.XLOOKUP(BD_Receitas[[#This Row],[ID]],TabCondicoesComerciais[ID],TabCondicoesComerciais[Avanço Horário],0), IF(BD_Receitas[[#This Row],[TIPO DE COBRANÇA]]="Operação Normal", _xlfn.XLOOKUP(BD_Receitas[[#This Row],[ID]],TabCondicoesComerciais[ID],TabCondicoesComerciais[Tarifa 1º Giro],0),0))) -> 0 | S5: =IF(BD_Receitas[[#This Row],[TIPO DE COBRANÇA]]="Operação Normal", _xlfn.XLOOKUP(BD_Receitas[[#This Row],[ID]],TabCondicoesComerciais[ID],TabCondicoesComerciais[Tarifa 2º Giro],0),0) -> 0 | T5: =IFERROR(IF(BD_Receitas[[#This Row],[TIPO DE COBRANÇA]]<>"Operação Normal","",BD_Receitas[[#This Row],[Valor Total R$]]/ MAX(BD_Receitas[[#This Row],[Vol. Movimentado M³]], BD_Receitas[[#This Row],[Volume Mínimo ]]) ),0) | U5: =IFERROR(IF(BD_Receitas[[#This Row],[TIPO DE COBRANÇA]]<>"Operação Normal","", SUMIFS(BD_Receitas[Valor Total R$],BD_Receitas[CONGENERE],BD_Receitas[[#This Row],[CONGENERE]],BD_Receitas[FILIAL],BD_Receitas[[#This Row],[FILIAL]],BD_Receitas[DATA CONTABIL],BD_Receitas[[#This Row],[DATA CONTABIL]]) /BD_Receitas[[#This Row],[Vol. Movimentado M³]] ),0) | V5: =IF(BD_Receitas[[#This Row],[TIPO DE COBRANÇA]]<>"Operação Normal","",(BD_Receitas[[#This Row],[Volume 1º Giro]]*BD_Receitas[[#This Row],[Tarifa 1º Giro]])+(BD_Receitas[[#This Row],[Volume Mínimo ]]-BD_Receitas[[#This Row],[Volume 1º Giro]])*BD_Receitas[[#This Row],[Tarifa 2º Giro]]) | W5: =IF(BD_Receitas[[#This Row],[TIPO DE COBRANÇA]]<>"OPERAÇÃO NORMAL","", IF(BD_Receitas[[#This Row],[Vol. Movimentado M³]]<BD_Receitas[[#This Row],[Volume 1º Giro]],BD_Receitas[[#This Row],[Vol. Movimentado M³]]* BD_Receitas[[#This Row],[Tarifa 1º Giro]], (BD_Receitas[[#This Row],[Volume 1º Giro]]*BD_Receitas[[#This Row],[Tarifa 1º Giro]])+(BD_Receitas[[#This Row],[Vol. Movimentado M³]]-BD_Receitas[[#This Row],[Volume 1º Giro]])*BD_Receitas[[#This Row],[Tarifa 2º Giro]]) ) | X5: =IF(BD_Receitas[[#This Row],[TIPO DE COBRANÇA]] <> "OPERAÇÃO NORMAL","", IF(BD_Receitas[[#This Row],[Vol. Movimentado M³]]= BD_Receitas[[#This Row],[Volume Mínimo ]], "Vol. Movimentado igual ao Vol. Mínimo", IF(ROUND(BD_Receitas[[#This Row],[Tarifa 1º Giro]],3) <> ROUND(BD_Receitas[[#This Row],[Tarifa Cobrada]],3), "Conferir tarifa cobrada", IF(BD_Receitas[[#This Row],[Volume Mínimo ]]=0,"Ok", IF(BD_Receitas[[#This Row],[Vol. Movimentado M³]]<= BD_Receitas[[#This Row],[Volume Mínimo ]], IF(ROUND(BD_Receitas[[#This Row],[Valor Total R$]],2) = ROUND(BD_Receitas[[#This Row],[Valor Total R$]],2), "Ok","Verificar Cobrança"), IF(ROUND(BD_Receitas[[#This Row],[Valor Contrato]],2) = ROUND(BD_Receitas[[#This Row],[Valor Movimentado]],2), "OK","Verificar cobrança") )))))
A6: 1102 | B6: 45658 | C6: BRASILIA | D6: MG RJ ES | E6: MINAS CENTRAL | F6: 1 | G6: Betim | H6: Ciapetro | I6: Avanço Espaço | J6: 0 | K6: 0 | P6: =IF(BD_Receitas[[#This Row],[TIPO DE COBRANÇA]]="Operação Normal", _xlfn.XLOOKUP(BD_Receitas[[#This Row],[ID]],TabCondicoesComerciais[ID],TabCondicoesComerciais[Volume mínimo (m3)],0),"") | Q6: =_xlfn.XLOOKUP(BD_Receitas[[#This Row],[ID]],TabCondicoesComerciais[ID],TabCondicoesComerciais[Vol. 1ºGiro],0) -> 365 | R6: =IF(BD_Receitas[[#This Row],[TIPO DE COBRANÇA]]="Avanço Espaço", _xlfn.XLOOKUP(BD_Receitas[[#This Row],[ID]],TabCondicoesComerciais[ID],TabCondicoesComerciais[Avanço Espaço],0), IF(BD_Receitas[[#This Row],[TIPO DE COBRANÇA]]="Avanço Horário", _xlfn.XLOOKUP(BD_Receitas[[#This Row],[ID]],TabCondicoesComerciais[ID],TabCondicoesComerciais[Avanço Horário],0), IF(BD_Receitas[[#This Row],[TIPO DE COBRANÇA]]="Operação Normal", _xlfn.XLOOKUP(BD_Receitas[[#This Row],[ID]],TabCondicoesComerciais[ID],TabCondicoesComerciais[Tarifa 1º Giro],0),0))) -> 0 | S6: =IF(BD_Receitas[[#This Row],[TIPO DE COBRANÇA]]="Operação Normal", _xlfn.XLOOKUP(BD_Receitas[[#This Row],[ID]],TabCondicoesComerciais[ID],TabCondicoesComerciais[Tarifa 2º Giro],0),0) -> 0 | T6: =IFERROR(IF(BD_Receitas[[#This Row],[TIPO DE COBRANÇA]]<>"Operação Normal","",BD_Receitas[[#This Row],[Valor Total R$]]/ MAX(BD_Receitas[[#This Row],[Vol. Movimentado M³]], BD_Receitas[[#This Row],[Volume Mínimo ]]) ),0) | U6: =IFERROR(IF(BD_Receitas[[#This Row],[TIPO DE COBRANÇA]]<>"Operação Normal","", SUMIFS(BD_Receitas[Valor Total R$],BD_Receitas[CONGENERE],BD_Receitas[[#This Row],[CONGENERE]],BD_Receitas[FILIAL],BD_Receitas[[#This Row],[FILIAL]],BD_Receitas[DATA CONTABIL],BD_Receitas[[#This Row],[DATA CONTABIL]]) /BD_Receitas[[#This Row],[Vol. Movimentado M³]] ),0) | V6: =IF(BD_Receitas[[#This Row],[TIPO DE COBRANÇA]]<>"Operação Normal","",(BD_Receitas[[#This Row],[Volume 1º Giro]]*BD_Receitas[[#This Row],[Tarifa 1º Giro]])+(BD_Receitas[[#This Row],[Volume Mínimo ]]-BD_Receitas[[#This Row],[Volume 1º Giro]])*BD_Receitas[[#This Row],[Tarifa 2º Giro]]) | W6: =IF(BD_Receitas[[#This Row],[TIPO DE COBRANÇA]]<>"OPERAÇÃO NORMAL","", IF(BD_Receitas[[#This Row],[Vol. Movimentado M³]]<BD_Receitas[[#This Row],[Volume 1º Giro]],BD_Receitas[[#This Row],[Vol. Movimentado M³]]* BD_Receitas[[#This Row],[Tarifa 1º Giro]], (BD_Receitas[[#This Row],[Volume 1º Giro]]*BD_Receitas[[#This Row],[Tarifa 1º Giro]])+(BD_Receitas[[#This Row],[Vol. Movimentado M³]]-BD_Receitas[[#This Row],[Volume 1º Giro]])*BD_Receitas[[#This Row],[Tarifa 2º Giro]]) ) | X6: =IF(BD_Receitas[[#This Row],[TIPO DE COBRANÇA]] <> "OPERAÇÃO NORMAL","", IF(BD_Receitas[[#This Row],[Vol. Movimentado M³]]= BD_Receitas[[#This Row],[Volume Mínimo ]], "Vol. Movimentado igual ao Vol. Mínimo", IF(ROUND(BD_Receitas[[#This Row],[Tarifa 1º Giro]],3) <> ROUND(BD_Receitas[[#This Row],[Tarifa Cobrada]],3), "Conferir tarifa cobrada", IF(BD_Receitas[[#This Row],[Volume Mínimo ]]=0,"Ok", IF(BD_Receitas[[#This Row],[Vol. Movimentado M³]]<= BD_Receitas[[#This Row],[Volume Mínimo ]], IF(ROUND(BD_Receitas[[#This Row],[Valor Total R$]],2) = ROUND(BD_Receitas[[#This Row],[Valor Total R$]],2), "Ok","Verificar Cobrança"), IF(ROUND(BD_Receitas[[#This Row],[Valor Contrato]],2) = ROUND(BD_Receitas[[#This Row],[Valor Movimentado]],2), "OK","Verificar cobrança") )))))
A7: 1102 | B7: 45658 | C7: BRASILIA | D7: MG RJ ES | E7: MINAS CENTRAL | F7: 1 | G7: Betim | H7: Ciapetro | I7: Avanço Horário | J7: 0 | K7: 0 | P7: =IF(BD_Receitas[[#This Row],[TIPO DE COBRANÇA]]="Operação Normal", _xlfn.XLOOKUP(BD_Receitas[[#This Row],[ID]],TabCondicoesComerciais[ID],TabCondicoesComerciais[Volume mínimo (m3)],0),"") | Q7: =_xlfn.XLOOKUP(BD_Receitas[[#This Row],[ID]],TabCondicoesComerciais[ID],TabCondicoesComerciais[Vol. 1ºGiro],0) -> 365 | R7: =IF(BD_Receitas[[#This Row],[TIPO DE COBRANÇA]]="Avanço Espaço", _xlfn.XLOOKUP(BD_Receitas[[#This Row],[ID]],TabCondicoesComerciais[ID],TabCondicoesComerciais[Avanço Espaço],0), IF(BD_Receitas[[#This Row],[TIPO DE COBRANÇA]]="Avanço Horário", _xlfn.XLOOKUP(BD_Receitas[[#This Row],[ID]],TabCondicoesComerciais[ID],TabCondicoesComerciais[Avanço Horário],0), IF(BD_Receitas[[#This Row],[TIPO DE COBRANÇA]]="Operação Normal", _xlfn.XLOOKUP(BD_Receitas[[#This Row],[ID]],TabCondicoesComerciais[ID],TabCondicoesComerciais[Tarifa 1º Giro],0),0))) -> 0 | S7: =IF(BD_Receitas[[#This Row],[TIPO DE COBRANÇA]]="Operação Normal", _xlfn.XLOOKUP(BD_Receitas[[#This Row],[ID]],TabCondicoesComerciais[ID],TabCondicoesComerciais[Tarifa 2º Giro],0),0) -> 0 | T7: =IFERROR(IF(BD_Receitas[[#This Row],[TIPO DE COBRANÇA]]<>"Operação Normal","",BD_Receitas[[#This Row],[Valor Total R$]]/ MAX(BD_Receitas[[#This Row],[Vol. Movimentado M³]], BD_Receitas[[#This Row],[Volume Mínimo ]]) ),0) | U7: =IFERROR(IF(BD_Receitas[[#This Row],[TIPO DE COBRANÇA]]<>"Operação Normal","", SUMIFS(BD_Receitas[Valor Total R$],BD_Receitas[CONGENERE],BD_Receitas[[#This Row],[CONGENERE]],BD_Receitas[FILIAL],BD_Receitas[[#This Row],[FILIAL]],BD_Receitas[DATA CONTABIL],BD_Receitas[[#This Row],[DATA CONTABIL]]) /BD_Receitas[[#This Row],[Vol. Movimentado M³]] ),0) | V7: =IF(BD_Receitas[[#This Row],[TIPO DE COBRANÇA]]<>"Operação Normal","",(BD_Receitas[[#This Row],[Volume 1º Giro]]*BD_Receitas[[#This Row],[Tarifa 1º Giro]])+(BD_Receitas[[#This Row],[Volume Mínimo ]]-BD_Receitas[[#This Row],[Volume 1º Giro]])*BD_Receitas[[#This Row],[Tarifa 2º Giro]]) | W7: =IF(BD_Receitas[[#This Row],[TIPO DE COBRANÇA]]<>"OPERAÇÃO NORMAL","", IF(BD_Receitas[[#This Row],[Vol. Movimentado M³]]<BD_Receitas[[#This Row],[Volume 1º Giro]],BD_Receitas[[#This Row],[Vol. Movimentado M³]]* BD_Receitas[[#This Row],[Tarifa 1º Giro]], (BD_Receitas[[#This Row],[Volume 1º Giro]]*BD_Receitas[[#This Row],[Tarifa 1º Giro]])+(BD_Receitas[[#This Row],[Vol. Movimentado M³]]-BD_Receitas[[#This Row],[Volume 1º Giro]])*BD_Receitas[[#This Row],[Tarifa 2º Giro]]) ) | X7: =IF(BD_Receitas[[#This Row],[TIPO DE COBRANÇA]] <> "OPERAÇÃO NORMAL","", IF(BD_Receitas[[#This Row],[Vol. Movimentado M³]]= BD_Receitas[[#This Row],[Volume Mínimo ]], "Vol. Movimentado igual ao Vol. Mínimo", IF(ROUND(BD_Receitas[[#This Row],[Tarifa 1º Giro]],3) <> ROUND(BD_Receitas[[#This Row],[Tarifa Cobrada]],3), "Conferir tarifa cobrada", IF(BD_Receitas[[#This Row],[Volume Mínimo ]]=0,"Ok", IF(BD_Receitas[[#This Row],[Vol. Movimentado M³]]<= BD_Receitas[[#This Row],[Volume Mínimo ]], IF(ROUND(BD_Receitas[[#This Row],[Valor Total R$]],2) = ROUND(BD_Receitas[[#This Row],[Valor Total R$]],2), "Ok","Verificar Cobrança"), IF(ROUND(BD_Receitas[[#This Row],[Valor Contrato]],2) = ROUND(BD_Receitas[[#This Row],[Valor Movimentado]],2), "OK","Verificar cobrança") )))))
A8: 1102 | B8: 45658 | C8: BRASILIA | D8: MG RJ ES | E8: MINAS CENTRAL | F8: 1 | G8: Betim | H8: Ciapetro | I8: Operação Normal | J8: 28839.059 | K8: 1500 | L8: 17387.03 | M8: 608.175 | N8: 17617 | O8: COBRANÇA DE ARMAZENAGEM CONJUNTA REFERENTE A DEZ/2024 | P8: =IF(BD_Receitas[[#This Row],[TIPO DE COBRANÇA]]="Operação Normal", _xlfn.XLOOKUP(BD_Receitas[[#This Row],[ID]],TabCondicoesComerciais[ID],TabCondicoesComerciais[Volume mínimo (m3)],0),"") -> 936 | Q8: =_xlfn.XLOOKUP(BD_Receitas[[#This Row],[ID]],TabCondicoesComerciais[ID],TabCondicoesComerciais[Vol. 1ºGiro],0) -> 365 | R8: =IF(BD_Receitas[[#This Row],[TIPO DE COBRANÇA]]="Avanço Espaço", _xlfn.XLOOKUP(BD_Receitas[[#This Row],[ID]],TabCondicoesComerciais[ID],TabCondicoesComerciais[Avanço Espaço],0), IF(BD_Receitas[[#This Row],[TIPO DE COBRANÇA]]="Avanço Horário", _xlfn.XLOOKUP(BD_Receitas[[#This Row],[ID]],TabCondicoesComerciais[ID],TabCondicoesComerciais[Avanço Horário],0), IF(BD_Receitas[[#This Row],[TIPO DE COBRANÇA]]="Operação Normal", _xlfn.XLOOKUP(BD_Receitas[[#This Row],[ID]],TabCondicoesComerciais[ID],TabCondicoesComerciais[Tarifa 1º Giro],0),0))) -> 17.87 | S8: =IF(BD_Receitas[[#This Row],[TIPO DE COBRANÇA]]="Operação Normal", _xlfn.XLOOKUP(BD_Receitas[[#This Row],[ID]],TabCondicoesComerciais[ID],TabCondicoesComerciais[Tarifa 2º Giro],0),0) -> 17.87 | T8: =IFERROR(IF(BD_Receitas[[#This Row],[TIPO DE COBRANÇA]]<>"Operação Normal","",BD_Receitas[[#This Row],[Valor Total R$]]/ MAX(BD_Receitas[[#This Row],[Vol. Movimentado M³]], BD_Receitas[[#This Row],[Volume Mínimo ]]) ),0) -> 18.575887 | U8: =IFERROR(IF(BD_Receitas[[#This Row],[TIPO DE COBRANÇA]]<>"Operação Normal","", SUMIFS(BD_Receitas[Valor Total R$],BD_Receitas[CONGENERE],BD_Receitas[[#This Row],[CONGENERE]],BD_Receitas[FILIAL],BD_Receitas[[#This Row],[FILIAL]],BD_Receitas[DATA CONTABIL],BD_Receitas[[#This Row],[DATA CONTABIL]]) /BD_Receitas[[#This Row],[Vol. Movimentado M³]] ),0) -> 28.58886 | V8: =IF(BD_Receitas[[#This Row],[TIPO DE COBRANÇA]]<>"Operação Normal","",(BD_Receitas[[#This Row],[Volume 1º Giro]]*BD_Receitas[[#This Row],[Tarifa 1º Giro]])+(BD_Receitas[[#This Row],[Volume Mínimo ]]-BD_Receitas[[#This Row],[Volume 1º Giro]])*BD_Receitas[[#This Row],[Tarifa 2º Giro]]) -> 16726.32 | W8: =IF(BD_Receitas[[#This Row],[TIPO DE COBRANÇA]]<>"OPERAÇÃO NORMAL","", IF(BD_Receitas[[#This Row],[Vol. Movimentado M³]]<BD_Receitas[[#This Row],[Volume 1º Giro]],BD_Receitas[[#This Row],[Vol. Movimentado M³]]* BD_Receitas[[#This Row],[Tarifa 1º Giro]], (BD_Receitas[[#This Row],[Volume 1º Giro]]*BD_Receitas[[#This Row],[Tarifa 1º Giro]])+(BD_Receitas[[#This Row],[Vol. Movimentado M³]]-BD_Receitas[[#This Row],[Volume 1º Giro]])*BD_Receitas[[#This Row],[Tarifa 2º Giro]]) ) -> 10868.087 | X8: =IF(BD_Receitas[[#This Row],[TIPO DE COBRANÇA]] <> "OPERAÇÃO NORMAL","", IF(BD_Receitas[[#This Row],[Vol. Movimentado M³]]= BD_Receitas[[#This Row],[Volume Mínimo ]], "Vol. Movimentado igual ao Vol. Mínimo", IF(ROUND(BD_Receitas[[#This Row],[Tarifa 1º Giro]],3) <> ROUND(BD_Receitas[[#This Row],[Tarifa Cobrada]],3), "Conferir tarifa cobrada", IF(BD_Receitas[[#This Row],[Volume Mínimo ]]=0,"Ok", IF(BD_Receitas[[#This Row],[Vol. Movimentado M³]]<= BD_Receitas[[#This Row],[Volume Mínimo ]], IF(ROUND(BD_Receitas[[#This Row],[Valor Total R$]],2) = ROUND(BD_Receitas[[#This Row],[Valor Total R$]],2), "Ok","Verificar Cobrança"), IF(ROUND(BD_Receitas[[#This Row],[Valor Contrato]],2) = ROUND(BD_Receitas[[#This Row],[Valor Movimentado]],2), "OK","Verificar cobrança") ))))) -> Conferir tarifa cobrada
A9: 1102 | B9: 45658 | C9: BRASILIA | D9: MG RJ ES | E9: MINAS CENTRAL | F9: 1 | G9: Betim | H9: Ciapetro | I9: Outras Receitas | J9: 0 | K9: 0 | P9: =IF(BD_Receitas[[#This Row],[TIPO DE COBRANÇA]]="Operação Normal", _xlfn.XLOOKUP(BD_Receitas[[#This Row],[ID]],TabCondicoesComerciais[ID],TabCondicoesComerciais[Volume mínimo (m3)],0),"") | Q9: =_xlfn.XLOOKUP(BD_Receitas[[#This Row],[ID]],TabCondicoesComerciais[ID],TabCondicoesComerciais[Vol. 1ºGiro],0) -> 365 | R9: =IF(BD_Receitas[[#This Row],[TIPO DE COBRANÇA]]="Avanço Espaço", _xlfn.XLOOKUP(BD_Receitas[[#This Row],[ID]],TabCondicoesComerciais[ID],TabCondicoesComerciais[Avanço Espaço],0), IF(BD_Receitas[[#This Row],[TIPO DE COBRANÇA]]="Avanço Horário", _xlfn.XLOOKUP(BD_Receitas[[#This Row],[ID]],TabCondicoesComerciais[ID],TabCondicoesComerciais[Avanço Horário],0), IF(BD_Receitas[[#This Row],[TIPO DE COBRANÇA]]="Operação Normal", _xlfn.XLOOKUP(BD_Receitas[[#This Row],[ID]],TabCondicoesComerciais[ID],TabCondicoesComerciais[Tarifa 1º Giro],0),0))) -> 0 | S9: =IF(BD_Receitas[[#This Row],[TIPO DE COBRANÇA]]="Operação Normal", _xlfn.XLOOKUP(BD_Receitas[[#This Row],[ID]],TabCondicoesComerciais[ID],TabCondicoesComerciais[Tarifa 2º Giro],0),0) -> 0 | T9: =IFERROR(IF(BD_Receitas[[#This Row],[TIPO DE COBRANÇA]]<>"Operação Normal","",BD_Receitas[[#This Row],[Valor Total R$]]/ MAX(BD_Receitas[[#This Row],[Vol. Movimentado M³]], BD_Receitas[[#This Row],[Volume Mínimo ]]) ),0) | U9: =IFERROR(IF(BD_Receitas[[#This Row],[TIPO DE COBRANÇA]]<>"Operação Normal","", SUMIFS(BD_Receitas[Valor Total R$],BD_Receitas[CONGENERE],BD_Receitas[[#This Row],[CONGENERE]],BD_Receitas[FILIAL],BD_Receitas[[#This Row],[FILIAL]],BD_Receitas[DATA CONTABIL],BD_Receitas[[#This Row],[DATA CONTABIL]]) /BD_Receitas[[#This Row],[Vol. Movimentado M³]] ),0) | V9: =IF(BD_Receitas[[#This Row],[TIPO DE COBRANÇA]]<>"Operação Normal","",(BD_Receitas[[#This Row],[Volume 1º Giro]]*BD_Receitas[[#This Row],[Tarifa 1º Giro]])+(BD_Receitas[[#This Row],[Volume Mínimo ]]-BD_Receitas[[#This Row],[Volume 1º Giro]])*BD_Receitas[[#This Row],[Tarifa 2º Giro]]) | W9: =IF(BD_Receitas[[#This Row],[TIPO DE COBRANÇA]]<>"OPERAÇÃO NORMAL","", IF(BD_Receitas[[#This Row],[Vol. Movimentado M³]]<BD_Receitas[[#This Row],[Volume 1º Giro]],BD_Receitas[[#This Row],[Vol. Movimentado M³]]* BD_Receitas[[#This Row],[Tarifa 1º Giro]], (BD_Receitas[[#This Row],[Volume 1º Giro]]*BD_Receitas[[#This Row],[Tarifa 1º Giro]])+(BD_Receitas[[#This Row],[Vol. Movimentado M³]]-BD_Receitas[[#This Row],[Volume 1º Giro]])*BD_Receitas[[#This Row],[Tarifa 2º Giro]]) ) | X9: =IF(BD_Receitas[[#This Row],[TIPO DE COBRANÇA]] <> "OPERAÇÃO NORMAL","", IF(BD_Receitas[[#This Row],[Vol. Movimentado M³]]= BD_Receitas[[#This Row],[Volume Mínimo ]], "Vol. Movimentado igual ao Vol. Mínimo", IF(ROUND(BD_Receitas[[#This Row],[Tarifa 1º Giro]],3) <> ROUND(BD_Receitas[[#This Row],[Tarifa Cobrada]],3), "Conferir tarifa cobrada", IF(BD_Receitas[[#This Row],[Volume Mínimo ]]=0,"Ok", IF(BD_Receitas[[#This Row],[Vol. Movimentado M³]]<= BD_Receitas[[#This Row],[Volume Mínimo ]], IF(ROUND(BD_Receitas[[#This Row],[Valor Total R$]],2) = ROUND(BD_Receitas[[#This Row],[Valor Total R$]],2), "Ok","Verificar Cobrança"), IF(ROUND(BD_Receitas[[#This Row],[Valor Contrato]],2) = ROUND(BD_Receitas[[#This Row],[Valor Movimentado]],2), "OK","Verificar cobrança") )))))
A10: 16 | B10: 45658 | C10: BRASILIA | D10: MG RJ ES | E10: MINAS CENTRAL | F10: 1 | G10: Betim | H10: Rede Sol | I10: Avanço Espaço | J10: 0 | K10: 0 | P10: =IF(BD_Receitas[[#This Row],[TIPO DE COBRANÇA]]="Operação Normal", _xlfn.XLOOKUP(BD_Receitas[[#This Row],[ID]],TabCondicoesComerciais[ID],TabCondicoesComerciais[Volume mínimo (m3)],0),"") | Q10: =_xlfn.XLOOKUP(BD_Receitas[[#This Row],[ID]],TabCondicoesComerciais[ID],TabCondicoesComerciais[Vol. 1ºGiro],0) -> 100 | R10: =IF(BD_Receitas[[#This Row],[TIPO DE COBRANÇA]]="Avanço Espaço", _xlfn.XLOOKUP(BD_Receitas[[#This Row],[ID]],TabCondicoesComerciais[ID],TabCondicoesComerciais[Avanço Espaço],0), IF(BD_Receitas[[#This Row],[TIPO DE COBRANÇA]]="Avanço Horário", _xlfn.XLOOKUP(BD_Receitas[[#This Row],[ID]],TabCondicoesComerciais[ID],TabCondicoesComerciais[Avanço Horário],0), IF(BD_Receitas[[#This Row],[TIPO DE COBRANÇA]]="Operação Normal", _xlfn.XLOOKUP(BD_Receitas[[#This Row],[ID]],TabCondicoesComerciais[ID],TabCondicoesComerciais[Tarifa 1º Giro],0),0))) -> 0 | S10: =IF(BD_Receitas[[#This Row],[TIPO DE COBRANÇA]]="Operação Normal", _xlfn.XLOOKUP(BD_Receitas[[#This Row],[ID]],TabCondicoesComerciais[ID],TabCondicoesComerciais[Tarifa 2º Giro],0),0) -> 0 | T10: =IFERROR(IF(BD_Receitas[[#This Row],[TIPO DE COBRANÇA]]<>"Operação Normal","",BD_Receitas[[#This Row],[Valor Total R$]]/ MAX(BD_Receitas[[#This Row],[Vol. Movimentado M³]], BD_Receitas[[#This Row],[Volume Mínimo ]]) ),0) | U10: =IFERROR(IF(BD_Receitas[[#This Row],[TIPO DE COBRANÇA]]<>"Operação Normal","", SUMIFS(BD_Receitas[Valor Total R$],BD_Receitas[CONGENERE],BD_Receitas[[#This Row],[CONGENERE]],BD_Receitas[FILIAL],BD_Receitas[[#This Row],[FILIAL]],BD_Receitas[DATA CONTABIL],BD_Receitas[[#This Row],[DATA CONTABIL]]) /BD_Receitas[[#This Row],[Vol. Movimentado M³]] ),0) | V10: =IF(BD_Receitas[[#This Row],[TIPO DE COBRANÇA]]<>"Operação Normal","",(BD_Receitas[[#This Row],[Volume 1º Giro]]*BD_Receitas[[#This Row],[Tarifa 1º Giro]])+(BD_Receitas[[#This Row],[Volume Mínimo ]]-BD_Receitas[[#This Row],[Volume 1º Giro]])*BD_Receitas[[#This Row],[Tarifa 2º Giro]]) | W10: =IF(BD_Receitas[[#This Row],[TIPO DE COBRANÇA]]<>"OPERAÇÃO NORMAL","", IF(BD_Receitas[[#This Row],[Vol. Movimentado M³]]<BD_Receitas[[#This Row],[Volume 1º Giro]],BD_Receitas[[#This Row],[Vol. Movimentado M³]]* BD_Receitas[[#This Row],[Tarifa 1º Giro]], (BD_Receitas[[#This Row],[Volume 1º Giro]]*BD_Receitas[[#This Row],[Tarifa 1º Giro]])+(BD_Receitas[[#This Row],[Vol. Movimentado M³]]-BD_Receitas[[#This Row],[Volume 1º Giro]])*BD_Receitas[[#This Row],[Tarifa 2º Giro]]) ) | X10: =IF(BD_Receitas[[#This Row],[TIPO DE COBRANÇA]] <> "OPERAÇÃO NORMAL","", IF(BD_Receitas[[#This Row],[Vol. Movimentado M³]]= BD_Receitas[[#This Row],[Volume Mínimo ]], "Vol. Movimentado igual ao Vol. Mínimo", IF(ROUND(BD_Receitas[[#This Row],[Tarifa 1º Giro]],3) <> ROUND(BD_Receitas[[#This Row],[Tarifa Cobrada]],3), "Conferir tarifa cobrada", IF(BD_Receitas[[#This Row],[Volume Mínimo ]]=0,"Ok", IF(BD_Receitas[[#This Row],[Vol. Movimentado M³]]<= BD_Receitas[[#This Row],[Volume Mínimo ]], IF(ROUND(BD_Receitas[[#This Row],[Valor Total R$]],2) = ROUND(BD_Receitas[[#This Row],[Valor Total R$]],2), "Ok","Verificar Cobrança"), IF(ROUND(BD_Receitas[[#This Row],[Valor Contrato]],2) = ROUND(BD_Receitas[[#This Row],[Valor Movimentado]],2), "OK","Verificar cobrança") )))))
A11: 16 | B11: 45658 | C11: BRASILIA | D11: MG RJ ES | E11: MINAS CENTRAL | F11: 1 | G11: Betim | H11: Rede Sol | I11: Avanço Horário | J11: 0 | K11: 0 | P11: =IF(BD_Receitas[[#This Row],[TIPO DE COBRANÇA]]="Operação Normal", _xlfn.XLOOKUP(BD_Receitas[[#This Row],[ID]],TabCondicoesComerciais[ID],TabCondicoesComerciais[Volume mínimo (m3)],0),"") | Q11: =_xlfn.XLOOKUP(BD_Receitas[[#This Row],[ID]],TabCondicoesComerciais[ID],TabCondicoesComerciais[Vol. 1ºGiro],0) -> 100 | R11: =IF(BD_Receitas[[#This Row],[TIPO DE COBRANÇA]]="Avanço Espaço", _xlfn.XLOOKUP(BD_Receitas[[#This Row],[ID]],TabCondicoesComerciais[ID],TabCondicoesComerciais[Avanço Espaço],0), IF(BD_Receitas[[#This Row],[TIPO DE COBRANÇA]]="Avanço Horário", _xlfn.XLOOKUP(BD_Receitas[[#This Row],[ID]],TabCondicoesComerciais[ID],TabCondicoesComerciais[Avanço Horário],0), IF(BD_Receitas[[#This Row],[TIPO DE COBRANÇA]]="Operação Normal", _xlfn.XLOOKUP(BD_Receitas[[#This Row],[ID]],TabCondicoesComerciais[ID],TabCondicoesComerciais[Tarifa 1º Giro],0),0))) -> 0 | S11: =IF(BD_Receitas[[#This Row],[TIPO DE COBRANÇA]]="Operação Normal", _xlfn.XLOOKUP(BD_Receitas[[#This Row],[ID]],TabCondicoesComerciais[ID],TabCondicoesComerciais[Tarifa 2º Giro],0),0) -> 0 | T11: =IFERROR(IF(BD_Receitas[[#This Row],[TIPO DE COBRANÇA]]<>"Operação Normal","",BD_Receitas[[#This Row],[Valor Total R$]]/ MAX(BD_Receitas[[#This Row],[Vol. Movimentado M³]], BD_Receitas[[#This Row],[Volume Mínimo ]]) ),0) | U11: =IFERROR(IF(BD_Receitas[[#This Row],[TIPO DE COBRANÇA]]<>"Operação Normal","", SUMIFS(BD_Receitas[Valor Total R$],BD_Receitas[CONGENERE],BD_Receitas[[#This Row],[CONGENERE]],BD_Receitas[FILIAL],BD_Receitas[[#This Row],[FILIAL]],BD_Receitas[DATA CONTABIL],BD_Receitas[[#This Row],[DATA CONTABIL]]) /BD_Receitas[[#This Row],[Vol. Movimentado M³]] ),0) | V11: =IF(BD_Receitas[[#This Row],[TIPO DE COBRANÇA]]<>"Operação Normal","",(BD_Receitas[[#This Row],[Volume 1º Giro]]*BD_Receitas[[#This Row],[Tarifa 1º Giro]])+(BD_Receitas[[#This Row],[Volume Mínimo ]]-BD_Receitas[[#This Row],[Volume 1º Giro]])*BD_Receitas[[#This Row],[Tarifa 2º Giro]]) | W11: =IF(BD_Receitas[[#This Row],[TIPO DE COBRANÇA]]<>"OPERAÇÃO NORMAL","", IF(BD_Receitas[[#This Row],[Vol. Movimentado M³]]<BD_Receitas[[#This Row],[Volume 1º Giro]],BD_Receitas[[#This Row],[Vol. Movimentado M³]]* BD_Receitas[[#This Row],[Tarifa 1º Giro]], (BD_Receitas[[#This Row],[Volume 1º Giro]]*BD_Receitas[[#This Row],[Tarifa 1º Giro]])+(BD_Receitas[[#This Row],[Vol. Movimentado M³]]-BD_Receitas[[#This Row],[Volume 1º Giro]])*BD_Receitas[[#This Row],[Tarifa 2º Giro]]) ) | X11: =IF(BD_Receitas[[#This Row],[TIPO DE COBRANÇA]] <> "OPERAÇÃO NORMAL","", IF(BD_Receitas[[#This Row],[Vol. Movimentado M³]]= BD_Receitas[[#This Row],[Volume Mínimo ]], "Vol. Movimentado igual ao Vol. Mínimo", IF(ROUND(BD_Receitas[[#This Row],[Tarifa 1º Giro]],3) <> ROUND(BD_Receitas[[#This Row],[Tarifa Cobrada]],3), "Conferir tarifa cobrada", IF(BD_Receitas[[#This Row],[Volume Mínimo ]]=0,"Ok", IF(BD_Receitas[[#This Row],[Vol. Movimentado M³]]<= BD_Receitas[[#This Row],[Volume Mínimo ]], IF(ROUND(BD_Receitas[[#This Row],[Valor Total R$]],2) = ROUND(BD_Receitas[[#This Row],[Valor Total R$]],2), "Ok","Verificar Cobrança"), IF(ROUND(BD_Receitas[[#This Row],[Valor Contrato]],2) = ROUND(BD_Receitas[[#This Row],[Valor Movimentado]],2), "OK","Verificar cobrança") )))))
A12: 16 | B12: 45658 | C12: BRASILIA | D12: MG RJ ES | E12: MINAS CENTRAL | F12: 1 | G12: Betim | H12: Rede Sol | I12: Operação Normal | J12: 9355.5094 | K12: 300 | P12: =IF(BD_Receitas[[#This Row],[TIPO DE COBRANÇA]]="Operação Normal", _xlfn.XLOOKUP(BD_Receitas[[#This Row],[ID]],TabCondicoesComerciais[ID],TabCondicoesComerciais[Volume mínimo (m3)],0),"") -> 300 | Q12: =_xlfn.XLOOKUP(BD_Receitas[[#This Row],[ID]],TabCondicoesComerciais[ID],TabCondicoesComerciais[Vol. 1ºGiro],0) -> 100 | R12: =IF(BD_Receitas[[#This Row],[TIPO DE COBRANÇA]]="Avanço Espaço", _xlfn.XLOOKUP(BD_Receitas[[#This Row],[ID]],TabCondicoesComerciais[ID],TabCondicoesComerciais[Avanço Espaço],0), IF(BD_Receitas[[#This Row],[TIPO DE COBRANÇA]]="Avanço Horário", _xlfn.XLOOKUP(BD_Receitas[[#This Row],[ID]],TabCondicoesComerciais[ID],TabCondicoesComerciais[Avanço Horário],0), IF(BD_Receitas[[#This Row],[TIPO DE COBRANÇA]]="Operação Normal", _xlfn.XLOOKUP(BD_Receitas[[#This Row],[ID]],TabCondicoesComerciais[ID],TabCondicoesComerciais[Tarifa 1º Giro],0),0))) -> 30 | S12: =IF(BD_Receitas[[#This Row],[TIPO DE COBRANÇA]]="Operação Normal", _xlfn.XLOOKUP(BD_Receitas[[#This Row],[ID]],TabCondicoesComerciais[ID],TabCondicoesComerciais[Tarifa 2º Giro],0),0) -> 30 | T12: =IFERROR(IF(BD_Receitas[[#This Row],[TIPO DE COBRANÇA]]<>"Operação Normal","",BD_Receitas[[#This Row],[Valor Total R$]]/ MAX(BD_Receitas[[#This Row],[Vol. Movimentado M³]], BD_Receitas[[#This Row],[Volume Mínimo ]]) ),0) -> 0 | U12: =IFERROR(IF(BD_Receitas[[#This Row],[TIPO DE COBRANÇA]]<>"Operação Normal","", SUMIFS(BD_Receitas[Valor Total R$],BD_Receitas[CONGENERE],BD_Receitas[[#This Row],[CONGENERE]],BD_Receitas[FILIAL],BD_Receitas[[#This Row],[FILIAL]],BD_Receitas[DATA CONTABIL],BD_Receitas[[#This Row],[DATA CONTABIL]]) /BD_Receitas[[#This Row],[Vol. Movimentado M³]] ),0) -> 0 | V12: =IF(BD_Receitas[[#This Row],[TIPO DE COBRANÇA]]<>"Operação Normal","",(BD_Receitas[[#This Row],[Volume 1º Giro]]*BD_Receitas[[#This Row],[Tarifa 1º Giro]])+(BD_Receitas[[#This Row],[Volume Mínimo ]]-BD_Receitas[[#This Row],[Volume 1º Giro]])*BD_Receitas[[#This Row],[Tarifa 2º Giro]]) -> 9000 | W12: =IF(BD_Receitas[[#This Row],[TIPO DE COBRANÇA]]<>"OPERAÇÃO NORMAL","", IF(BD_Receitas[[#This Row],[Vol. Movimentado M³]]<BD_Receitas[[#This Row],[Volume 1º Giro]],BD_Receitas[[#This Row],[Vol. Movimentado M³]]* BD_Receitas[[#This Row],[Tarifa 1º Giro]], (BD_Receitas[[#This Row],[Volume 1º Giro]]*BD_Receitas[[#This Row],[Tarifa 1º Giro]])+(BD_Receitas[[#This Row],[Vol. Movimentado M³]]-BD_Receitas[[#This Row],[Volume 1º Giro]])*BD_Receitas[[#This Row],[Tarifa 2º Giro]]) ) -> 0 | X12: =IF(BD_Receitas[[#This Row],[TIPO DE COBRANÇA]] <> "OPERAÇÃO NORMAL","", IF(BD_Receitas[[#This Row],[Vol. Movimentado M³]]= BD_Receitas[[#This Row],[Volume Mínimo ]], "Vol. Movimentado igual ao Vol. Mínimo", IF(ROUND(BD_Receitas[[#This Row],[Tarifa 1º Giro]],3) <> ROUND(BD_Receitas[[#This Row],[Tarifa Cobrada]],3), "Conferir tarifa cobrada", IF(BD_Receitas[[#This Row],[Volume Mínimo ]]=0,"Ok", IF(BD_Receitas[[#This Row],[Vol. Movimentado M³]]<= BD_Receitas[[#This Row],[Volume Mínimo ]], IF(ROUND(BD_Receitas[[#This Row],[Valor Total R$]],2) = ROUND(BD_Receitas[[#This Row],[Valor Total R$]],2), "Ok","Verificar Cobrança"), IF(ROUND(BD_Receitas[[#This Row],[Valor Contrato]],2) = ROUND(BD_Receitas[[#This Row],[Valor Movimentado]],2), "OK","Verificar cobrança") ))))) -> Conferir tarifa cobrada
A13: 16 | B13: 45658 | C13: BRASILIA | D13: MG RJ ES | E13: MINAS CENTRAL | F13: 1 | G13: Betim | H13: Rede Sol | I13: Outras Receitas | J13: 0 | K13: 0 | P13: =IF(BD_Receitas[[#This Row],[TIPO DE COBRANÇA]]="Operação Normal", _xlfn.XLOOKUP(BD_Receitas[[#This Row],[ID]],TabCondicoesComerciais[ID],TabCondicoesComerciais[Volume mínimo (m3)],0),"") | Q13: =_xlfn.XLOOKUP(BD_Receitas[[#This Row],[ID]],TabCondicoesComerciais[ID],TabCondicoesComerciais[Vol. 1ºGiro],0) -> 100 | R13: =IF(BD_Receitas[[#This Row],[TIPO DE COBRANÇA]]="Avanço Espaço", _xlfn.XLOOKUP(BD_Receitas[[#This Row],[ID]],TabCondicoesComerciais[ID],TabCondicoesComerciais[Avanço Espaço],0), IF(BD_Receitas[[#This Row],[TIPO DE COBRANÇA]]="Avanço Horário", _xlfn.XLOOKUP(BD_Receitas[[#This Row],[ID]],TabCondicoesComerciais[ID],TabCondicoesComerciais[Avanço Horário],0), IF(BD_Receitas[[#This Row],[TIPO DE COBRANÇA]]="Operação Normal", _xlfn.XLOOKUP(BD_Receitas[[#This Row],[ID]],TabCondicoesComerciais[ID],TabCondicoesComerciais[Tarifa 1º Giro],0),0))) -> 0 | S13: =IF(BD_Receitas[[#This Row],[TIPO DE COBRANÇA]]="Operação Normal", _xlfn.XLOOKUP(BD_Receitas[[#This Row],[ID]],TabCondicoesComerciais[ID],TabCondicoesComerciais[Tarifa 2º Giro],0),0) -> 0 | T13: =IFERROR(IF(BD_Receitas[[#This Row],[TIPO DE COBRANÇA]]<>"Operação Normal","",BD_Receitas[[#This Row],[Valor Total R$]]/ MAX(BD_Receitas[[#This Row],[Vol. Movimentado M³]], BD_Receitas[[#This Row],[Volume Mínimo ]]) ),0) | U13: =IFERROR(IF(BD_Receitas[[#This Row],[TIPO DE COBRANÇA]]<>"Operação Normal","", SUMIFS(BD_Receitas[Valor Total R$],BD_Receitas[CONGENERE],BD_Receitas[[#This Row],[CONGENERE]],BD_Receitas[FILIAL],BD_Receitas[[#This Row],[FILIAL]],BD_Receitas[DATA CONTABIL],BD_Receitas[[#This Row],[DATA CONTABIL]]) /BD_Receitas[[#This Row],[Vol. Movimentado M³]] ),0) | V13: =IF(BD_Receitas[[#This Row],[TIPO DE COBRANÇA]]<>"Operação Normal","",(BD_Receitas[[#This Row],[Volume 1º Giro]]*BD_Receitas[[#This Row],[Tarifa 1º Giro]])+(BD_Receitas[[#This Row],[Volume Mínimo ]]-BD_Receitas[[#This Row],[Volume 1º Giro]])*BD_Receitas[[#This Row],[Tarifa 2º Giro]]) | W13: =IF(BD_Receitas[[#This Row],[TIPO DE COBRANÇA]]<>"OPERAÇÃO NORMAL","", IF(BD_Receitas[[#This Row],[Vol. Movimentado M³]]<BD_Receitas[[#This Row],[Volume 1º Giro]],BD_Receitas[[#This Row],[Vol. Movimentado M³]]* BD_Receitas[[#This Row],[Tarifa 1º Giro]], (BD_Receitas[[#This Row],[Volume 1º Giro]]*BD_Receitas[[#This Row],[Tarifa 1º Giro]])+(BD_Receitas[[#This Row],[Vol. Movimentado M³]]-BD_Receitas[[#This Row],[Volume 1º Giro]])*BD_Receitas[[#This Row],[Tarifa 2º Giro]]) ) | X13: =IF(BD_Receitas[[#This Row],[TIPO DE COBRANÇA]] <> "OPERAÇÃO NORMAL","", IF(BD_Receitas[[#This Row],[Vol. Movimentado M³]]= BD_Receitas[[#This Row],[Volume Mínimo ]], "Vol. Movimentado igual ao Vol. Mínimo", IF(ROUND(BD_Receitas[[#This Row],[Tarifa 1º Giro]],3) <> ROUND(BD_Receitas[[#This Row],[Tarifa Cobrada]],3), "Conferir tarifa cobrada", IF(BD_Receitas[[#This Row],[Volume Mínimo ]]=0,"Ok", IF(BD_Receitas[[#This Row],[Vol. Movimentado M³]]<= BD_Receitas[[#This Row],[Volume Mínimo ]], IF(ROUND(BD_Receitas[[#This Row],[Valor Total R$]],2) = ROUND(BD_Receitas[[#This Row],[Valor Total R$]],2), "Ok","Verificar Cobrança"), IF(ROUND(BD_Receitas[[#This Row],[Valor Contrato]],2) = ROUND(BD_Receitas[[#This Row],[Valor Movimentado]],2), "OK","Verificar cobrança") )))))
A14: 1401 | B14: 45658 | C14: BRASILIA | D14: MG RJ ES | E14: MINAS CENTRAL | F14: 1 | G14: Betim | H14: Tobras | I14: Avanço Espaço | J14: 0 | K14: 0 | P14: =IF(BD_Receitas[[#This Row],[TIPO DE COBRANÇA]]="Operação Normal", _xlfn.XLOOKUP(BD_Receitas[[#This Row],[ID]],TabCondicoesComerciais[ID],TabCondicoesComerciais[Volume mínimo (m3)],0),"") | Q14: =_xlfn.XLOOKUP(BD_Receitas[[#This Row],[ID]],TabCondicoesComerciais[ID],TabCondicoesComerciais[Vol. 1ºGiro],0) -> 750 | R14: =IF(BD_Receitas[[#This Row],[TIPO DE COBRANÇA]]="Avanço Espaço", _xlfn.XLOOKUP(BD_Receitas[[#This Row],[ID]],TabCondicoesComerciais[ID],TabCondicoesComerciais[Avanço Espaço],0), IF(BD_Receitas[[#This Row],[TIPO DE COBRANÇA]]="Avanço Horário", _xlfn.XLOOKUP(BD_Receitas[[#This Row],[ID]],TabCondicoesComerciais[ID],TabCondicoesComerciais[Avanço Horário],0), IF(BD_Receitas[[#This Row],[TIPO DE COBRANÇA]]="Operação Normal", _xlfn.XLOOKUP(BD_Receitas[[#This Row],[ID]],TabCondicoesComerciais[ID],TabCondicoesComerciais[Tarifa 1º Giro],0),0))) -> 12.968 | S14: =IF(BD_Receitas[[#This Row],[TIPO DE COBRANÇA]]="Operação Normal", _xlfn.XLOOKUP(BD_Receitas[[#This Row],[ID]],TabCondicoesComerciais[ID],TabCondicoesComerciais[Tarifa 2º Giro],0),0) -> 0 | T14: =IFERROR(IF(BD_Receitas[[#This Row],[TIPO DE COBRANÇA]]<>"Operação Normal","",BD_Receitas[[#This Row],[Valor Total R$]]/ MAX(BD_Receitas[[#This Row],[Vol. Movimentado M³]], BD_Receitas[[#This Row],[Volume Mínimo ]]) ),0) | U14: =IFERROR(IF(BD_Receitas[[#This Row],[TIPO DE COBRANÇA]]<>"Operação Normal","", SUMIFS(BD_Receitas[Valor Total R$],BD_Receitas[CONGENERE],BD_Receitas[[#This Row],[CONGENERE]],BD_Receitas[FILIAL],BD_Receitas[[#This Row],[FILIAL]],BD_Receitas[DATA CONTABIL],BD_Receitas[[#This Row],[DATA CONTABIL]]) /BD_Receitas[[#This Row],[Vol. Movimentado M³]] ),0) | V14: =IF(BD_Receitas[[#This Row],[TIPO DE COBRANÇA]]<>"Operação Normal","",(BD_Receitas[[#This Row],[Volume 1º Giro]]*BD_Receitas[[#This Row],[Tarifa 1º Giro]])+(BD_Receitas[[#This Row],[Volume Mínimo ]]-BD_Receitas[[#This Row],[Volume 1º Giro]])*BD_Receitas[[#This Row],[Tarifa 2º Giro]]) | W14: =IF(BD_Receitas[[#This Row],[TIPO DE COBRANÇA]]<>"OPERAÇÃO NORMAL","", IF(BD_Receitas[[#This Row],[Vol. Movimentado M³]]<BD_Receitas[[#This Row],[Volume 1º Giro]],BD_Receitas[[#This Row],[Vol. Movimentado M³]]* BD_Receitas[[#This Row],[Tarifa 1º Giro]], (BD_Receitas[[#This Row],[Volume 1º Giro]]*BD_Receitas[[#This Row],[Tarifa 1º Giro]])+(BD_Receitas[[#This Row],[Vol. Movimentado M³]]-BD_Receitas[[#This Row],[Volume 1º Giro]])*BD_Receitas[[#This Row],[Tarifa 2º Giro]]) ) | X14: =IF(BD_Receitas[[#This Row],[TIPO DE COBRANÇA]] <> "OPERAÇÃO NORMAL","", IF(BD_Receitas[[#This Row],[Vol. Movimentado M³]]= BD_Receitas[[#This Row],[Volume Mínimo ]], "Vol. Movimentado igual ao Vol. Mínimo", IF(ROUND(BD_Receitas[[#This Row],[Tarifa 1º Giro]],3) <> ROUND(BD_Receitas[[#This Row],[Tarifa Cobrada]],3), "Conferir tarifa cobrada", IF(BD_Receitas[[#This Row],[Volume Mínimo ]]=0,"Ok", IF(BD_Receitas[[#This Row],[Vol. Movimentado M³]]<= BD_Receitas[[#This Row],[Volume Mínimo ]], IF(ROUND(BD_Receitas[[#This Row],[Valor Total R$]],2) = ROUND(BD_Receitas[[#This Row],[Valor Total R$]],2), "Ok","Verificar Cobrança"), IF(ROUND(BD_Receitas[[#This Row],[Valor Contrato]],2) = ROUND(BD_Receitas[[#This Row],[Valor Movimentado]],2), "OK","Verificar cobrança") )))))
A15: 1401 | B15: 45658 | C15: BRASILIA | D15: MG RJ ES | E15: MINAS CENTRAL | F15: 1 | G15: Betim | H15: Tobras | I15: Avanço Horário | J15: 0 | K15: 0 | P15: =IF(BD_Receitas[[#This Row],[TIPO DE COBRANÇA]]="Operação Normal", _xlfn.XLOOKUP(BD_Receitas[[#This Row],[ID]],TabCondicoesComerciais[ID],TabCondicoesComerciais[Volume mínimo (m3)],0),"") | Q15: =_xlfn.XLOOKUP(BD_Receitas[[#This Row],[ID]],TabCondicoesComerciais[ID],TabCondicoesComerciais[Vol. 1ºGiro],0) -> 750 | R15: =IF(BD_Receitas[[#This Row],[TIPO DE COBRANÇA]]="Avanço Espaço", _xlfn.XLOOKUP(BD_Receitas[[#This Row],[ID]],TabCondicoesComerciais[ID],TabCondicoesComerciais[Avanço Espaço],0), IF(BD_Receitas[[#This Row],[TIPO DE COBRANÇA]]="Avanço Horário", _xlfn.XLOOKUP(BD_Receitas[[#This Row],[ID]],TabCondicoesComerciais[ID],TabCondicoesComerciais[Avanço Horário],0), IF(BD_Receitas[[#This Row],[TIPO DE COBRANÇA]]="Operação Normal", _xlfn.XLOOKUP(BD_Receitas[[#This Row],[ID]],TabCondicoesComerciais[ID],TabCondicoesComerciais[Tarifa 1º Giro],0),0))) -> 12.968 | S15: =IF(BD_Receitas[[#This Row],[TIPO DE COBRANÇA]]="Operação Normal", _xlfn.XLOOKUP(BD_Receitas[[#This Row],[ID]],TabCondicoesComerciais[ID],TabCondicoesComerciais[Tarifa 2º Giro],0),0) -> 0 | T15: =IFERROR(IF(BD_Receitas[[#This Row],[TIPO DE COBRANÇA]]<>"Operação Normal","",BD_Receitas[[#This Row],[Valor Total R$]]/ MAX(BD_Receitas[[#This Row],[Vol. Movimentado M³]], BD_Receitas[[#This Row],[Volume Mínimo ]]) ),0) | U15: =IFERROR(IF(BD_Receitas[[#This Row],[TIPO DE COBRANÇA]]<>"Operação Normal","", SUMIFS(BD_Receitas[Valor Total R$],BD_Receitas[CONGENERE],BD_Receitas[[#This Row],[CONGENERE]],BD_Receitas[FILIAL],BD_Receitas[[#This Row],[FILIAL]],BD_Receitas[DATA CONTABIL],BD_Receitas[[#This Row],[DATA CONTABIL]]) /BD_Receitas[[#This Row],[Vol. Movimentado M³]] ),0) | V15: =IF(BD_Receitas[[#This Row],[TIPO DE COBRANÇA]]<>"Operação Normal","",(BD_Receitas[[#This Row],[Volume 1º Giro]]*BD_Receitas[[#This Row],[Tarifa 1º Giro]])+(BD_Receitas[[#This Row],[Volume Mínimo ]]-BD_Receitas[[#This Row],[Volume 1º Giro]])*BD_Receitas[[#This Row],[Tarifa 2º Giro]]) | W15: =IF(BD_Receitas[[#This Row],[TIPO DE COBRANÇA]]<>"OPERAÇÃO NORMAL","", IF(BD_Receitas[[#This Row],[Vol. Movimentado M³]]<BD_Receitas[[#This Row],[Volume 1º Giro]],BD_Receitas[[#This Row],[Vol. Movimentado M³]]* BD_Receitas[[#This Row],[Tarifa 1º Giro]], (BD_Receitas[[#This Row],[Volume 1º Giro]]*BD_Receitas[[#This Row],[Tarifa 1º Giro]])+(BD_Receitas[[#This Row],[Vol. Movimentado M³]]-BD_Receitas[[#This Row],[Volume 1º Giro]])*BD_Receitas[[#This Row],[Tarifa 2º Giro]]) ) | X15: =IF(BD_Receitas[[#This Row],[TIPO DE COBRANÇA]] <> "OPERAÇÃO NORMAL","", IF(BD_Receitas[[#This Row],[Vol. Movimentado M³]]= BD_Receitas[[#This Row],[Volume Mínimo ]], "Vol. Movimentado igual ao Vol. Mínimo", IF(ROUND(BD_Receitas[[#This Row],[Tarifa 1º Giro]],3) <> ROUND(BD_Receitas[[#This Row],[Tarifa Cobrada]],3), "Conferir tarifa cobrada", IF(BD_Receitas[[#This Row],[Volume Mínimo ]]=0,"Ok", IF(BD_Receitas[[#This Row],[Vol. Movimentado M³]]<= BD_Receitas[[#This Row],[Volume Mínimo ]], IF(ROUND(BD_Receitas[[#This Row],[Valor Total R$]],2) = ROUND(BD_Receitas[[#This Row],[Valor Total R$]],2), "Ok","Verificar Cobrança"), IF(ROUND(BD_Receitas[[#This Row],[Valor Contrato]],2) = ROUND(BD_Receitas[[#This Row],[Valor Movimentado]],2), "OK","Verificar cobrança") )))))
A16: 1401 | B16: 45658 | C16: BRASILIA | D16: MG RJ ES | E16: MINAS CENTRAL | F16: 1 | G16: Betim | H16: Tobras | I16: Operação Normal | J16: 226720.95 | K16: 6500 | L16: 219054.05 | M16: 4263.215 | N16: 17618 | O16: COBRANÇA DE ARMAZENAGEM CONJUNTA REFERENTE A DEZ/2024 | P16: =IF(BD_Receitas[[#This Row],[TIPO DE COBRANÇA]]="Operação Normal", _xlfn.XLOOKUP(BD_Receitas[[#This Row],[ID]],TabCondicoesComerciais[ID],TabCondicoesComerciais[Volume mínimo (m3)],0),"") -> 6500 | Q16: =_xlfn.XLOOKUP(BD_Receitas[[#This Row],[ID]],TabCondicoesComerciais[ID],TabCondicoesComerciais[Vol. 1ºGiro],0) -> 750 | R16: =IF(BD_Receitas[[#This Row],[TIPO DE COBRANÇA]]="Avanço Espaço", _xlfn.XLOOKUP(BD_Receitas[[#This Row],[ID]],TabCondicoesComerciais[ID],TabCondicoesComerciais[Avanço Espaço],0), IF(BD_Receitas[[#This Row],[TIPO DE COBRANÇA]]="Avanço Horário", _xlfn.XLOOKUP(BD_Receitas[[#This Row],[ID]],TabCondicoesComerciais[ID],TabCondicoesComerciais[Avanço Horário],0), IF(BD_Receitas[[#This Row],[TIPO DE COBRANÇA]]="Operação Normal", _xlfn.XLOOKUP(BD_Receitas[[#This Row],[ID]],TabCondicoesComerciais[ID],TabCondicoesComerciais[Tarifa 1º Giro],0),0))) -> 32.42 | S16: =IF(BD_Receitas[[#This Row],[TIPO DE COBRANÇA]]="Operação Normal", _xlfn.XLOOKUP(BD_Receitas[[#This Row],[ID]],TabCondicoesComerciais[ID],TabCondicoesComerciais[Tarifa 2º Giro],0),0) -> 32.42 | T16: =IFERROR(IF(BD_Receitas[[#This Row],[TIPO DE COBRANÇA]]<>"Operação Normal","",BD_Receitas[[#This Row],[Valor Total R$]]/ MAX(BD_Receitas[[#This Row],[Vol. Movimentado M³]], BD_Receitas[[#This Row],[Volume Mínimo ]]) ),0) -> 33.700623 | U16: =IFERROR(IF(BD_Receitas[[#This Row],[TIPO DE COBRANÇA]]<>"Operação Normal","", SUMIFS(BD_Receitas[Valor Total R$],BD_Receitas[CONGENERE],BD_Receitas[[#This Row],[CONGENERE]],BD_Receitas[FILIAL],BD_Receitas[[#This Row],[FILIAL]],BD_Receitas[DATA CONTABIL],BD_Receitas[[#This Row],[DATA CONTABIL]]) /BD_Receitas[[#This Row],[Vol. Movimentado M³]] ),0) -> 51.38236 | V16: =IF(BD_Receitas[[#This Row],[TIPO DE COBRANÇA]]<>"Operação Normal","",(BD_Receitas[[#This Row],[Volume 1º Giro]]*BD_Receitas[[#This Row],[Tarifa 1º Giro]])+(BD_Receitas[[#This Row],[Volume Mínimo ]]-BD_Receitas[[#This Row],[Volume 1º Giro]])*BD_Receitas[[#This Row],[Tarifa 2º Giro]]) -> 210730 | W16: =IF(BD_Receitas[[#This Row],[TIPO DE COBRANÇA]]<>"OPERAÇÃO NORMAL","", IF(BD_Receitas[[#This Row],[Vol. Movimentado M³]]<BD_Receitas[[#This Row],[Volume 1º Giro]],BD_Receitas[[#This Row],[Vol. Movimentado M³]]* BD_Receitas[[#This Row],[Tarifa 1º Giro]], (BD_Receitas[[#This Row],[Volume 1º Giro]]*BD_Receitas[[#This Row],[Tarifa 1º Giro]])+(BD_Receitas[[#This Row],[Vol. Movimentado M³]]-BD_Receitas[[#This Row],[Volume 1º Giro]])*BD_Receitas[[#This Row],[Tarifa 2º Giro]]) ) -> 138213.43 | X16: =IF(BD_Receitas[[#This Row],[TIPO DE COBRANÇA]] <> "OPERAÇÃO NORMAL","", IF(BD_Receitas[[#This Row],[Vol. Movimentado M³]]= BD_Receitas[[#This Row],[Volume Mínimo ]], "Vol. Movimentado igual ao Vol. Mínimo", IF(ROUND(BD_Receitas[[#This Row],[Tarifa 1º Giro]],3) <> ROUND(BD_Receitas[[#This Row],[Tarifa Cobrada]],3), "Conferir tarifa cobrada", IF(BD_Receitas[[#This Row],[Volume Mínimo ]]=0,"Ok", IF(BD_Receitas[[#This Row],[Vol. Movimentado M³]]<= BD_Receitas[[#This Row],[Volume Mínimo ]], IF(ROUND(BD_Receitas[[#This Row],[Valor Total R$]],2) = ROUND(BD_Receitas[[#This Row],[Valor Total R$]],2), "Ok","Verificar Cobrança"), IF(ROUND(BD_Receitas[[#This Row],[Valor Contrato]],2) = ROUND(BD_Receitas[[#This Row],[Valor Movimentado]],2), "OK","Verificar cobrança") ))))) -> Conferir tarifa cobrada
